File: GB3_Loc1_10um_250nm_test36.csv
Time On Sample,Displacement Into Surface,Load On Sample,Harmonic Contact Stiffness,Harmonic Displacement,Harmonic Load
0,0,0,476.216038,0.383745039,2.198319766
0.2,0.012205903,0.000689183,4522.09278,0.258012876,2.265068155
0.4,0.238413856,0.001363713,9516.624076,0.208680464,2.320874198
0.6,-0.088286211,0.002076103,13212.29773,0.186415395,2.439051639
0.8,0.206202552,0.002745957,14880.79524,0.174191434,2.551757951
1,0.18426805,0.003437478,16204.79329,0.165896603,2.662275768
1.2,0.226450894,0.004124608,17549.393,0.156728633,2.748720408
1.4,0.584224307,0.004790129,19769.84639,0.141885252,2.865803672
1.6,0.499005154,0.005485983,23115.02973,0.132280712,3.166718517
1.8,0.560339932,0.006171803,26465.65351,0.124859022,3.467633387
2,0.271111043,0.006881627,29276.24268,0.120929892,3.698517111
2.2,0.623055918,0.007544867,30459.38337,0.127041872,3.986301182
2.4,0.677729736,0.008226135,29645.26115,0.140575542,4.233598492
2.6,0.694099686,0.008910025,29697.05658,0.159784622,4.802601135
2.8,0.45566564,0.009611363,29843.63706,0.178120563,5.350813242
3,0.716430925,0.010278519,30171.75733,0.194710222,5.881517677
3.2,0.696162391,0.010964918,32080.4234,0.202131913,6.44614337
3.4,0.841183377,0.011639999,34309.56204,0.204751332,6.914476344
3.6,0.678524377,0.012336148,38625.34822,0.205624473,7.757037905
3.8,0.789404958,0.013013567,41571.22497,0.210426742,8.533945387
4,0.725420053,0.013702959,42836.93944,0.221777563,9.276931509
4.2,0.883764123,0.014377128,41675.99584,0.245352342,9.99146757
4.4,0.928861974,0.015059051,39795.85166,0.272856252,10.60095693
4.6,0.687929851,0.01576056,38350.59057,0.311274414,11.63500973
4.8,1.187261618,0.01641138,37292.2507,0.346200011,12.57167586
5,0.874717916,0.017117793,36532.72628,0.379815904,13.51490699
5.2,0.978520609,0.017795696,36231.83804,0.408629523,14.4504787
5.4,0.908290508,0.018485517,36060.68347,0.438752854,15.51407594
5.6,1.067050924,0.019159657,35655.99433,0.468439613,16.41025516
5.8,0.739518752,0.019867096,34617.40652,0.512096616,17.40819808
6,0.858309915,0.020543973,33219.08205,0.564485016,18.37331416
6.2,0.823052911,0.021231398,31752.45505,0.621675687,19.28371841
6.4,1.086732619,0.021898354,30648.28133,0.670134954,20.00919693
6.6,1.228839179,0.022573635,29530.56769,0.729945043,20.96337067
6.8,0.946272418,0.023277995,28900.86792,0.771419197,21.67790651
7,0.803597646,0.023976199,28148.87068,0.82293446,22.52156225
7.2,0.828294524,0.02465952,27341.46438,0.87663257,23.31488326
7.4,0.712266718,0.025349052,26533.98036,0.926838123,23.94516302
7.6,0.769438614,0.026030149,25544.00757,0.992760193,24.71003391
7.8,0.750835466,0.026716434,24711.55349,1.047331444,25.2144766
8,1.141084478,0.027374723,23637.22902,1.119802057,25.78895077
8.2,1.126644794,0.028060723,22650.0495,1.191836107,26.30105317
8.4,0.996460813,0.028754649,21993.95307,1.245534221,26.70482611
8.6,0.967865352,0.029441618,21354.06882,1.304471172,27.20160908
8.8,1.114135376,0.030116613,21121.95622,1.334594499,27.58130918
9,1.031414884,0.030807289,21025.39265,1.357296141,27.97742236
9.2,1.202665692,0.031480574,21116.61285,1.372139517,28.48624222
9.4,0.83349888,0.032190864,21199.12853,1.385236627,28.91299387
9.6,1.209592114,0.032850122,21215.34473,1.401389707,29.30582488
9.8,1.12021008,0.033541254,21139.58943,1.4262742,29.73804794
10,1.380559015,0.034208438,21114.48917,1.442863853,30.06850744
10.2,1.063019158,0.034915193,21127.12999,1.461199802,30.48650525
10.4,1.240931508,0.035588022,21167.1258,1.473860327,30.82571848
10.6,1.051626339,0.036285995,21369.7035,1.479972313,31.26231845
10.8,0.920609665,0.036979978,21633.68934,1.478226036,31.6037199
11,1.516533793,0.037624184,21906.72953,1.47735288,31.95497023
11.2,1.136541977,0.038335215,22189.78241,1.480408881,32.38062758
11.4,1.604231415,0.038988201,22483.24985,1.479972298,32.74610286
11.6,1.418257019,0.039685947,22808.39966,1.477352883,33.11376588
11.8,1.824327189,0.040343153,23258.04476,1.469931182,33.56349728
12,1.799895192,0.041029837,23720.50116,1.459016933,33.93334897
12.2,1.658886206,0.041724504,24659.62939,1.428893607,34.46843021
12.4,1.79349853,0.042400298,25565.06745,1.400079984,34.94114018
12.6,1.595866435,0.043098842,26739.91755,1.364717819,35.55281779
12.8,1.553115197,0.043786781,27556.79315,1.34288932,36.00036028
13,1.724366004,0.044460066,28512.89449,1.320187676,36.58468244
13.2,1.721584019,0.045145267,29168.43124,1.310146566,37.14711964
13.4,1.894500211,0.045818438,29626.63253,1.305780862,37.62420666
13.6,2.063252938,0.046491894,30046.02956,1.303598009,38.1144245
13.8,2.261982604,0.047163298,30399.55758,1.305780854,38.66920235
14,1.882823486,0.047874272,30814.5785,1.305780863,39.25571228
14.2,2.131514719,0.048542254,31128.65879,1.306217428,39.6977839
14.4,2.183690457,0.049223693,31407.95188,1.308836846,40.15955152
14.6,2.334956636,0.049898346,31591.90797,1.319751094,40.7471564
14.8,2.236414982,0.050590105,31767.46726,1.329355635,41.27786066
15,2.238629154,0.051274965,31812.08961,1.341143025,41.70023572
15.2,1.87862197,0.051984627,31812.74445,1.356859554,42.19154711
15.4,2.118153583,0.052653237,31921.91141,1.366027518,42.6292418
15.6,2.01378308,0.053345395,32226.17642,1.370393222,43.20152702
15.8,2.167547337,0.054019877,32552.98839,1.373012637,43.73660859
16,2.400417406,0.054688943,32804.93978,1.376068621,44.1655494
16.2,1.976292879,0.055402996,33098.1879,1.380434331,44.69078214
16.4,2.004320527,0.056086088,33254.15192,1.38785602,45.13723026
16.6,2.093134748,0.056765018,33217.78495,1.406628528,45.67231195
16.8,2.100345077,0.057449536,33097.51997,1.426274178,46.13626796
17,2.052597682,0.058137816,32966.24739,1.442427269,46.49627143
17.2,2.290463909,0.05880654,32732.79162,1.464692333,46.9295892
17.4,2.173603015,0.059499553,32580.84837,1.481281996,47.27099062
17.6,2.251592229,0.060179224,32628.7643,1.492632814,47.75792568
17.8,2.34373722,0.060857926,32709.84441,1.501364211,48.20875105
18,2.579105368,0.061526821,32971.70944,1.500491065,48.57860321
18.2,2.714550382,0.062202557,33414.94385,1.495688791,49.07429221
18.4,2.493602893,0.062902698,33787.41782,1.491759667,49.48134762
18.6,2.531622854,0.063585106,34247.46778,1.488703677,50.02846572
18.8,2.413929268,0.064278176,34629.79858,1.48564769,50.44974633
19,2.352858789,0.064967369,34887.69125,1.489140252,50.94215231
19.2,2.693146225,0.06562908,34921.27649,1.500491062,51.39954349
19.4,2.718675795,0.066312343,34814.4049,1.514897871,51.75517027
19.6,2.582662968,0.067006668,34624.85955,1.534543525,52.20271244
19.8,2.796381102,0.067677045,34393.49003,1.552442889,52.51566434
20,3.037578097,0.06834554,34409.32905,1.563357132,52.91396656
20.2,2.550168924,0.069063927,34792.39885,1.560737726,53.36807361
20.4,2.803856311,0.069731567,35274.50846,1.551569749,53.77731829
20.6,2.945130175,0.070406904,35850.66286,1.541965205,54.26261218
20.8,2.909873173,0.07109433,36418.20552,1.532360666,54.72383257
21,3.169389408,0.071761571,36762.6236,1.532360659,55.21186226
21.2,2.740268729,0.072475966,36819.98926,1.542401781,55.64517884
21.4,3.131350421,0.073134198,36957.25128,1.54807718,56.03144483
21.6,3.004497216,0.073827896,37157.75308,1.551133174,56.4363119
21.8,3.483844338,0.074480084,37523.80572,1.54982345,56.92434208
22,3.220429496,0.075183349,37990.65048,1.544584618,57.41784196
22.2,3.050275663,0.075885202,38430.18285,1.538472643,57.84131085
22.4,3.213198119,0.076571254,38816.7565,1.538036069,58.38952348
22.6,3.303675502,0.077269175,39116.13122,1.537162926,58.79767359
22.8,3.250096227,0.077983922,39349.13565,1.540655488,59.29336233
23,3.266462307,0.07870108,39555.29612,1.545021187,59.78248584
23.2,3.270337156,0.07942631,39695.47326,1.548513747,60.15343192
23.4,3.598961344,0.080136493,39871.28844,1.553752578,60.68085416
23.6,3.327213192,0.080895204,40097.54389,1.554189156,61.09447483
23.8,3.384377814,0.081638824,40470.01284,1.551569734,61.60438888
24,3.31830305,0.08239827,40989.03104,1.543711476,62.1405643
24.2,3.470392453,0.083154243,41653.67571,1.532797222,62.70190764
24.4,3.551702971,0.083915076,42226.5303,1.525375531,63.23808341
24.6,3.645502544,0.084686547,42484.1355,1.527558378,63.68672046
24.8,3.745962292,0.085469304,42621.22674,1.535416635,64.20976524
25,3.798125863,0.086255351,42681.5486,1.545457743,64.713114
25.2,3.661266786,0.087066321,42639.85842,1.555498857,65.09281366
25.4,3.917437771,0.087858259,42750.31527,1.560737689,65.50971802
25.6,3.998742344,0.088670203,43185.37463,1.558554837,66.0973229
25.8,3.976792047,0.089497547,43657.63168,1.552879428,66.56675009
26,3.78663685,0.090344709,44218.55983,1.547204024,67.14450621
26.2,3.860444276,0.091182206,44757.67528,1.542401752,67.71132055
26.4,3.765214081,0.092039813,45141.28352,1.540655475,68.1905957
26.6,3.87066185,0.09289218,45526.03557,1.541965182,68.80993353
26.8,3.845375859,0.093762086,45679.31656,1.546767453,69.2476279
27,3.91085236,0.094634517,45647.05837,1.558991411,69.75097643
27.2,4.109558682,0.095506593,45698.53869,1.568159375,70.26526787
27.4,3.941879165,0.096412616,45751.80839,1.575581069,70.68873676
27.6,4.058979525,0.097308094,45669.1961,1.589114736,71.20521647
27.8,3.979563338,0.098226137,45645.4381,1.597846138,71.6013295
28,3.941780732,0.099150404,45908.09854,1.599592419,72.1101493
28.2,3.904829734,0.100083949,46306.11792,1.59784614,72.64851335
28.4,4.058564281,0.101013846,46566.64267,1.598719276,73.08839643
28.6,3.838418698,0.101978676,47088.4607,1.594353582,73.68366028
28.8,4.040447218,0.102924238,47435.99129,1.592607297,74.12901468
29,4.097586089,0.103889263,47572.36996,1.599592415,74.6454942
29.2,4.009835294,0.104873919,47528.96657,1.611379807,75.11382701
29.4,4.2626547,0.10584498,47556.66995,1.619674629,75.5362028
29.6,4.18073047,0.106848869,47542.6973,1.629279171,75.94106997
29.8,4.350278276,0.107845632,47776.40441,1.632771726,76.43894754
30,4.238374764,0.108871728,48311.40503,1.62665975,76.97621721
30.2,4.277187443,0.109897776,48834.80392,1.619674629,77.45111576
30.4,4.38677782,0.110929177,49548.46685,1.609633517,78.09562103
30.6,4.438078484,0.111975065,50122.17797,1.601338686,78.59896946
30.8,4.172121994,0.11305315,50696.64084,1.594790144,79.19642178
31,4.450745311,0.114104672,51106.57571,1.593043857,79.78840392
31.2,4.931711737,0.115152872,51304.7449,1.595226692,80.23923066
31.4,4.795651597,0.116254051,51482.71769,1.598719256,80.70646891
31.6,5.028473064,0.117340925,51772.10094,1.601775241,81.32690126
31.8,4.994831575,0.118457056,52090.35938,1.603521522,81.9210713
32,4.964519552,0.119584188,52406.98584,1.603084952,82.40253503
32.2,5.039125501,0.120715409,52994.69054,1.59697297,83.02624975
32.4,5.107901286,0.121858343,53491.7189,1.591734127,83.55804862
32.6,5.076752602,0.123019647,54150.83037,1.58474901,84.27039615
32.8,5.095564133,0.124189123,54528.4704,1.582566159,84.77155628
33,5.403318663,0.125350675,54901.31337,1.583439291,85.40730827
33.2,5.539537139,0.126535583,55224.28997,1.586058707,86.01460964
33.4,5.534196461,0.127742142,55376.91326,1.592170688,86.53984289
33.6,5.493881285,0.128963162,55373.33812,1.604394646,87.14057858
33.8,5.507689711,0.130192726,55456.75508,1.610943196,87.6100056
34,5.338304292,0.131447263,55773.71934,1.61268948,88.21621183
34.2,5.491169494,0.132692325,56175.67808,1.611379766,88.83883279
34.4,5.810571801,0.133938362,56795.41575,1.603521499,89.45160569
34.6,5.595383898,0.135233738,57533.92996,1.592607254,90.04905834
34.8,5.687458105,0.136521009,58206.7765,1.586058702,90.75921756
35,5.831157758,0.137817673,58648.81201,1.585622128,91.42560773
35.2,5.710892295,0.139145502,58937.58708,1.587368412,91.96615992
35.4,6.464119989,0.140426464,59169.06175,1.59042438,92.49796115
35.6,6.349680345,0.141779956,59377.97183,1.596099793,93.18514085
35.8,6.653250863,0.143118414,59956.97471,1.591734084,93.88326437
36,6.693688903,0.144488478,60660.96743,1.584748964,94.62077969
36.2,6.766600365,0.145870023,61350.85444,1.576454133,95.23136361
36.4,6.769564017,0.147270303,62544.12226,1.561174184,96.14395646
36.6,6.729226019,0.148687556,63445.80384,1.550259936,96.82785386
36.8,6.611445933,0.150124439,64679.85231,1.534979991,97.72403274
37,6.768452783,0.151556763,65711.70312,1.524938877,98.59395092
37.2,6.661494361,0.153021632,66462.93923,1.518826901,99.29644991
37.4,6.500409196,0.154504973,66870.59221,1.520573185,100.0142685
37.6,7.050441884,0.155954403,66828.85883,1.534543409,100.8535494
37.8,6.816076331,0.157472261,66400.747,1.555498774,101.5538595
38,6.900630325,0.158983398,66121.87939,1.57077872,102.1086375
38.2,6.953123889,0.160511879,65906.76568,1.586058667,102.7662735
38.4,7.250843676,0.16203885,66024.41866,1.592170638,103.3560678
38.6,7.15261628,0.163608439,66686.76254,1.589114651,104.1931581
38.8,7.20427175,0.165183406,67575.02926,1.580383251,105.0072699
39,7.355848489,0.166767492,68354.90702,1.574271267,105.8180994
39.2,7.362118499,0.16837745,68977.25687,1.570342138,106.5085623
39.4,7.354230853,0.170004544,69374.22277,1.571651848,107.1869886
39.6,7.734376107,0.171621384,69413.74017,1.582566086,108.007667
39.8,7.537463414,0.173294135,69209.34409,1.59740947,108.7134488
40,7.394673788,0.174980019,69142.18436,1.607014013,109.2682257
40.2,7.524172729,0.176663987,69089.51759,1.618364829,109.9543122
40.4,7.706129344,0.17836126,69128.98675,1.626223083,110.5594254
40.6,7.906403203,0.180074429,69358.25894,1.630588776,111.1973657
40.8,8.076698127,0.181806821,69669.03153,1.634517901,111.9381646
41,8.051308234,0.183570111,69910.35065,1.639320171,112.6603601
41.2,7.907673914,0.185359257,70073.73995,1.643685875,113.2238909
41.4,8.492643636,0.18711622,70328.68249,1.646305277,113.8290059
41.6,8.439768668,0.18893484,70831.19894,1.645868709,114.6398346
41.8,8.192874184,0.190784979,71355.13236,1.642812727,115.2843387
42,9.207506976,0.192567098,71967.73425,1.640193277,116.0710982
42.2,9.622598949,0.194408199,72525.8929,1.636700705,116.7298302
42.4,9.35571233,0.196324325,73346.29563,1.628842454,117.4651559
42.6,9.643397921,0.198212003,74478.74432,1.617491627,118.4127654
42.8,9.854473571,0.20012397,75631.08846,1.603957953,119.212653
43,10.00642693,0.202049542,77405.54374,1.581692882,120.2937588
43.2,10.09592496,0.204008438,79030.07162,1.561610662,121.215106
43.4,10.11047835,0.205992264,80411.70251,1.547203854,122.170374
43.6,10.19580831,0.207991068,81462.52758,1.541528443,123.2985319
43.8,10.60255528,0.209988076,81716.6866,1.54676727,124.1071743
44,10.32066309,0.212052278,81874.43426,1.555498677,125.0591587
44.2,10.73739766,0.214089169,81868.97402,1.564230064,125.7857332
44.4,10.8851701,0.216165044,81915.09675,1.572524889,126.5670185
44.6,10.63824379,0.218289003,82663.536,1.571215186,127.6349919
44.8,10.7660267,0.220408429,83379.81834,1.567722623,128.4731774
45,11.1835842,0.222529151,84247.92923,1.564230052,129.5280227
45.2,11.317191,0.224690815,84752.38088,1.565103188,130.36402
45.4,11.6531396,0.226860285,85269.87927,1.566412888,131.2426933
45.6,11.38788155,0.229092892,85430.50267,1.576017434,132.2887815
45.8,11.45736335,0.231324912,85756.61923,1.579946561,133.0799147
46,11.49103677,0.233581699,86520.41903,1.579073421,134.1424184
46.2,11.78617304,0.235843327,87348.94927,1.574707713,135.0276566
46.4,11.23945439,0.238185406,88163.41335,1.5707786,135.94353
46.6,11.64949688,0.240485196,89608.15329,1.55986434,137.2205055
46.8,11.71396921,0.24283202,90164.85041,1.559864338,138.1385701
47,11.63688105,0.24521212,90254.11194,1.568595739,139.1474555
47.2,11.81792485,0.247598268,90180.97408,1.580383122,140.1541536
47.4,12.10971396,0.25000093,89817.76761,1.595663061,140.9627954
47.6,11.92603276,0.252460419,89470.74775,1.610069874,141.6904618
47.8,12.0129738,0.254925997,89575.46032,1.619237839,142.5997725
48,11.93836959,0.257427425,89763.42538,1.624913251,143.3657375
48.2,11.87958362,0.259952842,90130.63783,1.628842382,144.3155341
48.4,12.16303137,0.262480197,90708.30336,1.627532664,145.1537208
48.6,12.18917415,0.265050578,91331.05487,1.625786383,146.0247329
48.8,12.42265439,0.267632537,91793.68777,1.627969226,147.0215831
49,12.32555262,0.270263169,91951.6918,1.63364464,147.7919251
49.2,12.56235753,0.272897361,91925.79838,1.644122311,148.7001423
49.4,12.95903636,0.275546955,91748.71196,1.655036547,149.3993607
49.6,13.19000624,0.278234624,91549.28193,1.666387358,150.1106155
49.8,13.38683259,0.280951595,91429.09918,1.676865029,150.9061262
50,13.46874419,0.283703699,91609.90864,1.682103866,151.7705733
50.2,13.46488524,0.286489304,92126.12355,1.680794156,152.4905807
50.4,13.54595768,0.289297072,92680.79718,1.679484445,153.2751486
50.6,13.56707296,0.292137156,93634.22658,1.673809035,154.3157674
50.8,13.76471577,0.294993709,94522.76344,1.667697051,155.1451995
51,13.90573212,0.297882962,95695.074,1.659402217,156.1880074
51.2,14.18247399,0.300791873,96491.1285,1.654599941,157.0152515
51.4,13.86966608,0.303770618,97382.28805,1.649361112,157.9256545
51.6,13.84912981,0.306759143,98205.86548,1.647614832,159.0198906
51.8,14.29156715,0.309745833,98595.32671,1.649797667,159.816497
52,14.10365269,0.312805783,98742.297,1.657219361,160.7575397
52.2,14.57272913,0.315851373,98693.51239,1.665514175,161.461136
52.4,14.9568674,0.318932984,98641.68396,1.673808993,162.1909935
52.6,15.68074064,0.322022375,98643.82123,1.682976937,163.1276644
52.8,15.67600423,0.325192949,98974.58797,1.684286647,163.8903472
53,15.8194834,0.328385132,100018.6041,1.676428385,164.9484746
53.2,15.95213384,0.331610082,101106.1138,1.666387273,165.8380893
53.4,16.1330767,0.334864035,102514.3367,1.652853602,166.8360339
53.6,16.23990609,0.33815593,104553.5215,1.633644523,168.2093009
53.8,16.02447961,0.341503026,106401.3605,1.617928014,169.474237
54,16.24787822,0.344853443,107553.0238,1.610942889,170.491878
54.2,16.42047868,0.348240998,108665.0301,1.607013755,171.7097643
54.4,16.62888095,0.351660183,109312.4849,1.607450319,172.6934839
54.6,16.648258,0.355126795,110017.6734,1.610069738,173.9967197
54.8,16.70426947,0.358625713,110282.1879,1.615308575,174.92135
55,16.6553576,0.362166951,110316.4589,1.625349684,176.0210572
55.2,16.64890891,0.365740841,110574.787,1.630151953,176.9358386
55.4,17.00759174,0.369325544,110971.9368,1.633207931,177.890015
55.6,16.96782695,0.372973849,111317.0716,1.639319911,179.0991458
55.8,17.05504353,0.376650065,111649.718,1.644122177,180.1944768
56,17.26840872,0.380354609,112051.3912,1.64630502,181.1245793
56.2,17.55921001,0.384090973,112249.4674,1.65110728,182.016384
56.4,17.76465595,0.387870684,112280.5983,1.658528962,182.9136591
56.6,17.67116081,0.391709115,112230.3155,1.669006642,184.0100832
56.8,18.0660354,0.395552406,112362.177,1.674682038,184.8285743
57,18.92971142,0.399401903,112565.5065,1.68123056,185.8407487
57.2,18.92654999,0.403349702,112794.4662,1.686905968,186.8430692
57.4,18.9516955,0.407335134,113237.6125,1.687779108,187.721741
57.6,19.45147109,0.411328059,113878.698,1.686032813,188.6781072
57.8,19.79469581,0.415371914,114551.8078,1.684723093,189.80955
58,19.65245607,0.419489693,115255.2549,1.681667108,190.7440273
58.2,19.92655777,0.423620295,116343.2328,1.675991692,191.9520656
58.4,19.99331422,0.427806543,117175.2263,1.672499131,192.9434446
58.6,20.32819276,0.432016515,118217.3153,1.667696852,194.0387776
58.8,20.29917973,0.436293947,119656.6857,1.659402026,195.3332589
59,20.3942329,0.440605658,120743.1831,1.653726615,196.4012347
59.2,20.83817921,0.444936644,121808.1438,1.650234043,197.6804002
59.4,21.08144157,0.449324928,122653.5594,1.648051186,198.753848
59.6,21.16565451,0.453768326,123326.9357,1.648051184,199.8623104
59.8,21.07582952,0.458268318,124073.1323,1.648924326,201.1370952
60,21.23580437,0.462819254,124417.978,1.65285345,202.1011184
60.2,21.58646582,0.467356926,125284.5004,1.65241687,203.3726237
60.4,21.66732419,0.472005256,125957.4636,1.652853437,204.4340342
60.6,21.7207037,0.476655401,126646.4569,1.653726576,205.5490612
60.8,21.66582503,0.481383229,127020.3732,1.659401985,206.7669461
61,21.98815053,0.486132609,127757.6394,1.658528836,207.7966253
61.2,22.22303777,0.490935817,128358.3645,1.661148248,209.0451502
61.4,21.92999235,0.495823462,128958.075,1.662021397,210.1021811
61.6,22.39885487,0.500707797,129801.1007,1.662457952,211.4907707
61.8,22.44720195,0.505670215,130417.2269,1.662894521,212.521542
62,22.40477976,0.510688719,130689.8841,1.6690065,213.7339558
62.2,22.9310807,0.515718363,131153.4639,1.671189333,214.7450342
62.4,23.01937949,0.520828779,131590.2077,1.673808749,215.7747115
62.6,22.95112611,0.526001366,132166.4791,1.676864741,217.1085856
62.8,23.31420141,0.531196209,132717.1304,1.677737869,218.1426415
63,23.3475244,0.536465991,134131.8998,1.670752751,219.5563957
63.2,23.22929121,0.54179906,135123.0527,1.666823626,220.6867414
63.4,23.08190755,0.547187746,135497.385,1.66987962,221.753621
63.6,23.50824273,0.552591009,135592.2234,1.678174433,223.0557657
63.8,23.49157919,0.558078953,135428.0367,1.686905831,223.9617938
64,24.64151143,0.563541661,133928.2946,1.712226845,224.866736
64.2,25.23936216,0.569097229,132406.2847,1.735801596,225.429178
64.4,25.40503899,0.574738499,131695.9068,1.750208395,226.1021352
64.6,25.61734002,0.580433061,131557.8986,1.759376354,227.0584994
64.8,25.7180536,0.586192583,132134.6458,1.758066642,227.8726123
65,25.80793546,0.592010667,134333.3118,1.739730707,229.1922627
65.2,25.92195859,0.597885563,136852.797,1.717465643,230.4331275
65.4,26.68963843,0.603774548,138973.0368,1.700875966,231.661962
65.6,26.82529783,0.609766067,141349.9498,1.684722879,233.3142606
65.8,27.01590791,0.615814143,142148.83,1.683413164,234.4271008
66,27.165709,0.621925799,142271.4865,1.690834846,235.6449875
66.2,27.16894908,0.628108839,142043.3078,1.701749093,236.7709566
66.4,27.57353969,0.63432648,141758.1996,1.711353614,237.6748
66.6,27.76245569,0.640621403,141923.6525,1.716155876,238.6727457
66.8,28.01298358,0.646975272,143164.381,1.710480463,239.9978677
67,27.94708091,0.653414848,143973.6673,1.707861046,241.0395816
67.2,28.278365,0.659891764,145053.4312,1.703931907,242.3428194
67.4,27.88603182,0.666483521,146866.9913,1.692144536,243.6482406
67.6,28.26726219,0.673088272,148304.5059,1.685159408,244.9492914
67.8,28.32623288,0.67978159,148806.8903,1.689088533,246.3116167
68,28.49094768,0.686534874,149681.0591,1.687342249,247.4704149
68.2,28.42916225,0.693371583,150193.4538,1.690398241,248.7758389
68.4,28.84949774,0.700243816,149482.4217,1.704368461,249.6928129
68.6,29.14825212,0.707193417,148738.2068,1.718775254,250.6032205
68.8,29.80588877,0.714188323,148609.5491,1.727943199,251.7445151
69,29.78320756,0.721300332,148307.1549,1.737547734,252.5881716
69.2,29.5373565,0.728498919,148570.508,1.742786578,253.6845959
69.4,29.83357978,0.735732464,149474.2997,1.74016715,254.7394427
69.6,30.1189696,0.743039564,150711.6183,1.734055165,255.8883929
69.8,30.52009512,0.750412097,151658.9016,1.731872303,257.1347335
70,30.42326198,0.757892986,152417.4849,1.731872306,258.3843504
70.2,30.53042973,0.765434984,152879.1568,1.733182012,259.3801072
70.4,31.19465986,0.773014443,153312.9733,1.73492827,260.3911879
70.6,31.55578111,0.780690911,153507.1684,1.741040235,261.6134538
70.8,31.74785685,0.788456095,153704.4355,1.744969357,262.5151068
71,31.90495043,0.796301638,154307.9009,1.745405922,263.6542088
71.2,32.38345408,0.804204031,154637.1361,1.748898465,264.7703345
71.4,32.32985808,0.812222459,154855.1151,1.752391025,265.7321685
71.6,32.50940658,0.820305271,155005.2241,1.756756717,266.6841561
71.8,32.96373411,0.828450423,155469.759,1.758939551,267.8418627
72,33.29148289,0.836686095,155722.7694,1.762432099,268.7303864
72.2,33.46600664,0.84501514,156496.6054,1.761995523,269.8793368
72.4,33.65301104,0.853426966,157729.4624,1.755883541,270.9309002
72.6,33.75840177,0.861928858,159103.6927,1.748898421,272.0951696
72.8,34.66066912,0.870461397,160702.588,1.741040137,273.4761045
73,34.83640241,0.879129936,161999.9659,1.734491586,274.6075481
73.2,35.05958901,0.887882538,163138.4981,1.730999021,276.0114557
73.4,35.77238846,0.896689268,163447.1284,1.734054986,277.0903807
73.6,35.72034972,0.905637261,164390.1677,1.731435569,278.2874754
73.8,35.82692841,0.914664215,165286.312,1.730125857,279.6880999
74,36.47391385,0.92374476,166072.4419,1.728379558,280.7943796
74.2,36.85775793,0.932934469,167653.1381,1.72139443,282.2869231
74.4,37.44768265,0.942201888,169135.3616,1.714409296,283.5945421
74.6,37.66788116,0.951587927,170055.9448,1.713972719,285.131947
74.8,37.88557063,0.961068443,171051.6881,1.711353294,286.3782852
75,38.16570094,0.970639879,172306.4733,1.708297297,287.9145975
75.2,38.48412392,0.980304796,173448.6828,1.70480473,289.1696904
75.4,38.80253558,0.990066925,174765.0298,1.700439023,290.5254539
75.6,38.81450509,0.999948245,176743.4598,1.693017337,292.3539235
75.8,38.93054958,1.00992165,178423.196,1.686032219,293.7764337
76,39.22727663,1.019982894,180161.3205,1.679920234,295.5118969
76.2,39.20174002,1.030167466,180557.333,1.683412792,296.8162273
76.4,39.45597611,1.040434997,181008.811,1.686468772,298.1873087
76.6,39.42708484,1.050825127,181244.126,1.692580749,299.8658687
76.8,39.72792757,1.061296979,180523.2921,1.704804692,300.9699576
77,39.82891191,1.071887836,179553.5099,1.720957767,302.2491212
77.2,40.05895118,1.08257612,179937.2857,1.724013748,303.3805651
77.4,40.30896256,1.093370548,180099.797,1.729689146,304.5481186
77.6,40.01188253,1.104311057,180355.5897,1.736674271,306.0220534
77.8,40.73399854,1.115346963,181372.5215,1.73405483,307.231193
78,41.68676383,1.126422606,182541.1651,1.731871951,308.7893969
78.2,42.87933149,1.13759315,182569.488,1.737547319,309.8803636
78.4,43.06350247,1.148888268,182873.2279,1.740603301,311.0336918
78.6,43.72561893,1.160321031,182967.8162,1.746715255,312.4594907
78.8,44.41603356,1.17186672,182983.6445,1.751954069,313.5154369
79,44.67676554,1.183557892,183667.0618,1.7528272,314.9160633
79.2,44.95830114,1.195365267,184828.0149,1.748461495,316.1514601
79.4,45.43966906,1.207277561,186178.1884,1.743222644,317.4536085
79.6,45.407252,1.219344782,187843.2338,1.737547239,319.1584297
79.8,45.49722658,1.231524942,188633.9581,1.737547236,320.3894479
80,45.75705612,1.243815784,189619.1631,1.737110658,321.9071585
80.2,45.69545215,1.25625209,190055.6122,1.739730078,323.0856514
80.4,46.61058154,1.268746089,190354.7217,1.743659176,324.2893228
80.6,46.82290415,1.281414039,191132.0475,1.745405448,325.8125041
80.8,47.20008498,1.294198017,192227.1173,1.742349448,327.1026135
81,47.93447581,1.307085769,193356.6876,1.740603146,328.6914552
81.2,47.88279026,1.320156663,194470.1777,1.737547161,330.0012566
81.4,48.32820665,1.333324537,195462.4274,1.735364298,331.3395142
81.6,48.57625959,1.346638463,197351.5916,1.727942607,333.2051918
81.8,48.59031051,1.360102189,198361.4311,1.726196328,334.5762718
82,48.51441495,1.373707259,199932.6022,1.722267204,336.3029777
82.2,48.75242843,1.387427363,201416.665,1.7179015,337.7626934
82.4,49.19693351,1.401271197,202897.3937,1.714408929,339.3044793
82.6,49.94951848,1.415232917,203417.8699,1.717901462,340.7313743
82.8,51.07346781,1.429309302,203533.0835,1.72532311,342.2819217
83,51.44464702,1.443578973,202924.8885,1.737547047,343.7077177
83.2,52.17719792,1.457967152,202199.7433,1.748024695,344.6651836
83.4,52.79815125,1.472507598,201725.6636,1.756756067,345.7506747
83.6,53.47154719,1.487190482,201478.5658,1.765050867,347.1327056
83.8,53.63365307,1.502056002,202189.2647,1.764177723,348.3484053
84,54.09217992,1.517050587,204508.0177,1.752826899,350.1298301
84.2,54.15765862,1.532222784,206830.6825,1.741476089,351.6650466
84.4,54.69941942,1.547514733,209146.3674,1.7309984,353.2735827
84.6,54.96221052,1.562979532,212930.4908,1.712225901,355.5747674
84.8,55.20916241,1.578600705,215318.2361,1.703494501,357.5859795
85,55.84746129,1.594351891,216552.9574,1.701311634,359.0982246
85.2,56.2192803,1.610279777,217620.7535,1.701748193,360.9901657
85.4,56.61023262,1.62636634,217783.3661,1.707423583,362.4487896
85.6,56.78216815,1.64262957,217535.117,1.716591541,363.8680182
85.8,57.47368448,1.659020427,217648.6111,1.72444977,365.4765565
86,58.08774129,1.675581262,217221.7478,1.735800559,366.988801
86.2,58.6126807,1.692314663,216941.9121,1.744095364,368.1169668
86.4,59.04517175,1.70922251,216316.3948,1.755009589,369.2451316
86.6,58.99551439,1.726333462,215961.2997,1.76505069,370.6928078
86.8,59.39299263,1.743585481,216403.3536,1.768543233,372.1656582
87,60.03692751,1.760993934,217457.4319,1.766360364,373.484222
87.2,61.00975536,1.778554577,219615.62,1.757192372,375.2415816
87.4,61.18900726,1.796346388,222296.6483,1.743658711,376.9485943
87.6,61.68299593,1.814295232,224870.0558,1.731434749,378.7311145
87.8,61.8197388,1.832448898,227455.1721,1.720520506,380.85175
88,62.12050075,1.85077373,229431.0138,1.712662245,382.5675194
88.2,62.91419491,1.869248661,232079.7984,1.702621121,384.7953994
88.4,63.0050755,1.88795767,233884.2155,1.697818854,386.6249665
88.6,63.87366846,1.906801065,236326.686,1.691270284,389.0563748
88.8,64.07941664,1.925879529,237905.7883,1.688214291,390.8465516
89,65.01624599,1.94509931,238619.8165,1.692579957,392.9026375
89.2,65.05457834,1.964574105,238861.6964,1.69781879,394.4641154
89.4,65.80650488,1.984195342,238490.452,1.708296434,396.2794668
89.6,66.4743066,2.004019493,237708.6043,1.720520359,397.7501318
89.8,66.70575461,2.024072946,237061.3301,1.732744297,399.405717
90,67.01961568,2.044322243,237111.6089,1.738419691,400.7713313
90.2,67.41838766,2.064769109,237062.5571,1.746277929,402.4214477
90.4,67.83920205,2.085420098,237324.7446,1.75064361,403.7859688
90.6,68.49439496,2.106263209,238494.7436,1.750643589,405.6921407
90.8,68.95846073,2.127328912,239762.9641,1.748460727,407.2437776
91,69.26095967,2.148617458,241448.2992,1.744968161,409.1827715
91.2,69.72955575,2.170108396,243215.9633,1.739292743,410.8252301
91.4,70.29596799,2.191808566,244671.7003,1.735800169,412.5760191
91.6,70.58506852,2.213745757,246042.9103,1.734053882,414.6824326
91.8,71.54029688,2.235857111,247012.7072,1.733180713,416.2844108
92,71.81477394,2.258236836,248739.1496,1.729251579,418.3864467
92.2,72.11836905,2.280839498,250267.5307,1.725759014,420.1317609
92.4,72.95069703,2.303632694,252183.5453,1.720956724,421.9865074
92.6,73.58065425,2.326668979,254804.8767,1.714844732,424.4419873
92.8,73.93246551,2.349955864,255810.1194,1.71571786,426.1927745
93,74.86713377,2.373436553,256247.8085,1.720956663,428.2007162
93.2,75.13145774,2.397199381,255722.2246,1.730124613,429.6276064
93.4,76.25176101,2.421141925,255458.3319,1.737546257,431.135484
93.6,76.90822702,2.445357015,255407.7987,1.744967916,433.1291966
93.8,77.29237453,2.469834228,256805.1659,1.743658195,435.1590148
94,77.92047213,2.494540376,257851.6411,1.743221606,436.7150311
94.2,78.56352928,2.519493789,259976.5123,1.738419322,438.9057063
94.4,79.14743617,2.544701925,262213.6769,1.732307332,441.0000893
94.6,79.31580047,2.57019189,263455.6056,1.731434188,442.7246113
94.8,80.4284073,2.595873034,264434.8272,1.733616999,444.7839856
95,81.2503747,2.621832331,266322.2259,1.72881471,446.6135644
95.2,82.11311365,2.648049608,267955.2566,1.727068405,448.7801708
95.4,82.37210503,2.674705179,269286.5327,1.726195258,450.581293
95.6,82.81593825,2.701483051,271489.7311,1.72226612,453.0794466
95.8,83.4187842,2.728519549,273492.3787,1.717463838,455.0271998
96,84.06156775,2.755824966,274173.5083,1.721829511,457.1916153
96.2,84.81924693,2.783258234,274695.3475,1.725322042,458.8789428
96.4,85.95825065,2.811079554,274845.87,1.730997407,460.5805029
96.6,86.50434545,2.839221278,274827.7876,1.739292207,462.6015715
96.8,86.98462472,2.867650381,274729.8709,1.747587008,464.4989885
97,87.64389946,2.896352694,275671.2494,1.748023556,466.1020589
97.2,88.41805207,2.925335534,277708.5449,1.743657838,468.2894557
97.4,88.68089821,2.954644805,280000.7469,1.73710929,470.2930113
97.6,89.45415,2.984213331,282933.4923,1.728814449,472.8984078
97.8,89.77688113,3.014110016,285529.2966,1.720519622,474.9993519
98,90.66414215,3.044268204,288516.3296,1.712224777,477.6550845
98.2,91.34486042,3.07474364,289458.6316,1.713534463,479.6159718
98.4,92.06717765,3.105522367,289399.0319,1.72008298,481.4488353
98.6,93.1799912,3.136583443,289408.2536,1.727941191,483.6756293
98.8,93.9055669,3.167983318,287999.4414,1.743221093,485.5205282
99,94.38046585,3.199715401,286858.237,1.755008448,486.9474242
99.2,94.91777966,3.23176124,287472.318,1.758937554,488.9345714
99.4,95.50834826,3.264125427,289596.705,1.754135273,491.061783
99.6,96.5585247,3.296782984,291182.5619,1.751079254,492.8968408
99.8,96.9300195,3.329815295,293751.2116,1.744530703,495.3818642
100,97.74696557,3.3631489,295178.8678,1.7427844,497.2431785
100.2,98.30823645,3.396834912,296369.114,1.741911244,499.1405998
100.4,99.13343112,3.430841106,296884.9826,1.744967202,501.0719473
100.6,100.2350395,3.465170195,298070.9058,1.746713443,503.4716327
100.8,101.0892985,3.499860986,299591.5306,1.746276846,505.6710689
101,101.3839484,3.534938913,301355.4185,1.743220852,507.5498836
101.2,102.1731759,3.570335222,301605.6205,1.750205934,509.6836648
101.4,102.9415447,3.606088669,301349.871,1.758064155,511.3578644
101.6,103.3842895,3.64222359,301215.7059,1.764612678,512.9981372
101.8,104.3415953,3.678686268,301754.8823,1.768105201,514.9426179
102,105.0224049,3.715534256,302372.7244,1.771597732,516.9560313
102.2,106.1528248,3.752721566,303875.3048,1.76897828,518.7199644
102.4,106.9667784,3.790304312,306142.4655,1.762866285,520.7300985
102.6,107.8664554,3.828258762,308883.5442,1.75631772,523.3037652
102.8,108.6553401,3.866602092,310303.1137,1.755007987,525.2219817
103,109.3692377,3.905335758,312063.247,1.752825118,527.5428772
103.2,110.7126046,3.944415363,314665.0432,1.747149676,530.0695013
103.4,111.6695571,3.983914183,316606.6769,1.743657092,532.1912498
103.6,112.3533408,4.023828605,318483.7502,1.740601086,534.3666113
103.8,112.9321587,4.064151202,320836.2844,1.736671944,536.9927978
104,113.757406,4.104861987,322435.3249,1.734925642,539.1156385
104.2,114.8249189,4.145965232,324483.6237,1.731869623,541.7068186
104.4,115.0180581,4.187541651,326363.1272,1.728813634,543.9182813
104.6,116.256176,4.229463775,329115.0072,1.724447904,546.9241819
104.8,116.849742,4.271851502,330457.1742,1.724447884,549.0699978
105,117.6697505,4.314649433,331415.9397,1.728376981,551.6841529
105.2,118.729524,4.357860832,330362.2379,1.74016431,553.4196391
105.4,119.5069646,4.401525844,328701.4291,1.754571064,555.012867
105.6,120.1561199,4.445638285,327371.04,1.768541253,557.0711455
105.8,121.0167271,4.490179436,328104.8111,1.77072407,558.875564
106,121.7015844,4.535180179,330362.4028,1.766794926,561.3157329
106.2,122.7685943,4.580606818,333730.2888,1.756317234,563.5666057
106.4,123.7897531,4.626493139,337908.1012,1.74322013,566.2365723
106.6,124.8982908,4.672834374,341108.2949,1.73623499,569.1976073
106.8,125.8094266,4.719654793,342400.5407,1.736234961,571.3357713
107,126.7729671,4.766942055,342997.3656,1.741037189,573.8908421
107.2,127.7222967,4.814705365,343405.2227,1.74496628,575.8331372
107.4,128.9646776,4.862928376,344041.7131,1.748022222,577.9527063
107.6,130.1220677,4.911641747,346346.3633,1.744966202,580.9345337
107.8,130.664875,4.960886842,348113.1547,1.74278334,583.1897741
108,131.5207162,5.010607203,350348.2541,1.739727329,586.0468538
108.2,132.8199072,5.060797037,351991.3795,1.737981012,588.3371267
108.4,133.6523162,5.111523349,353748.5982,1.736671278,590.7455672
108.6,134.4563545,5.162761119,356719.9578,1.732305563,593.844473
108.8,135.7840954,5.214477698,359696.707,1.725756986,596.3076363
109,136.8923619,5.266728997,363552.9255,1.71789871,599.5488005
109.2,138.2058255,5.319491281,365390.0654,1.71702553,601.9681931
109.4,138.92885,5.372821643,366460.4794,1.719644921,604.4576058
109.6,140.3187974,5.426641991,366190.4841,1.729249392,607.3092261
109.8,141.1416196,5.481042028,364273.1726,1.74321957,609.0698775
110,142.1975315,5.535972606,362041.2317,1.759809153,611.14677
110.2,143.3807809,5.591446357,360899.7975,1.771596474,613.3013537
110.4,144.557304,5.647477849,360958.0084,1.776835262,615.1714373
110.6,145.6421656,5.704078648,361741.8703,1.77901807,617.1564135
110.8,146.9759355,5.761231096,363944.6999,1.776398613,619.7104007
111,147.686786,5.819000561,366450.3726,1.771159764,621.903275
111.2,149.1128502,5.877301135,371066.4143,1.75893579,625.0361189
111.4,149.9151611,5.936230326,374870.759,1.74933125,627.6951428
111.6,151.320271,5.995710123,378942.4367,1.739290122,630.6321163
111.8,152.9035072,6.05577534,384497.8294,1.724446732,634.1643616
112,153.9495877,6.116481179,389337.5365,1.711786203,637.2545221
112.2,154.9098302,6.177802651,394242.9709,1.700871953,640.9902846
112.4,155.7800704,6.239746407,398519.8987,1.691703982,644.3846416
112.6,157.1356968,6.302279092,401656.3374,1.686901683,647.6838081
112.8,158.2006411,6.365460031,402800.309,1.689957631,651.0880196
113,159.482011,6.42926096,400372.0022,1.706110634,653.9516776
113.2,160.6192509,6.493713035,397497.0734,1.722263641,655.9443163
113.4,162.087788,6.559118863,394664.8257,1.738853205,657.9774508
113.6,163.2232104,6.624878074,392000.7881,1.755442779,659.9000601
113.8,164.4668446,6.690956951,389307.1025,1.773342056,661.9572631
114,165.5263381,6.758046449,389975.0073,1.777707708,664.3689959
114.2,166.7522912,6.825798769,391914.0556,1.775524824,666.5618847
114.4,167.9015575,6.894237157,394055.7345,1.772905374,668.9834687
114.6,169.2289396,6.963351002,398511.2416,1.762427682,672.3329722
114.8,170.5146064,7.033161962,403234.4082,1.750203718,675.2447815
115,171.7493975,7.103677908,408142.9181,1.739289462,678.7770236
115.2,173.1739595,7.174889175,411356.1358,1.734923729,682.0597843
115.4,174.5576365,7.246818696,415500.9977,1.726628881,685.1401089
115.6,175.8146605,7.319479777,419161.3312,1.72051688,688.263105
115.8,177.1781838,7.392863596,422126.847,1.717897425,691.8314633
116,178.7814361,7.466968314,424601.5389,1.715277962,694.7181107
116.2,180.0731757,7.541838886,428316.4832,1.710475666,698.4648288
116.4,181.1283438,7.617478072,430470.1752,1.710039064,701.572503
116.6,182.6006012,7.693848438,431858.4974,1.71222186,704.547784
116.8,183.8179663,7.771002108,433305.8242,1.71571437,708.0143722
117,185.3549944,7.848907386,433896.4348,1.72182628,711.3026103
117.2,186.8078298,7.927601296,434169.7249,1.727065056,713.8390994
117.4,188.183133,8.007090879,434744.8979,1.731430696,716.6042839
117.6,189.9230615,8.087353747,434816.7264,1.738415736,719.8027989
117.8,191.5821252,8.168428789,435588.1803,1.741035093,722.4355876
118,192.9746334,8.25033652,437051.2263,1.742344754,725.6428491
118.2,194.4827897,8.333059256,438428.5318,1.742781273,728.3489494
118.4,195.7368789,8.416630657,439732.2786,1.744527506,731.2126142
118.6,197.1457508,8.501030906,443370.9439,1.740161776,734.954962
118.8,198.5645162,8.586278457,446863.8217,1.734922909,737.9510355
119,200.3254175,8.672358987,451325.9438,1.728374326,741.7918738
119.2,201.7506442,8.759327528,454650.2792,1.725754869,745.5965929
119.4,203.3639572,8.847156726,458423.9044,1.720515997,749.1835669
119.6,204.9854943,8.935867967,459991.8095,1.72182565,752.1205551
119.8,206.447884,9.025481326,460589.8715,1.727500992,755.5685553
120,208.2190968,9.115973815,460510.8685,1.733612891,758.172899
120.2,209.4581151,9.207412083,462928.0143,1.733176283,761.7828406
120.4,211.4947432,9.29971421,464126.4942,1.735359059,764.6946767
120.6,212.6394528,9.393005126,467647.2133,1.730120203,768.1175015
120.8,214.1854098,9.487205734,473997.0923,1.71789624,772.5032712
121,215.7345874,9.582352459,479522.2369,1.707418552,776.1537095
121.2,217.5018184,9.678440056,485183.4999,1.698687131,780.6642298
121.4,219.2597775,9.775493776,490624.7172,1.690392277,784.702037
121.6,221.1150478,9.873515914,493891.1991,1.690392219,789.196147
121.8,222.7403812,9.972538773,493799.3409,1.697813827,792.3760642
122,224.6961766,10.07253379,493638.0259,1.70654513,796.0691913
122.2,226.3654099,10.17355313,491382.5166,1.719642122,798.6625956
122.4,228.2401993,10.27557321,488868.4279,1.733612243,801.3205662
122.6,229.8084398,10.37863944,487260.1534,1.745836101,804.7434059
122.8,231.6222032,10.48272414,486852.866,1.752384565,807.3072702
123,233.50246,10.58785027,486099.4392,1.761115865,810.3919976
123.2,234.8396805,10.69406989,489016.1846,1.758496412,813.9242556
123.4,236.7371768,10.8013181,490170.0534,1.760679191,816.8317171
123.6,238.3539314,10.90966309,492281.1643,1.760242569,819.8223328
123.8,240.1121164,11.01908694,496676.2816,1.75369399,823.6511444
124,241.8868274,11.12960916,500572.7555,1.747581979,826.9776995
124.2,243.7188647,11.24123782,504130.4222,1.743652807,830.9312559
124.4,245.5099697,11.35399084,510032.0069,1.732301979,834.8476109
124.6,247.2584757,11.46787963,515964.5443,1.721387722,838.9587401
124.8,249.1342501,11.58290385,520633.1296,1.715712277,843.4999084
125,250.9174615,11.69909007,525152.4639,1.709600268,847.3473291
125.174,252.9874186,11.8010857,529889.0945,1.703051682,851.203504
125.4,254.6219545,11.80392218,533545.3344,1.701305358,856.0893602
125.6,255.6984169,11.80384874,535130.6945,1.703488164,859.9400407
125.8,256.7669689,11.80377584,537790.3749,1.70348813,864.5085466
126,257.5091067,11.80372529,537694.4125,1.710473194,868.5682191
126.2,258.3370115,11.80366887,536770.4532,1.718767958,871.6310371
126.4,258.5787034,11.80365259,535991.4335,1.727499309,874.860162
126.6,259.2908644,11.8036041,536174.4177,1.735357509,878.7786763
126.8,259.8198339,11.80356815,536707.3006,1.740596307,881.7933366
127,260.2859354,11.80353651,539743.7867,1.740596292,885.8781707
127.2,260.6271336,11.80351341,543154.6471,1.739286578,890.0768002
127.4,261.1323715,11.80347909,544552.5604,1.740596265,892.7194176
127.6,261.501881,11.80345406,543908.6735,1.750200747,896.5843026
127.8,261.8514061,11.80343039,539565.6057,1.768973156,899.4304464
128,262.0318953,11.80341831,533950.0901,1.78992841,901.1899989
128.2,262.5604484,11.80338239,528362.1952,1.811320219,903.1443381
128.4,262.6884782,11.80337389,525716.8753,1.823107548,905.0297268
128.6,263.1654047,11.8033415,525261.6386,1.828346347,907.0672273
128.8,263.2043368,11.80333911,528127.1425,1.824853803,910.0939118
129,263.5538618,11.80331545,532442.8048,1.817432137,913.3788475
129.2,263.3554776,11.8033293,535376.4371,1.8139396,916.0389524
129.4,264.2995424,11.80326493,536912.1358,1.815249272,918.5929495
129.6,264.2585365,11.80326801,537063.0214,1.820488088,920.9685559
129.8,264.2666591,11.80326772,535972.6279,1.829219446,923.3113365
130,264.8501697,11.80322804,534814.2805,1.837950784,925.6245903
130.2,264.845802,11.80322861,534697.4644,1.841879895,927.4421299
130.4,264.9854894,11.80321931,535762.4009,1.842316458,929.6098378
130.6,265.1534883,11.80320808,537919.1619,1.840570181,932.5271004
130.8,265.4705385,11.80318664,540872.2835,1.835767924,934.9399223
131,265.3204502,11.80319719,545308.9789,1.827909707,938.199676
131.2,265.5833756,11.80317946,549003.6744,1.821797748,940.9462414
131.4,265.680596,11.80317307,552826.8966,1.815685795,943.8328626
131.6,265.5488269,11.80318237,555670.2646,1.813939528,947.3431993
131.8,265.9566401,11.80315471,554841.641,1.820488032,949.3533429
132,266.1845926,11.80313937,550080.4892,1.838823875,951.2343579
132.2,266.1777268,11.80314012,546824.2146,1.851484344,952.57809
132.4,266.2866048,11.80313293,540786.1702,1.873312734,953.8485129
132.6,266.3904867,11.80312609,538418.2551,1.882917224,954.934008
132.8,266.4427418,11.80312278,537635.2972,1.888156036,956.610395
133,266.31014,11.80313213,538638.7078,1.887719473,958.2003305
133.2,266.7687473,11.803101,539166.8797,1.889465729,960.0386765
133.4,266.8309947,11.80309701,540688.0923,1.887719455,961.7413253
133.6,266.8949075,11.80309291,541041.6942,1.889902292,963.2502931
133.8,267.10121,11.80307905,541515.9463,1.892521692,964.9485677
134,267.0152388,11.80308521,543190.3571,1.890775424,966.5122402
134.2,267.0275249,11.80308464,545308.2526,1.888592585,968.5355022
134.4,267.3912056,11.80306001,546428.0743,1.888592572,970.1353012
134.6,267.5009163,11.80305276,546188.571,1.892958247,971.8532726
134.8,267.5565022,11.80304923,545589.2716,1.897323924,973.0284918
135,267.7877854,11.80303366,542019.5519,1.910857519,973.9028028
135.18,267.7588738,11.80303589,539305.1448,1.920898581,974.4499268
136,267.6260425,11.63848599,1.7977E+308,1.899506762,0
136.2,267.5129893,11.52052977,1.7977E+308,1.785125987,0
136.4,267.4340764,11.40257121,1.7977E+308,1.596528673,0
136.6,266.8039236,11.2846504,1.7977E+308,1.347685008,0
136.8,266.8182718,11.16668546,1.7977E+308,1.033356144,0
137,266.7277012,11.0487277,1.7977E+308,0.675807061,0
137.2,266.3989817,10.93078624,1.7977E+308,0.413866342,0
137.4,266.1335465,10.81284046,1.7977E+308,0.208679444,0
137.6,265.767356,10.69490157,1.7977E+308,0.067231453,0
137.8,265.9657284,10.57692403,1.7977E+308,0.020082122,0
138,265.4563154,10.45899495,1.7977E+308,0.018772419,0
138.2,265.3457603,10.34103855,1.7977E+308,0.018335851,0
138.4,265.0153754,10.22309722,1.7977E+308,0.017899283,0
138.6,264.8481974,10.1051447,1.7977E+308,0.006985086,0
138.8,264.6843503,9.987191959,1.7977E+308,0.011787333,0
139,264.3639576,9.869249936,1.7977E+308,0.029250049,0
139.2,264.0202497,9.75130951,1.7977E+308,0.044966493,0
139.4,264.0445901,9.633343882,1.7977E+308,0.054570987,0
139.6,263.6950534,9.515403854,1.7977E+308,0.055007555,0
139.8,263.764359,9.397435147,1.7977E+308,0.051515012,0
140,263.3756859,9.2794978,1.7977E+308,0.040600815,0
140.2,263.0261491,9.161557773,1.7977E+308,0.023574667,0
140.4,263.1237662,9.043587127,1.7977E+308,0.009167926,0
140.6,262.7808909,8.925646644,1.7977E+308,0.005238815,0
140.8,262.3639064,8.807711235,1.7977E+308,0.007421654,0
141,262.2050553,8.689758151,1.7977E+308,0.004802247,0
141.2,262.0695196,8.57180347,1.7977E+308,0.004802247,0
141.4,261.7233135,8.453863214,1.7977E+308,0.011350766,0
141.6,261.4703686,8.335916573,1.7977E+308,0.01266047,0
141.8,261.4838842,8.217951686,1.7977E+308,0.00829479,0
142,261.4016405,8.099993356,1.7977E+308,0.006548519,0
142.2,261.1595205,7.982045974,1.7977E+308,0.009167926,0
142.4,260.8091511,7.864106004,1.7977E+308,0.017462717,0
142.6,260.1973173,7.746183937,1.7977E+308,0.019645557,0
142.8,260.2274866,7.62821791,1.7977E+308,0.026194076,0
143,260.1302545,7.510260606,1.7977E+308,0.038854545,0
143.2,259.5812887,7.392334235,1.7977E+308,0.045403065,0
143.4,259.5610803,7.274371657,1.7977E+308,0.044966497,0
143.6,259.2019676,7.156432285,1.7977E+308,0.03798141,0
143.8,258.9852447,7.038483164,1.7977E+308,0.020518693,0
144,258.7443738,6.920535696,1.7977E+308,0.006548519,0
144.2,258.4502108,6.802591877,1.7977E+308,0.012223902,0
144.4,258.4021073,6.684631209,1.7977E+308,0.022264965,0
144.6,258.2024545,6.566680919,1.7977E+308,0.029250052,0
144.8,257.678053,6.448752865,1.7977E+308,0.030559756,0
145,257.6740821,6.330789176,1.7977E+308,0.034488868,0
145.2,257.2329495,6.212855421,1.7977E+308,0.03623514,0
145.4,257.2439669,6.094890705,1.7977E+308,0.037544844,0
145.6,256.8336438,5.97695484,1.7977E+308,0.03841798,0
145.8,256.8971207,5.858986532,1.7977E+308,0.04060082,0
146,256.2594735,5.741066233,1.7977E+308,0.036671709,0
146.2,256.120607,5.62311178,1.7977E+308,0.032306029,0
146.4,255.9234522,5.505161318,1.7977E+308,0.026194078,0
146.6,255.4714946,5.387228304,1.7977E+308,0.022701534,0
146.8,255.1827441,5.269284115,1.7977E+308,0.015716447,0
147,254.8864993,5.151340439,1.7977E+308,0.014843311,0
147.2,254.7851038,5.03338342,1.7977E+308,0.018335855,0
147.4,254.5646337,4.915434555,1.7977E+308,0.027067214,0
147.6,254.2942023,4.797489111,1.7977E+308,0.034052302,0
147.8,253.9854673,4.67954629,1.7977E+308,0.037981414,0
148,253.7000475,4.561601873,1.7977E+308,0.040600822,0
148.2,253.2597475,4.44366806,1.7977E+308,0.041037391,0
148.4,253.0026391,4.325721704,1.7977E+308,0.037108279,0
148.6,252.9504408,4.207171496,1.7977E+308,0.032742599,0
148.8,252.8448818,4.089214762,1.7977E+308,0.031432895,0
149,252.4095094,3.971870434,1.7977E+308,0.02837692,0
149.2,252.3456535,3.853321024,1.7977E+308,0.023138104,0
149.4,251.8336737,3.735981941,1.7977E+308,0.01746272,0
149.6,251.6023786,3.618033817,1.7977E+308,0.013533608,0
149.8,251.1579152,3.50010029,1.7977E+308,0.016153016,0
150,250.9924026,3.382147662,1.7977E+308,0.020518696,0
150.2,250.7411231,3.264200906,1.7977E+308,0.019208992,0
150.4,250.5639528,3.146249077,1.7977E+308,0.016589584,0
150.6,250.1802757,3.028311387,1.7977E+308,0.01309704,0
150.8,249.7899371,2.910374154,1.7977E+308,0.013970177,0
151,249.6360821,2.792420727,1.7977E+308,0.016589585,0
151.2,249.2832145,2.674480928,1.7977E+308,0.018772425,0
151.4,248.7904551,2.556550708,1.7977E+308,0.022264969,0
151.6,248.296863,2.438620545,1.7977E+308,0.028376922,0
151.8,248.5002316,2.320642658,1.7977E+308,0.034052306,0
152,248.0282894,2.202711013,1.7977E+308,0.037544851,0
152.2,247.795329,2.084763003,1.7977E+308,0.034925443,0
152.4,247.6989296,1.966805642,1.7977E+308,0.02663065,0
152.6,247.0429631,1.848886598,1.7977E+308,0.011787337,0
152.8,246.7725317,1.730941154,1.7977E+308,0.00218284,0
153,246.6186767,1.612987727,1.7977E+308,0.010477633,0
153.2,246.0484772,1.49506281,1.7977E+308,0.021828402,0
153.4,245.8479916,1.377112577,1.7977E+308,0.028813491,0
153.6,245.1828656,1.259194159,1.7977E+308,0.033179172,0
153.724,245.1072269,1.186061682,1.7977E+308,0.0314329,0
229,243.8334163,1.031127978,1.7977E+308,0.011787338,0
229.2,243.5904636,0.913180653,1.7977E+308,0.0205187,0
229.4,243.1160233,0.795249178,1.7977E+308,0.02270154,0
229.6,242.8172804,0.677305673,1.7977E+308,0.013970179,0
229.8,242.4177821,0.559369067,1.7977E+308,0.005238817,0
230,241.8750613,0.441442268,1.7977E+308,0.005238817,0
230.2,241.0517242,0.323534684,1.7977E+308,0.011350771,0
230.4,240.8454098,0.20558485,1.7977E+308,0.010914203,0
230.6,239.8051572,0.087692119,1.7977E+308,0.004365681,0
230.738,239.1170641,0.006344102,1.7977E+308,0.004365681,0