File: GB3_Loc1_10um_250nm_test39.csv
Time On Sample,Displacement Into Surface,Load On Sample,Harmonic Contact Stiffness,Harmonic Displacement,Harmonic Load
0,0,0,-40.34450999,0.536983197,2.147966992
0.2,0.153601207,0.000680266,1935.628801,0.348820791,2.217997514
0.4,0.062389781,0.001377296,6074.401533,0.247099585,2.291310692
0.6,0.208496724,0.002058076,11527.94834,0.191654978,2.381037292
0.79,0.042947921,0.002725656,15067.59079,0.168080106,2.470763871
1,0.040230388,0.003445291,17193.75942,0.15105381,2.557207778
1.2,0.190501478,0.004120054,19344.206,0.137083515,2.646934378
1.4,0.216700859,0.004803312,22536.09794,0.125296079,2.804503021
1.6,0.361143076,0.005478474,27537.17419,0.113945214,3.071494351
1.8,0.14336252,0.006178439,30044.45948,0.113945215,3.320978016
2,0.613388486,0.00683473,30768.89731,0.119184074,3.560613719
2.2,0.20492054,0.007547752,31345.14599,0.124859507,3.805720456
2.4,0.956398557,0.008177924,33120.7898,0.132717796,4.270766902
2.6,0.453003267,0.008897447,35772.20577,0.137520086,4.79161874
2.8,0.793129049,0.009559209,39495.74478,0.137956657,5.331072567
3,0.81308321,0.010242895,42701.96477,0.140139515,5.867243659
3.2,0.873006779,0.010923845,42923.81409,0.151926951,6.392472492
3.4,0.745157396,0.011617652,43653.18685,0.166333818,7.108096743
3.6,1.004928011,0.012284917,44166.13213,0.184669828,7.971441681
3.8,0.959931882,0.01297305,43625.01231,0.206498413,8.79648864
4,0.885375044,0.013663208,43283.96777,0.227453855,9.611687536
4.2,0.774179581,0.014355874,43372.33319,0.24666301,10.44329977
4.4,0.963587382,0.015027957,43919.74726,0.264562449,11.34494265
4.6,1.098869941,0.015703746,44263.85215,0.287700748,12.43807521
4.8,0.735367584,0.016413689,43551.6154,0.318260769,13.55199785
5,0.956417834,0.017083606,42251.29775,0.353623076,14.63090551
5.2,0.997605743,0.017765838,40534.84954,0.392914528,15.61789802
5.4,0.724867252,0.018469566,39279.1028,0.43133284,16.63334031
5.6,0.637819974,0.019160579,37791.57199,0.478482584,17.7669591
5.8,0.460008828,0.019857807,35938.3112,0.534363764,18.86118568
6,0.527843011,0.020538215,33684.33483,0.601595805,19.87006277
6.2,0.416647547,0.021230881,31635.21317,0.663588988,20.56380242
6.4,0.264649978,0.021926341,28572.5352,0.769675914,21.50374307
6.6,0.759657222,0.022577499,26120.0343,0.871397113,22.22046186
6.8,0.362847021,0.023289723,24286.85181,0.959148032,22.7325597
7,0.376555962,0.023973836,22294.95288,1.070473816,23.30812293
7.2,0.347797405,0.024660858,21122.45442,1.149056723,23.72502329
7.4,0.826983424,0.025313099,20121.86544,1.226766476,24.16599703
7.6,0.6866436,0.026007761,19422.61384,1.293125378,24.64089131
7.8,0.742820038,0.026688967,19272.41497,1.324995111,25.06216859
8,0.450929537,0.027394006,19478.95732,1.3407117,25.63007206
8.2,0.578717833,0.028070308,19794.47052,1.343767698,26.10496651
8.4,0.665704024,0.028749405,20306.67425,1.338092264,26.66192802
8.6,0.711055413,0.029431352,20905.52259,1.32936083,27.27141233
8.8,0.589867598,0.030124702,21319.11265,1.329797404,27.85791766
9,0.502820319,0.030815715,21444.22224,1.340275127,28.30326784
9.2,0.67973768,0.031488654,21390.95525,1.363849995,28.81427188
9.4,0.6767927,0.032173908,21129.24869,1.394410014,29.18083782
9.6,1.145986365,0.032826833,20897.35896,1.421914019,29.51020053
9.8,1.08974884,0.033515736,20569.52498,1.458586044,29.86472993
10,0.791196772,0.034221232,20360.77841,1.486526641,30.1382863
10.2,0.99809119,0.034892117,20249.27201,1.512720938,30.49172173
10.4,0.967667241,0.035579253,20281.81407,1.524944945,30.80795322
10.6,1.09462284,0.036255612,20286.24949,1.541098095,31.13512714
10.8,1.339821274,0.036923875,20296.36628,1.552012381,31.38132841
11,1.23945086,0.0376158,20284.29277,1.568602109,31.70193673
11.2,1.171555591,0.038305502,20274.20655,1.581699261,31.94047807
11.4,1.521673722,0.03896658,20300.52884,1.597415833,32.19543328
11.6,1.490417077,0.039653773,20499.9442,1.603527837,32.50072257
11.8,1.362567695,0.04034758,20857.02154,1.594796406,32.77537333
12,1.800951602,0.041002615,21664.9915,1.56030723,33.2075933
12.2,1.506563018,0.041707825,22538.16726,1.520142643,33.61245695
12.4,1.682647681,0.042380821,23905.03052,1.455530027,34.14862827
12.6,1.618083196,0.043070294,25628.09134,1.382185984,34.79422197
12.8,1.916574172,0.043734908,27126.98258,1.325868229,35.35337214
13,1.698793621,0.044434872,28739.47634,1.275662489,36.03069825
13.2,1.669202369,0.045121951,29917.04952,1.248158473,36.65112475
13.4,1.936883592,0.045788675,30345.30635,1.251214469,37.18620195
13.6,1.856497884,0.046479231,30513.08044,1.26125562,37.61951562
13.8,1.781108351,0.047169446,30422.61193,1.284393922,38.12614251
14,1.763174843,0.047855727,30193.23951,1.312334511,38.61197918
14.2,1.846830248,0.048535051,29988.31381,1.334599665,38.96979142
14.4,1.926322173,0.04921466,29989.5017,1.352935674,39.49830302
14.6,1.912552145,0.049900656,30119.43252,1.360357394,39.90863801
14.8,1.902112901,0.050586423,30416.87584,1.363413396,40.41417086
15,1.998258746,0.051264892,30863.51042,1.360793963,40.94815364
15.2,1.792968636,0.051964002,31331.10424,1.354681965,41.39788045
15.4,1.960726338,0.052637567,31804.30199,1.350316244,41.8946596
15.6,1.847032789,0.053330405,32059.15372,1.357301394,42.44396132
15.8,1.764981688,0.054021076,32114.56217,1.370398547,42.93964589
16,1.771196365,0.054705703,32070.15987,1.384368841,43.33466175
16.2,1.779909129,0.055390159,31939.32425,1.403577995,43.7865774
16.4,1.791952677,0.056074386,31876.07751,1.419294576,44.22098545
16.6,1.777349953,0.056760439,31868.6407,1.434138014,44.67837219
16.8,1.725275908,0.057449057,31910.48241,1.444615736,45.05588031
17,1.99129174,0.058115894,32081.59691,1.453347163,45.535152
17.2,2.097429937,0.058793679,32232.37734,1.461642023,45.9969159
17.4,2.227716318,0.05946981,32459.47248,1.466007737,46.44226638
17.6,1.959974008,0.060173196,32651.54616,1.469500317,46.82305696
17.8,2.225157143,0.060840091,32841.50282,1.475612314,47.29248062
18,2.093144282,0.061534183,32871.18331,1.487836325,47.73564224
18.2,1.967792989,0.062227819,32870.60412,1.498750621,48.07266389
18.4,2.237139603,0.062894428,32730.11528,1.519269483,48.52457992
18.6,2.383247208,0.063569476,32707.14355,1.530183771,48.84737706
18.8,1.958958049,0.064283581,32750.32092,1.540661504,49.25771135
19,2.446471017,0.064935252,32859.15776,1.545463779,49.59692248
19.2,2.185390276,0.065638181,33138.67016,1.544590643,50.02695318
19.4,2.21075696,0.066321497,33444.00855,1.542407784,50.43619402
19.6,2.260271829,0.067003159,33779.50369,1.540224924,50.88373277
19.8,2.220688224,0.067690922,34154.51073,1.536732352,51.3487791
20,2.18360231,0.068381938,34541.52117,1.53323978,51.797412
20.2,2.355523491,0.069055218,34800.87474,1.532803203,52.16178986
20.4,2.247659213,0.069744233,35170.59656,1.529310633,52.59729186
20.6,2.487861466,0.070412838,35564.64187,1.526691196,53.10610771
20.8,2.255508465,0.071116143,35922.96343,1.524071773,53.55036329
21,2.251313386,0.071810554,36147.09081,1.526254631,53.9782059
21.2,2.453626098,0.072497859,36437.95472,1.526691198,54.45638345
21.4,2.472744881,0.073204658,36638.33699,1.530620342,54.89626261
21.6,2.504769624,0.073917693,36708.56265,1.53804206,55.25298055
21.8,2.581759114,0.074634845,36715.04076,1.550266066,55.69614251
22,2.637930363,0.075360646,36866.80673,1.555941496,56.11960842
22.2,2.440961184,0.076111043,36920.31232,1.565546079,56.53213148
22.4,2.80939172,0.076830196,37017.57994,1.572531216,56.93480759
22.6,2.58993801,0.077597089,37165.44175,1.576023796,57.28386556
22.8,2.6685886,0.078351033,37413.1846,1.578206652,57.73031028
23,2.732249771,0.079113652,37604.26017,1.582135795,58.15705884
23.2,2.82172363,0.079882147,37875.96039,1.580826078,58.51815397
23.4,2.773801741,0.080667857,38292.3349,1.577770078,59.04338259
23.6,3.08477094,0.081436617,38719.44144,1.570784922,59.4548124
23.8,2.876969603,0.082248894,39225.92459,1.562926638,59.95377951
24,2.945622404,0.083050268,39735.75425,1.555504917,60.45931235
24.2,3.066734115,0.08385611,40160.12845,1.55157577,60.96922216
24.4,2.879747347,0.084691306,40465.98992,1.551575774,61.43207967
24.6,3.109107618,0.085506233,40623.4471,1.555504913,61.82053078
24.8,2.972913383,0.086354487,40639.11292,1.566855781,62.28995382
25,3.254731565,0.087182471,40663.13191,1.576896922,62.72764504
25.2,3.082729428,0.088050154,40687.80526,1.584755217,63.07560889
25.4,3.068105843,0.088915576,40643.16789,1.596106081,63.46187086
25.6,3.357415289,0.089768839,40670.20622,1.60571065,63.89409108
25.8,3.108802116,0.090667603,40866.97242,1.608766659,64.33396968
26,3.298185995,0.09154531,41077.22715,1.609639798,64.70710128
26.2,3.289387198,0.09244545,41431.76616,1.607456939,65.18856113
26.4,3.491259444,0.093340125,41919.02638,1.600035217,65.66236189
26.6,3.619020698,0.094248894,42516.31114,1.589994065,66.18540237
26.8,3.759271308,0.095166125,43095.92043,1.579079768,66.63184721
27,3.444868838,0.096123692,43663.53008,1.571221486,67.18224256
27.2,3.883222452,0.097039075,44226.08844,1.563799757,67.74029923
27.4,3.926044364,0.097991063,44639.94253,1.561180325,68.25896283
27.6,3.704900552,0.098970568,44974.11907,1.561616902,68.79513344
27.8,3.52788848,0.099956904,45150.7851,1.565109482,69.22625837
28,3.806359982,0.100921771,45355.45669,1.569911762,69.74820521
28.2,3.798382916,0.101916135,45323.33533,1.579952911,70.12571343
28.4,4.012734543,0.102905029,45338.14944,1.592176913,70.67501579
28.6,3.981439665,0.103920973,45426.58885,1.597852345,71.05361818
28.8,3.999272683,0.104943585,45502.76115,1.606147207,71.53398378
29,3.987127445,0.105978578,45610.82237,1.613132353,72.02200911
29.2,3.892544096,0.107029605,45941.44411,1.610076354,72.43562658
29.4,3.988646907,0.108078066,46176.93805,1.610949494,72.88754264
29.6,4.144702597,0.109133008,46145.2045,1.620990639,73.34274118
29.8,3.981834486,0.11022045,45960.12189,1.636270652,73.78043153
30,4.048789204,0.111303007,45977.14739,1.644128941,74.21374544
30.2,4.069111686,0.112399606,45965.22254,1.651550659,74.55295589
30.4,4.115246455,0.113505501,46043.95052,1.657226089,74.96219697
30.6,4.15138758,0.114623201,46314.14133,1.657226088,75.42177208
30.8,4.490628738,0.115731352,46801.51805,1.651114075,75.92730584
31,4.356897275,0.116883106,47048.09284,1.651550651,76.31794445
31.2,4.540421647,0.118024597,47177.35145,1.657662649,76.76220094
31.4,4.67398293,0.119180939,47286.693,1.663338077,77.16378253
31.6,4.372042854,0.120378839,47441.38974,1.668140374,77.61241481
31.8,4.436487609,0.12156367,47451.17989,1.674688948,77.94724845
32,4.461794275,0.12276303,47521.54455,1.68080095,78.37071422
32.2,4.74440259,0.123956866,47794.97432,1.679927799,78.81497104
32.4,4.624817351,0.12519027,48032.68751,1.679927802,79.22858851
32.6,5.036490709,0.126399612,48505.16838,1.673379215,79.72536857
32.8,4.711226705,0.127671693,49106.20139,1.662028361,80.17290636
33,4.808138072,0.128927642,49941.60064,1.645438635,80.7561295
33.2,5.043275526,0.13018655,50729.9774,1.631468335,81.34810678
33.4,4.994462168,0.13147767,51418.50306,1.620554044,81.91491638
33.6,5.600979029,0.132736871,51751.36537,1.619244312,82.36683373
33.8,5.423094809,0.134062526,51921.55517,1.624919749,82.89534458
34,5.62158762,0.13537568,52066.03251,1.631468318,83.41072613
34.2,5.526137225,0.136722136,52221.07594,1.635397466,83.83090906
34.4,5.643022731,0.138067546,52621.9685,1.633214604,84.33972466
34.6,5.641663824,0.139434687,53202.92262,1.627102601,84.94811496
34.8,5.742724941,0.140808397,53856.07805,1.61706145,85.47006138
35,5.832959396,0.14219672,54656.98976,1.605274013,86.11237284
35.2,5.749991463,0.143610915,55506.01663,1.592613437,86.77766244
35.4,5.706158593,0.145036589,56179.49351,1.584755148,87.39918329
35.6,5.97458506,0.14645504,56995.50039,1.575150564,88.11590271
35.8,5.793354019,0.14791883,57334.96818,1.575587141,88.65973277
36,6.042625102,0.149367624,57480.68128,1.582572281,89.26921797
36.2,6.125355282,0.150842549,57578.48357,1.59086714,89.87651407
36.4,5.994080869,0.152347021,57706.00247,1.596979147,90.43456951
36.6,6.19005423,0.153844005,58000.45399,1.599598572,91.06265625
36.8,6.169524885,0.155370939,58475.08439,1.596105999,91.60320427
37,6.044906758,0.156920366,59393.10475,1.584318568,92.35712607
37.2,6.339131976,0.15846449,60065.89222,1.5790797,93.07384568
37.4,6.177872516,0.160039746,60247.45339,1.585191708,93.69427186
37.6,6.124860779,0.161631229,60059.51847,1.598288859,94.18120253
37.8,6.185092903,0.163238942,59798.74529,1.614005438,94.74144695
38,6.287792523,0.164843726,59366.91859,1.631904873,95.15615914
38.2,6.253094498,0.166482102,59178.59148,1.644565452,95.70655519
38.4,6.706354393,0.168103448,59353.59702,1.647184869,96.24491632
38.6,6.517187431,0.169785412,59943.62759,1.641509443,96.9014518
38.8,6.306368426,0.171485605,60403.92383,1.640199734,97.53938542
39,6.394901626,0.173182395,60866.79788,1.63714373,98.0449185
39.2,6.62998735,0.174886033,61062.86819,1.643255727,98.63908438
39.4,6.682710642,0.176619515,61274.80279,1.647621442,99.18400979
39.6,6.727937639,0.178370978,61341.76347,1.655916302,99.76066722
39.8,8.376102311,0.180029829,61378.69433,1.663774543,100.2935614
40,8.39467906,0.181817315,61497.23416,1.667703687,100.7597022
40.2,8.646408577,0.183606795,62025.38767,1.66246482,101.3812239
40.4,8.610023217,0.185433969,62633.59762,1.655043103,101.9939908
40.6,8.845094607,0.187260771,63682.48545,1.638016802,102.7413488
40.8,8.994396179,0.189111835,65506.64754,1.604837353,103.6539346
41,8.968829444,0.190993488,67279.69968,1.574277339,104.4702276
41.2,9.132282482,0.192881103,69645.86837,1.536295602,105.5567957
41.4,9.290737152,0.194787903,71898.63421,1.502679581,106.6050658
41.6,9.060320579,0.196740716,74298.93698,1.470373286,107.7802646
41.8,9.202949504,0.19868749,75878.41244,1.452473845,108.7158294
42,9.458822796,0.200646085,77452.36102,1.438066975,109.8746166
42.2,9.275030358,0.202654482,78381.84357,1.433264692,110.8112742
42.4,9.169508979,0.204677779,79003.56254,1.435884124,111.8310933
42.6,9.287980455,0.206705891,79272.17473,1.445925269,112.9231323
42.8,9.425601559,0.208753133,79323.35771,1.456839556,113.7799127
43,9.886306293,0.210798714,79443.56349,1.46906355,114.8336552
43.2,9.740805993,0.21290659,79478.10397,1.479541273,115.6510421
43.4,9.916723863,0.215013501,79770.47458,1.486526415,116.6063028
43.6,9.789537952,0.217162439,80242.56917,1.491765279,117.7136601
43.8,9.739790254,0.219327607,80481.05264,1.497877283,118.5748167
44,10.10805338,0.221485799,80541.08944,1.509228136,119.5826012
44.2,10.61870498,0.223655916,80731.92128,1.515776696,120.4087445
44.4,10.84623744,0.225867246,80868.93403,1.524071551,121.3038231
44.6,10.72070424,0.228125124,80939.32185,1.535422417,122.3192653
44.8,11.03066836,0.230375692,81114.76252,1.542407554,123.1311831
45,11.12163084,0.232663945,81770.88914,1.542844124,124.1761703
45.2,11.24506577,0.234973005,82470.5637,1.54022469,125.0362333
45.4,10.97879632,0.237332041,83284.32432,1.537605268,126.0385441
45.6,11.53522767,0.239658211,84545.46007,1.529310391,127.2476674
45.8,11.34722616,0.242058996,85487.11015,1.523634966,128.1930788
46,11.4523308,0.244463694,86375.89621,1.521888678,129.3770329
46.2,11.3817338,0.246904646,86828.91338,1.524071537,130.265545
46.4,11.47184426,0.249359062,87218.86337,1.528437251,131.2809883
46.6,11.63689448,0.251832967,87628.22939,1.533676106,132.4014773
46.8,11.94100203,0.254322177,88209.91766,1.5367321,133.5318153
47,11.87955315,0.256861597,88799.57781,1.536732101,134.4214218
47.2,11.90719978,0.259420359,89784.90527,1.53411267,135.5966218
47.4,12.02310918,0.261998776,91061.46746,1.526254378,136.7203934
47.6,12.42546296,0.264583411,92331.9769,1.517959506,137.8080571
47.8,12.14167229,0.267241218,93713.68227,1.510537797,139.1594261
48,12.09436416,0.269909409,94771.13932,1.505298939,140.2208264
48.2,12.46423355,0.272575753,95553.28656,1.506608644,141.5196757
48.4,12.71252622,0.275277294,95407.62788,1.519705785,142.5756062
48.6,12.75097636,0.278020465,94956.23351,1.536295506,143.4652131
48.8,12.99509919,0.280776915,94401.2573,1.556377793,144.4773743
49,13.18759164,0.283564725,93510.13466,1.581698941,145.4085624
49.2,12.9862157,0.286407535,93014.29622,1.59872524,146.1559186
49.4,13.1154167,0.28925617,92840.63998,1.611385813,146.974401
49.6,13.25877019,0.292132553,92964.25045,1.620990384,147.9799963
49.8,13.2247561,0.29504992,93061.36059,1.628412103,148.7678398
50,13.39308371,0.297982676,93823.81917,1.627102383,149.8412772
50.2,13.71795472,0.300934115,94633.47892,1.622736658,150.7177552
50.4,13.78885003,0.303932715,95612.57755,1.617061225,151.7747789
50.6,13.9072055,0.30695819,96653.4832,1.610949219,152.9182468
50.8,13.91897236,0.310021428,97649.4429,1.603527502,153.8866381
51,13.87661041,0.313119136,98468.11255,1.601344645,155.0749684
51.2,14.2039618,0.316222596,98637.3891,1.606583495,155.9536347
51.4,14.37975892,0.319367597,98847.82802,1.612695492,156.9515707
51.6,14.35986883,0.322557742,99417.13855,1.614441779,158.0468917
51.8,14.40159451,0.32577567,99830.20815,1.617061208,158.9485353
52,14.64149805,0.329012292,100372.6597,1.619244059,160.0515177
52.2,15.09123714,0.332267104,101259.3607,1.61487833,161.0199109
52.4,15.64172865,0.335547522,102099.6841,1.612258884,162.0988222
52.6,15.80084926,0.338887891,102308.3468,1.619244025,163.1656947
52.8,15.86420595,0.342268391,102518.1728,1.624482883,164.0224749
53,16.25647355,0.345660219,103104.3113,1.626665729,165.1615677
53.2,16.082504,0.349125156,103674.5983,1.627102306,166.082906
53.4,15.97764418,0.352620014,104496.9238,1.625356023,167.1454001
53.6,16.33908993,0.356117933,105800.3895,1.618807439,168.421271
53.8,16.53649052,0.359662325,106800.1801,1.614005146,169.4268673
54,16.60148832,0.363251493,107452.7345,1.616624573,170.6294228
54.2,16.73059949,0.366872363,107437.6055,1.625356001,171.4763553
54.4,16.51746846,0.370553117,107800.8341,1.629721723,172.5005513
54.6,16.70819062,0.374242887,108399.0134,1.631904576,173.6910715
54.8,16.95386641,0.37796578,108745.4179,1.63496057,174.592716
55,16.91558637,0.381764588,109706.5514,1.631467998,175.8324757
55.2,17.08131457,0.385568612,110973.913,1.62229999,176.9146675
55.4,16.96225859,0.389411226,111721.4248,1.621426851,178.0471915
55.6,17.1642001,0.393289778,111987.5912,1.627975419,179.2147332
55.8,17.46356247,0.397200721,112261.2205,1.634523984,180.3330354
56,17.30826835,0.401182281,111879.3237,1.648057707,181.1537047
56.2,17.61386672,0.405172083,110929.0558,1.67075942,182.0236176
56.4,17.53184053,0.409228553,109978.1096,1.69215143,182.7523725
56.6,17.63425174,0.413312944,109499.3226,1.705685146,183.4078147
56.8,17.67670407,0.417442599,109087.1303,1.719655435,184.2427107
57,17.60007608,0.421621833,109309.0947,1.72314801,184.973654
57.2,17.89898902,0.425817269,110381.0538,1.716162856,186.0044179
57.4,17.95641526,0.430071568,111662.8313,1.706121708,187.0253324
57.6,18.2961204,0.434349196,112688.1799,1.699136553,187.9269781
57.8,18.2702671,0.438694904,113862.3948,1.692151408,189.059503
58,18.37264387,0.443075394,114648.0801,1.688222261,189.9348856
58.2,18.79893419,0.447477642,115071.6992,1.690841678,190.9798754
58.4,19.80394295,0.451884203,115228.701,1.696080506,191.914352
58.6,19.97042188,0.45639279,115707.2737,1.696080501,192.7908294
58.8,20.33008098,0.460933271,116489.1765,1.693897632,193.8927185
59,20.10934583,0.465559247,117124.3268,1.692151353,194.7746645
59.2,20.61055251,0.470181936,118179.5484,1.687349051,195.9520567
59.4,20.74453495,0.474876427,119317.8452,1.681237045,197.027683
59.6,21.04338567,0.479606695,120480.1539,1.676434749,198.27401
59.8,20.79098625,0.484422485,121209.5074,1.674251899,199.2084781
60,21.34546341,0.489231124,122313.2934,1.669886167,200.473409
60.2,21.58517594,0.494109766,123685.0228,1.660281586,201.5534128
60.4,21.9181447,0.499031052,125215.1826,1.649803859,202.831473
60.6,22.09955708,0.504012097,126776.1961,1.64019928,204.2977386
60.8,22.03365301,0.509060162,128368.5089,1.629284993,205.5123311
61,21.98023348,0.514158072,129992.2655,1.620553564,207.0486263
61.2,22.09084905,0.519295962,130815.4212,1.619243846,208.1866234
61.4,22.04241373,0.524496441,131564.3798,1.620990134,209.4996962
61.6,22.44112994,0.529718424,132104.2286,1.626228981,210.8751425
61.8,22.60085637,0.535009312,131964.3145,1.636270122,211.8665137
62,22.83468653,0.540348314,131564.1178,1.651113548,213.0351507
62.2,22.91113098,0.545751613,131299.1438,1.661591262,213.9127213
62.4,23.05251936,0.551204945,130851.8718,1.675124975,214.9336366
62.6,23.34045584,0.556702794,130768.7895,1.684729542,216.0650699
62.8,23.47100638,0.562266823,130734.7346,1.691714682,216.9492067
63,23.40753233,0.567899997,131031.7761,1.696516971,218.1178412
63.2,23.47645032,0.573580642,131220.8277,1.700882683,219.0304274
63.4,23.52038079,0.579320127,131717.7762,1.702628968,220.0896399
63.6,23.70836092,0.585107348,132037.3813,1.70743125,221.2440513
63.8,23.97460769,0.59094737,132484.1578,1.709177528,222.1818063
64,23.98104655,0.596864001,132790.3721,1.713979815,223.2804108
64.2,24.38134359,0.602812887,133014.396,1.717908945,224.1393824
64.4,24.33863955,0.608851986,133046.8034,1.724894091,225.0760407
64.6,24.60569127,0.614930455,133598.8501,1.726640369,226.1768363
64.8,24.95184197,0.621064577,134339.2273,1.726203788,227.3367197
65,25.29465472,0.627260534,135295.7216,1.721401489,228.3105849
65.2,25.53170787,0.633526055,136448.3639,1.716162624,229.5689487
65.4,25.89532344,0.639845891,137124.6582,1.713979755,230.4388624
65.6,26.50624225,0.646212082,138029.1834,1.711360307,231.6873811
65.8,26.620867,0.652676306,138900.6836,1.709177446,232.935896
66,26.80459792,0.659200833,139640.4345,1.707431155,233.9633773
66.2,26.98582313,0.665791123,141139.3393,1.699136291,235.3267859
66.4,26.91639924,0.672464884,143017.5631,1.686912291,236.696758
66.6,27.29495782,0.67917491,144276.613,1.680800278,237.8664907
66.8,27.10144663,0.68599164,145471.8985,1.677307712,239.3305658
67,27.59323603,0.692829631,146151.2096,1.677307698,240.4324568
67.2,27.77275654,0.699757962,146571.2915,1.682109979,241.772887
67.4,27.84485122,0.706763261,146535.318,1.690404835,242.9294864
67.6,28.07431719,0.713828149,146901.6462,1.693460829,243.9635336
67.8,28.18469944,0.720972045,148153.4433,1.689968253,245.3761825
68,28.40082567,0.728180646,149151.4124,1.687348818,246.5382537
68.2,28.3654694,0.735478943,150768.8335,1.679927104,248.0450052
68.4,28.66568094,0.742827463,152064.6722,1.67556138,249.4292056
68.6,28.56868808,0.75027705,152782.124,1.675997954,250.5901802
68.8,28.69235086,0.757786302,152812.0979,1.684292809,251.9109145
69,28.89927444,0.765365249,152514.6059,1.693897376,252.9143228
69.2,29.25690707,0.773010004,151731.8975,1.71005051,254.0129301
69.4,29.60120762,0.780732572,151185.4637,1.722711072,254.9988323
69.6,29.50750124,0.788562847,150858.6146,1.731879076,255.8578006
69.8,29.65693286,0.796454934,150770.2735,1.74017393,256.9487466
70,30.06615628,0.804408559,150974.2712,1.744103061,257.8646191
70.2,30.07567649,0.812469603,151025.2662,1.750215061,258.9413395
70.4,30.92537718,0.820553835,151177.224,1.75501732,259.9447533
70.6,31.58521383,0.828732142,152076.2261,1.751524728,260.9262813
70.8,32.09682108,0.837002968,153700.9878,1.742793283,262.2918825
71,32.17958043,0.845386398,155307.0822,1.733188708,263.4605186
71.2,32.39722665,0.853844909,157751.5941,1.717472129,264.9825917
71.4,32.58738405,0.862390146,159684.9505,1.706557836,266.4149375
71.6,32.80501042,0.871019408,160156.0307,1.708740687,267.5365227
71.8,32.88606462,0.879744771,160764.2121,1.710923542,268.926193
72,32.92880463,0.88856045,160864.3183,1.716162398,269.9678978
72.2,33.04647693,0.897459615,160959.0525,1.722274395,271.1901521
72.4,33.19744666,0.906445792,161790.3969,1.720964676,272.4441386
72.6,33.80139228,0.915491236,163607.9786,1.711796657,273.9957591
72.8,34.68011149,0.924654819,164268.3151,1.71179663,275.127199
73,34.81855894,0.933915668,164972.3263,1.712669768,276.5343773
73.2,35.30422958,0.94324603,165354.9474,1.715289182,277.6439288
73.4,35.47805035,0.952644065,165649.1674,1.71921832,278.8924443
73.6,35.64352767,0.962184597,165752.4463,1.724893743,280.1661273
73.8,35.91516252,0.971813652,166104.4849,1.727513163,281.2494156
74,36.22175937,0.981536645,166486.8229,1.731442297,282.5154405
74.2,36.40094244,0.991366129,166738.3836,1.735371434,283.5472992
74.4,36.63257386,1.001290677,166464.095,1.74541257,284.5758757
74.6,36.88667644,1.011313493,166201.7603,1.755890276,285.6733881
74.8,37.24901774,1.021429486,166500.2121,1.759382836,286.6319357
75,37.41649645,1.031660547,167086.7978,1.761129117,287.8344937
75.2,37.65224425,1.041989676,167759.486,1.760255966,288.8302442
75.4,37.88964538,1.052422425,168805.7064,1.756326816,290.0393685
75.6,38.21280193,1.062954236,170158.3054,1.750214806,291.4695267
75.8,38.34026273,1.073605349,171001.2752,1.747595374,292.5933008
76,38.58928463,1.08435503,172065.5935,1.744539366,294.0048575
76.2,39.06145638,1.095197328,173239.471,1.739737066,295.1658381
76.4,39.60772538,1.106143167,174302.8446,1.73711762,296.4712575
76.6,39.85587661,1.117219398,175006.5205,1.73930047,297.866401
76.8,40.79431945,1.128359398,175221.0183,1.744102725,298.9070213
77,41.25561475,1.139644231,175068.6812,1.75327071,300.0822274
77.2,41.79267217,1.151037055,174824.598,1.761128978,300.9674637
77.4,42.23811978,1.162550521,175093.768,1.765058107,302.0551312
77.6,42.80929093,1.174171154,176625.0032,1.758072946,303.4776331
77.8,43.05819536,1.185930762,178960.9759,1.744102654,305.0938108
78,43.09308331,1.197823295,181346.3221,1.729259227,306.5458523
78.2,43.27118099,1.209825379,183190.7859,1.719654651,307.9541259
78.4,43.74320613,1.221927851,185064.6607,1.71135978,309.5724941
78.6,44.13444567,1.234157479,185933.7657,1.712232911,311.1230195
78.8,44.36995687,1.24652068,186473.0016,1.714852332,312.3748192
79,44.69371933,1.259002066,187407.787,1.715725465,313.9756794
79.2,44.60694838,1.271637013,188910.8032,1.710486612,315.378479
79.4,45.44611995,1.284335243,190410.5791,1.706120871,316.9519879
79.6,45.65742434,1.297204323,192629.1874,1.697389438,318.8220263
79.8,45.74714017,1.310210936,193959.5165,1.693896864,320.310178
80,46.14660348,1.323327014,194847.2776,1.695206567,321.9876344
80.2,46.33537955,1.336589224,195180.878,1.700445418,323.5655137
80.4,46.8505567,1.349962309,195216.2181,1.707430544,325.0317854
80.6,47.03014198,1.36349289,194526.9144,1.718344822,326.1883867
80.8,47.05483011,1.377169971,194081.3181,1.728822534,327.6294858
81,47.81060879,1.390934241,194027.566,1.734497937,328.7631148
81.2,48.32572242,1.404853404,194595.6845,1.736680777,330.3027
81.4,48.68677115,1.418922903,195307.9102,1.736244195,331.447267
81.6,49.25264648,1.433119731,197673.9544,1.726203038,333.256033
81.8,49.79352435,1.44746102,199982.3316,1.715288737,334.8459531
82,50.93642418,1.461904938,202577.113,1.704374417,336.8046352
82.2,51.39399887,1.476541081,203898.2635,1.701754976,338.3146758
82.4,51.58009779,1.491342918,204604.0627,1.704374398,339.8969326
82.6,51.64460589,1.506301808,204762.9972,1.711359537,341.5842336
82.8,52.30613906,1.521369864,204687.4415,1.719654371,343.1117846
83,52.85024456,1.536597573,204456.116,1.727512638,344.3329501
83.2,53.04626564,1.552002098,205093.6692,1.73013206,345.9338089
83.4,53.47375803,1.56754538,206115.0046,1.729258904,347.5226341
83.6,53.98033828,1.583239468,207081.4315,1.727949174,348.9035567
83.8,54.22376849,1.599109338,207667.4656,1.731005165,350.5350542
84,54.48883022,1.615137262,208375.4076,1.7318783,351.892995
84.2,55.12525531,1.63130062,209055.1652,1.733624565,353.4872934
84.4,55.45439696,1.647647478,210206.2698,1.73187827,355.0662697
84.6,55.93756813,1.664148019,211223.9155,1.730568541,356.5008088
84.8,56.45236243,1.680812134,213577.6949,1.720963957,358.4638614
85,56.77978082,1.697656633,215252.1667,1.714851949,359.9914089
85.2,57.1130084,1.714669891,217620.8392,1.706557084,362.0310557
85.4,57.67021112,1.731838638,219636.1624,1.70044507,363.9175128
85.6,57.84935014,1.749205911,221487.6185,1.696952494,366.019529
85.8,58.38069893,1.766723512,222096.0645,1.700008477,367.5230058
86,58.94117159,1.784415027,222814.643,1.703501029,369.3580337
86.2,59.76225715,1.802266436,222808.5912,1.710049573,370.7389615
86.4,60.31269591,1.820315858,222200.7687,1.721400408,372.1953872
86.6,60.77401519,1.838552734,221906.3241,1.731004961,373.8542441
86.8,61.47263128,1.856956467,221565.5907,1.738863221,375.0896366
87,61.74072246,1.875574757,221304.6962,1.747594638,376.5712264
87.2,62.46011265,1.894349088,221984.4828,1.748467757,377.9346447
87.4,62.74398135,1.913341927,223730.0134,1.742792322,379.6350801
87.6,62.99035656,1.932528199,225291.7276,1.739299745,381.4908955
87.8,63.52398918,1.951887434,227842.904,1.729695161,383.5403941
88,63.70869991,1.971465203,229771.026,1.722710016,385.1565727
88.2,64.11072121,1.991224643,231639.3058,1.718344292,387.2235761
88.4,64.72505666,2.011168014,232621.2456,1.719217415,388.9809165
88.6,65.19697792,2.031321688,233926.2647,1.717471115,390.5927216
88.8,65.76963174,2.051670904,235292.85,1.717034526,392.6236185
89,66.55126825,2.072210114,236320.452,1.717034502,394.2015078
89.2,67.2379535,2.092962238,237971.417,1.714851625,396.2838341
89.4,67.72060421,2.113936922,239511.5733,1.712668754,398.2392286
89.6,68.23903629,2.135119831,240729.7695,1.711359024,399.959364
89.8,68.79824567,2.156512821,242115.5814,1.710485865,402.0526315
90,69.27832401,2.178126149,243526.9014,1.707866423,403.8209127
90.2,69.6051612,2.199967281,245389.8981,1.703937272,406.0257894
90.4,70.26088091,2.222061056,246715.9403,1.70306411,408.0096352
90.6,70.82957099,2.244272542,248056.1602,1.701754379,409.8315348
90.8,71.40321157,2.266876278,249255.3442,1.702627503,411.999211
91,71.99808589,2.28947837,249930.2603,1.704810341,413.6766735
91.2,72.82482604,2.312406055,250501.2117,1.709612598,415.7557207
91.4,73.17773605,2.335595753,251745.1488,1.709176016,417.7450343
91.6,74.03481579,2.358983535,252953.5483,1.707866276,419.5209802
91.8,74.33146447,2.382644936,254768.5377,1.704810269,421.8090188
92,74.38743665,2.406560578,256401.7545,1.70219084,423.7031311
92.2,74.8913708,2.430685578,257834.4723,1.702190825,425.9977373
92.4,75.40277099,2.455052526,258805.2437,1.704373665,428.0056558
92.6,76.0781836,2.479653085,259393.9663,1.707866213,429.7181347
92.8,76.51208593,2.504517465,259494.4155,1.715724479,431.6888477
93,77.12165783,2.529619475,259818.8202,1.720526743,433.3422381
93.2,77.67624252,2.554977565,260399.7691,1.725329008,435.3534396
93.4,78.25577843,2.580588645,260669.2823,1.731004414,437.1873774
93.6,79.00265607,2.606445608,260778.594,1.736679815,438.7543244
93.8,79.60378189,2.632572337,261139.1692,1.741918649,440.6703306
94,80.20154645,2.658961239,261053.3927,1.748030625,442.1125334
94.2,80.94250374,2.685604999,260584.1892,1.757635165,443.8556532
94.4,81.78668407,2.712509204,260176.4003,1.76636656,445.3853982
94.6,82.40600536,2.739699011,260283.3711,1.771168822,446.7750788
94.8,83.36003817,2.767139095,261006.1997,1.773351646,448.5444635
95,83.99012064,2.794877058,261595.9212,1.77509791,449.9418052
95.2,84.35620642,2.822911884,263824.9838,1.768549333,451.9551928
95.4,85.44670392,2.851178614,265982.8797,1.762000732,453.8744888
95.6,85.95261664,2.879769421,267151.1192,1.760691004,455.511465
95.8,86.43184969,2.908649461,267997.3452,1.762437272,457.4198084
96,87.25495194,2.937796,269348.1863,1.761127532,459.4091313
96.2,87.54426278,2.967272039,269180.0406,1.767239517,460.7747351
96.4,88.34398108,2.997008975,269812.9141,1.769422347,462.4040562
96.6,89.12451263,3.027046064,271336.0762,1.767239467,464.443713
96.8,90.06904992,3.057373769,272291.4454,1.766802865,465.9964404
97,90.72710477,3.08802591,273642.4921,1.765493131,467.9781016
97.2,91.70571125,3.118964065,275383.0851,1.760690818,469.6807387
97.4,92.19049362,3.150246847,277358.7176,1.755451952,471.6864705
97.6,92.64442974,3.181846033,280412.1793,1.745847376,474.0708053
97.8,93.19741957,3.213756034,283741.0191,1.734059941,476.2155052
98,93.73122015,3.245987894,288032.6966,1.719216513,478.9653141
98.2,94.17421933,3.278549866,292483.148,1.704373084,481.7884351
98.4,95.03186241,3.311410352,295996.2995,1.694331925,484.4386747
98.6,95.90778635,3.344599851,298357.6833,1.689529618,486.7683053
98.8,96.85028707,3.378118142,300506.357,1.687346734,489.4732581
99,97.21402585,3.41201303,301064.6145,1.691712434,491.5457362
99.2,98.11148227,3.446211736,300383.1033,1.703499821,493.8698964
99.4,98.60420914,3.480781838,299655.2513,1.714414078,495.8821942
99.6,99.32089045,3.515683889,299065.2654,1.723145476,497.5509076
99.8,100.2407084,3.550922641,298810.142,1.731440295,499.7787762
100,100.8573844,3.58653634,299918.3466,1.731003703,501.6904072
100.2,101.6447212,3.622495957,302420.8484,1.725328257,504.2881238
100.4,102.336256,3.658823452,305844.3146,1.714850533,506.9044392
100.6,103.4774035,3.695485113,308763.6329,1.706992222,509.3128615
100.8,104.2054915,3.732543569,310274.3458,1.707865341,511.9631004
101,105.0184711,3.769968591,309643.4259,1.717469875,513.8134582
101.2,105.8730417,3.807766679,308463.6934,1.730566975,515.9165847
101.4,106.7891875,3.845940261,306417.0346,1.747156639,517.5885851
101.6,107.4329976,3.884516014,305555.7326,1.757197749,519.1544408
101.8,108.3440576,3.923461016,306746.2756,1.758070861,521.3801219
102,109.3283491,3.962792286,311044.7367,1.744100562,524.2021603
102.2,110.0702805,4.002535465,313963.1699,1.735805693,526.4037659
102.4,110.4924109,4.042699986,317746.319,1.724891408,529.0682247
102.6,111.2958683,4.083241634,321329.8957,1.716159966,531.9570083
102.8,112.0351609,4.124195088,323835.336,1.711357664,534.3522934
103,112.814375,4.165557264,324076.9611,1.718342773,536.7749353
103.2,113.873326,4.207315757,324841.6667,1.721398736,538.7959986
103.4,114.5666754,4.249518982,325623.8093,1.725327851,541.0862374
103.6,115.8886597,4.292102966,326661.6276,1.728383805,543.651138
103.8,116.2646535,4.335179872,327504.6518,1.730566647,545.6700018
104,117.2584561,4.378647034,331045.9423,1.7218352,548.6277269
104.2,118.3579601,4.422543673,334531.0341,1.713540321,551.5887361
104.4,119.2792161,4.466893596,338013.5292,1.705245447,554.4829951
104.6,120.0830105,4.511697248,340949.4407,1.699133432,557.0511702
104.8,121.2506399,4.556925955,344665.2452,1.691711693,560.2813623
105,121.9077748,4.602644172,346022.9855,1.694767668,563.2445532
105.2,123.2793079,4.648772608,346659.8957,1.699133333,565.5687264
105.4,124.1961361,4.695395836,346781.1617,1.706118436,568.0646859
105.6,124.9422075,4.742499166,347069.7532,1.711357262,570.3231944
105.8,126.0038149,4.790053948,346517.9013,1.720961784,572.8246275
106,126.9804319,4.838092526,346927.4312,1.726200602,575.401562
106.2,128.0735699,4.886605596,347060.9287,1.731002845,577.4456079
106.4,129.0001124,4.935617617,346588.11,1.73973423,579.6898937
106.6,129.9307612,4.985121662,346058.6271,1.748902185,582.0370388
106.8,131.2468894,5.035096674,346234.5729,1.753704421,583.9366512
107,132.4322262,5.085582695,345785.2237,1.762435796,586.2126757
107.2,133.244457,5.136601558,347058.5548,1.763308911,588.6003055
107.4,134.4454964,5.188106369,349776.8496,1.757196883,591.084236
107.6,135.2317938,5.240157331,352537.0159,1.751084869,593.4543583
107.8,136.2745002,5.292713655,355914.8941,1.743663135,596.3562808
108,137.0935666,5.345815565,359613.8449,1.734058555,598.9200822
108.2,138.1265418,5.399707074,363110.1676,1.727073392,602.0528888
108.4,139.2918836,5.45386202,365396.2973,1.724890502,604.8836905
108.6,140.3684801,5.50856803,366853.848,1.724890468,607.3336979
108.8,141.258938,5.563557758,368418.036,1.725327011,610.3165925
109,142.5743897,5.619347119,368985.0823,1.728382964,612.5740199
109.2,143.968882,5.675691615,369356.5913,1.734058337,615.3577759
109.4,144.8536999,5.732637285,370045.1049,1.737550874,617.8034025
109.6,146.1423077,5.790127408,371423.3749,1.739297115,620.5860623
109.8,147.2926211,5.848204627,373135.8077,1.738860508,622.9080472
110,148.5486188,5.906858057,375876.0118,1.735804474,625.8767259
110.2,149.6263514,5.966113029,379238.1831,1.728819311,628.5751266
110.4,150.8672228,6.02595223,382652.3411,1.723143855,631.6729249
110.6,151.6308906,6.086425522,385001.2442,1.72227069,634.8505916
110.8,152.8641271,6.14747402,387915.2675,1.717468376,637.5665029
111,154.3562599,6.20911807,390087.2653,1.717031758,640.7277729
111.2,155.5310644,6.271403396,389727.4178,1.72488999,643.0245922
111.4,156.7990577,6.33430801,390153.4148,1.730128796,645.7350344
111.6,157.8812869,6.397856615,392819.2303,1.727509339,648.9947768
111.8,159.0167345,6.462038283,393507.457,1.731001867,651.4371287
112,160.4277286,6.526845932,393799.4407,1.737113808,654.2887307
112.2,161.6004966,6.592320725,396675.5098,1.733621207,657.4313931
112.4,162.7948381,6.658451832,399162.5146,1.731438317,660.3946012
112.6,164.218093,6.725231551,399551.0934,1.735803976,662.6695451
112.8,165.3972907,6.792699034,399856.1932,1.741915924,665.5189515
113,166.593896,6.860843172,402456.1765,1.737986753,668.1287254
113.2,167.6546927,6.929681287,404449.8689,1.737550149,671.3457931
113.4,168.8519706,6.99920169,404161.6339,1.744535236,673.8986651
113.6,170.0375096,7.069421243,405241.1195,1.74671805,676.7524536
113.8,171.4436303,7.140331078,406334.4621,1.748027716,679.1346317
114,172.6872928,7.211964624,405092.5196,1.759378506,681.7367461
114.2,174.2447971,7.284296282,403741.4779,1.769856144,683.5663405
114.4,175.5632338,7.357371011,404163.5205,1.774658374,685.8861461
114.6,177.0348006,7.431169328,405963.3478,1.775094897,688.646932
114.8,178.303104,7.505723246,407553.984,1.774658285,690.9415698
115,179.607126,7.581023741,411657.366,1.766363407,694.1684932
115.2,181.0526179,7.6570711,417700.732,1.74977369,697.2455134
115.4,182.4438958,7.733886176,423915.5433,1.734057114,700.7755417
115.6,183.7742973,7.811477227,429442.4094,1.722269674,704.7060623
115.8,185.2719795,7.889836359,434102.4166,1.712665084,707.9450297
116,186.6171872,7.968993235,438603.7395,1.705679917,712.0024804
116.2,188.2262661,8.048927174,439880.5923,1.707862717,714.9339716
116.4,189.7403245,8.129670792,439624.7737,1.715720934,717.9289263
116.6,191.2084905,8.211228797,439834.1277,1.722269441,721.1766482
116.8,192.5208474,8.293616968,439542.382,1.730127662,724.2875874
117,194.313572,8.376799819,439495.6045,1.735803018,726.772637
117.2,195.5732758,8.460855147,441275.1125,1.736676117,730.1243068
117.4,197.140145,8.545733864,446924.9147,1.724452103,733.935563
117.6,198.7418882,8.631462817,451056.9022,1.71659379,737.1449917
117.8,200.2660906,8.718058524,457535.5461,1.703496638,741.5504167
118,201.7252418,8.805528712,465567.3371,1.686906929,746.3311612
118.2,203.0394021,8.893887663,469668.7246,1.681231476,749.8163326
118.4,204.6682171,8.983112649,469571.0306,1.689962828,753.341996
118.6,206.6225108,9.073211699,469514.5994,1.699130739,757.0449357
118.8,208.034616,9.164253467,467568.7932,1.712227797,759.7072444
119,209.4208013,9.256211644,463072.4805,1.733619686,762.3848719
119.2,211.089162,9.349074224,459024.866,1.751955574,764.3786113
119.4,212.3660484,9.442896784,456551.2506,1.765925774,766.8067506
119.6,213.7477445,9.537654836,454368.4573,1.7794594,769.315867
119.8,215.4674032,9.633341617,453898.8423,1.786007893,771.4573299
120,217.1178364,9.729994653,455274.5973,1.788190689,774.2969118
120.2,218.883901,9.827610807,458098.9874,1.784698071,776.8793536
120.4,220.3684013,9.926227039,462623.7661,1.776403193,780.1270809
120.6,222.2150077,10.025809,468531.6311,1.763742604,783.8836398
120.8,223.6110109,10.12642255,473322.4505,1.75501116,787.6215828
121,225.8179391,10.22799112,476945.3857,1.74889911,790.692067
121.2,227.72831,10.3306006,481296.3002,1.74191393,794.6138583
121.4,229.278005,10.43426591,485559.7674,1.734928762,798.2620792
121.6,231.0632309,10.53895657,488551.1766,1.731872715,801.54155
121.8,232.4444784,10.64472678,493708.7328,1.724014414,805.7992605
122,234.3951641,10.75152044,499284.1792,1.713536675,809.5186179
122.2,236.1925094,10.85939769,504500.3779,1.706114931,814.0564631
122.4,238.056344,10.96835437,506691.6601,1.706551442,817.8130251
122.6,239.8767513,11.07840846,508095.9845,1.708734234,821.2172433
122.8,241.6562279,11.18957113,504785.2654,1.7257604,824.6334973
123,243.5879574,11.30184019,500001.0331,1.745405978,826.7322965
123.2,245.4795863,11.41524004,495557.3888,1.765488127,829.2983316
123.4,247.1470884,11.52979465,493536.1992,1.778148595,831.7418082
123.6,249.1957619,11.64605583,493236.9745,1.786006783,834.5857859
123.8,251.2635876,11.76231402,497449.1857,1.77858503,837.634386
123.952,252.9095682,11.85189194,501858.8547,1.769417011,840.1106882
124.2,254.8468095,11.85472153,510384.0622,1.752827301,845.2908588
124.4,256.1496056,11.85463264,517422.9962,1.738857029,849.5901511
124.6,257.1659555,11.85456336,525237.4172,1.724013628,854.4825112
124.8,257.9025208,11.85451324,528135.5059,1.722267326,858.0388009
125,258.8689091,11.85444739,531359.0698,1.719647878,861.6552805
125.2,259.0892053,11.85443262,536483.7523,1.713535896,866.3998939
125.4,259.7062793,11.85439068,538681.6985,1.715282155,870.427796
125.6,260.2259283,11.85435542,540268.4937,1.717464987,873.9326503
125.8,260.7222619,11.85432175,543160.9262,1.717901541,878.4102791
126,261.2331676,11.85428708,542770.8224,1.725323209,881.5759209
126.2,261.7424079,11.85425253,540401.13,1.739293422,885.0041789
126.4,262.0505531,11.85423175,539585.1629,1.748024804,888.2026408
126.6,262.5889376,11.8541952,538986.3375,1.755446471,890.8616521
126.8,262.8408761,11.85417826,539569.9733,1.760685299,894.4321534
127,263.1935703,11.85415443,541965.8757,1.759812148,897.6163904
127.2,263.6162106,11.85412581,545204.6684,1.758065856,901.5665971
127.4,263.8290126,11.85411155,547230.1157,1.759375558,905.1283435
127.6,263.8994242,11.85410705,547912.3745,1.764614391,908.7185357
127.8,264.3270606,11.85407808,545731.5173,1.775965188,911.0700627
128,264.7138952,11.85405191,543000.4955,1.789498833,913.7586136
128.2,264.9175375,11.85403829,540538.1072,1.800849636,915.7709202
128.4,265.1603164,11.85402198,539909.0982,1.807398173,918.390531
128.6,265.1099876,11.85402574,540774.7834,1.810017592,921.3854548
128.8,265.1704069,11.85402192,543550.5802,1.806525033,924.1615337
129,265.5339261,11.85399735,546892.153,1.802595895,927.6116748
129.2,265.9615626,11.85396838,550473.3697,1.796920476,930.5628421
129.4,266.1385587,11.85395658,551377.6371,1.799539888,933.5512071
129.6,266.1140434,11.85395857,549155.9477,1.810454129,935.9771285
129.8,266.41178,11.8539385,544958.7816,1.827043764,938.0463412
130,266.4713665,11.85393474,543617.2169,1.834902015,939.909828
130.2,266.6100589,11.85392556,541367.5662,1.846689389,941.8871165
130.4,267.0376953,11.8538966,542297.8426,1.848872223,944.0810751
130.6,267.045655,11.85389637,546299.9037,1.841887109,946.6087617
130.8,266.9994897,11.85389985,551837.9346,1.831409441,949.9330501
131,267.6253069,11.85385731,552298.9789,1.834028837,952.0296282
131.2,267.559157,11.85386216,550962.6726,1.842323662,954.3012621
131.4,267.8602243,11.85384186,547739.1066,1.85498417,955.8485208
131.6,267.6225398,11.85385845,542533.3542,1.872883531,956.867249
131.8,267.9444244,11.85383673,535863.2733,1.895585139,957.5445897
132,268.0073418,11.85383274,533275.6495,1.905626237,958.2985231
132.2,267.9270361,11.85383855,532484.7088,1.910865074,959.5754929
132.4,268.2930533,11.85381381,533042.7379,1.911738202,960.8579492
132.6,268.3909438,11.85380742,534552.8428,1.90999192,962.1677543
132.8,268.1624189,11.85382339,536889.0126,1.906499371,963.936034
133,268.3877112,11.85380828,540180.4593,1.89995082,965.9384911
133.2,268.5588785,11.85379687,543177.3787,1.89383884,967.7002225
133.4,268.5518498,11.85379767,546586.9993,1.887290296,969.7956853
133.6,268.8970497,11.85377435,549163.4155,1.883361159,971.9896411
133.8,268.8134133,11.85378039,550456.851,1.882488023,973.639747
133.958,268.8245644,11.85377988,549524.9503,1.888163427,974.8817059
134.7,268.7516419,11.73349218,1.7977E+308,1.876812622,0
134.9,268.6867856,11.6149808,1.7977E+308,1.748897738,0
135.1,268.4945274,11.49647815,1.7977E+308,1.54545632,0
135.3,268.1398943,11.37798662,1.7977E+308,1.276529466,0
135.5,267.79109,11.25949469,1.7977E+308,0.951285131,0
135.7,267.7070818,11.14098462,1.7977E+308,0.618182537,0
135.9,267.4215621,11.02248836,1.7977E+308,0.376759557,0
136.1,267.4724499,10.90396906,1.7977E+308,0.205624277,0
136.3,266.9979092,10.78548574,1.7977E+308,0.088623628,0
136.5,266.6099684,10.66699649,1.7977E+308,0.013970227,0
136.7,266.4851582,10.54848922,1.7977E+308,0.016153075,0
136.9,266.3078885,10.42998554,1.7977E+308,0.016589645,0
137.1,266.1605956,10.31147981,1.7977E+308,0.02182848,0
137.3,266.053272,10.19297135,1.7977E+308,0.025757607,0
137.5,265.4863024,10.07449435,1.7977E+308,0.028377024,0
137.7,265.5471826,9.955974369,1.7977E+308,0.038854695,0
137.9,265.1442533,9.837486144,1.7977E+308,0.046712948,0
138.1,264.8429125,9.718990963,1.7977E+308,0.050205506,0
138.3,264.9570849,9.60046733,1.7977E+308,0.051078645,0
138.5,264.544996,9.481979732,1.7977E+308,0.053698063,0
138.7,264.152059,9.363490823,1.7977E+308,0.048459228,0
138.9,263.9764547,9.244987032,1.7977E+308,0.043656962,0
139.1,263.6809427,9.126491452,1.7977E+308,0.035798709,0
139.3,263.6335729,9.00797888,1.7977E+308,0.032306152,0
139.5,263.4146685,8.889478054,1.7977E+308,0.029686735,0
139.7,263.2432276,8.770973978,1.7977E+308,0.029686735,0
139.9,262.9635367,8.652477314,1.7977E+308,0.02313819,0
140.1,262.6272228,8.533984528,1.7977E+308,0.019209064,0
140.3,262.7139164,8.415462776,1.7977E+308,0.016153076,0
140.5,262.1344564,8.296986639,1.7977E+308,0.0244479,0
140.7,262.0945808,8.178473554,1.7977E+308,0.034489001,0
140.9,261.9198092,8.059969706,1.7977E+308,0.03579871,0
141.1,261.6043125,7.941475494,1.7977E+308,0.03710842,0
141.3,261.1047909,7.822993883,1.7977E+308,0.039727838,0
141.5,260.7559866,7.704501952,1.7977E+308,0.041037547,0
141.7,260.8160341,7.585982025,1.7977E+308,0.038854699,0
141.9,260.866922,7.467462725,1.7977E+308,0.035362141,0
142.1,260.3182715,7.348984478,1.7977E+308,0.031433015,0
142.3,260.1559902,7.230479775,1.7977E+308,0.030559876,0
142.5,260.0295147,7.11197262,1.7977E+308,0.030996446,0
142.7,259.7964545,6.993472763,1.7977E+308,0.033615864,0
142.9,259.2090839,6.874997168,1.7977E+308,0.033615864,0
143.1,259.1608814,6.756484653,1.7977E+308,0.030123307,0
143.3,258.9423934,6.637983799,1.7977E+308,0.027503889,0
143.5,258.8050928,6.519477385,1.7977E+308,0.022265053,0
143.7,258.6378843,6.400380439,1.7977E+308,0.015716508,0
143.9,258.0650858,6.281903845,1.7977E+308,0.01266052,0
144.1,257.6621564,6.16341562,1.7977E+308,0.014406799,0
144.3,257.5689196,6.04549877,1.7977E+308,0.017899357,0
144.5,257.3375249,5.926998799,1.7977E+308,0.016153078,0
144.7,257.3900781,5.808479385,1.7977E+308,0.010477672,0
144.9,257.1370334,5.689980897,1.7977E+308,0.005238836,0
145.1,256.9098021,5.571480641,1.7977E+308,0.011350812,0
145.3,256.5443439,5.45298985,1.7977E+308,0.016589648,0
145.5,256.1014453,5.334504362,1.7977E+308,0.019209066,0
145.7,256.0957101,5.21598894,1.7977E+308,0.023138194,0
145.9,255.9808922,5.097480986,1.7977E+308,0.024447903,0
146.1,255.6162667,4.978990138,1.7977E+308,0.026194182,0
146.3,255.4323354,4.860486918,1.7977E+308,0.021828485,0
146.5,255.0210791,4.741999263,1.7977E+308,0.010914242,0
146.7,254.8846112,4.623492792,1.7977E+308,0.010477673,0
146.9,254.6348972,4.504994076,1.7977E+308,0.020955346,0
147.1,254.0920755,4.38651543,1.7977E+308,0.032306158,0
147.3,253.8956538,4.268013064,1.7977E+308,0.037108425,0
147.5,254.0298109,4.149488063,1.7977E+308,0.035362146,0
147.7,253.5061412,4.031008105,1.7977E+308,0.026194183,0
147.9,253.2930656,3.91250688,1.7977E+308,0.017026219,0
148.1,253.1357805,3.794001835,1.7977E+308,0.018335928,0
148.3,252.7528357,3.675512241,1.7977E+308,0.023138195,0
148.5,252.3390813,3.557024758,1.7977E+308,0.027503892,0
148.7,252.2134384,3.438517546,1.7977E+308,0.023574765,0
148.9,251.6339783,3.320041408,1.7977E+308,0.017026219,0
149.1,251.65822,3.201523933,1.7977E+308,0.012223952,0
149.3,251.072931,3.083048195,1.7977E+308,0.014843371,0
149.5,251.126317,2.964528724,1.7977E+308,0.023138196,0
149.7,250.9848529,2.846022595,1.7977E+308,0.027503893,0
149.9,250.3970658,2.727547028,1.7977E+308,0.029686742,0
150.1,249.9699883,2.609060457,1.7977E+308,0.031869591,0
150.3,249.6944609,2.490563508,1.7977E+308,0.035362149,0
150.5,249.3281699,2.372072774,1.7977E+308,0.03536215,0
150.7,249.0226655,2.253577878,1.7977E+308,0.031869592,0
150.9,248.7604611,2.135080017,1.7977E+308,0.029686743,0
151.1,248.3825124,2.016590081,1.7977E+308,0.028377034,0
151.3,248.1003234,1.898093589,1.7977E+308,0.023138197,0
151.5,247.7190439,1.779603881,1.7977E+308,0.01833593,0
151.7,247.5492684,1.661099691,1.7977E+308,0.01746279,0
151.9,246.8207562,1.54263376,1.7977E+308,0.011787384,0
152.1,246.4128306,1.424145877,1.7977E+308,0.012223954,0
152.3,246.1905954,1.305645279,1.7977E+308,0.01920907,0
152.5,246.0549602,1.187138752,1.7977E+308,0.017026221,0
227.7,245.5484648,1.075887447,1.7977E+308,0.051078666,0
227.9,245.0864141,0.95740327,1.7977E+308,0.045839829,0
228.1,244.9466155,0.838897027,1.7977E+308,0.040600991,0
228.3,244.4779033,0.720413306,1.7977E+308,0.034489014,0
228.5,243.9750507,0.601931924,1.7977E+308,0.027940468,0
228.7,243.4405559,0.483452707,1.7977E+308,0.02270163,0
228.9,243.0734322,0.364962031,1.7977E+308,0.016589653,0
229.1,242.4240257,0.246490683,1.7977E+308,0.012660525,0
229.3,241.6988443,0.128024524,1.7977E+308,0.009604536,0
229.5,240.7813108,0.009571536,1.7977E+308,0.012223955,0
229.514,240.7209805,0.00127956,1.7977E+308,0.012223955,0