File: GB3_Loc1_10um_250nm_test41.csv
Time On Sample,Displacement Into Surface,Load On Sample,Harmonic Contact Stiffness,Harmonic Displacement,Harmonic Load
0,0,0,114.6193714,0.441811723,2.178596894
0.2,0.230171551,0.00067529,2851.661483,0.323937053,2.234402259
0.4,0.003191782,0.001381884,7341.316881,0.267182584,2.296772913
0.6,0.251682694,0.00205592,10048.89225,0.241861357,2.355860952
0.788,0.30083815,0.002702142,12041.54614,0.218722996,2.464188977
1,0.338977711,0.00342589,13465.31989,0.204752665,2.590024564
1.2,0.477553149,0.004101506,15065.25672,0.190345761,2.716954379
1.4,0.578657168,0.004779687,16513.41504,0.179868012,2.842789973
1.6,0.455765368,0.005473207,17958.66879,0.171573128,2.968625543
1.8,0.708004111,0.00614104,19822.79365,0.164587962,3.163397169
2,0.574703585,0.006835272,22588.21937,0.156729651,3.458837218
2.2,0.839016451,0.007502279,25666.18686,0.14887134,3.749900432
2.4,0.72195354,0.008195399,30041.82601,0.1366473,4.044246265
2.6,0.828470096,0.00887321,35046.71204,0.125296406,4.333121009
2.8,0.631468157,0.009571805,41234.48573,0.11656495,4.779563743
3,0.986961477,0.010232567,46297.38216,0.114818657,5.345276828
3.2,0.977316634,0.010918332,47585.86315,0.122240396,5.900047622
3.4,0.860253722,0.011611453,45634.55941,0.137520446,6.336642362
3.6,0.714046374,0.012306569,42060.5664,0.161968525,6.850926896
3.8,0.827640865,0.012983896,39560.77164,0.191218905,7.544663971
4,1.012847401,0.013656319,38796.1189,0.219159567,8.473658905
4.2,1.258008208,0.014324636,38180.64813,0.247100227,9.387334755
4.4,0.925276463,0.015032524,38668.30298,0.266746007,10.28131441
4.6,1.12880236,0.015703693,39555.88861,0.283335774,11.19499026
4.8,0.973435331,0.016399436,41236.76496,0.29643296,12.2126171
5,0.916326691,0.017088451,42452.14305,0.311276437,13.1339524
5.2,1.040746258,0.017765037,43137.9658,0.333105078,14.25005939
5.4,0.857900189,0.018462662,41975.50596,0.369340626,15.33662221
5.6,1.130540037,0.019129098,40073.43894,0.412561336,16.32361104
5.8,1.23830564,0.019806823,38052.69892,0.462330638,17.34233223
6,1.096261783,0.020501654,36057.5831,0.519085109,18.43217774
6.2,0.762697339,0.0212096,34635.49322,0.565361834,19.24956171
6.4,0.81134137,0.021891373,33177.60803,0.621243157,20.22779661
6.6,1.00903838,0.022562941,31967.17689,0.675378188,21.16663963
6.8,0.832021198,0.023260167,31099.78541,0.723401203,22.06609037
7,0.911475063,0.023939831,30118.14106,0.776663089,22.99070845
7.2,0.851035629,0.024629074,28683.50787,0.843895308,23.89344193
7.4,0.956303138,0.025306971,27546.81694,0.89977663,24.55763501
7.6,0.604419332,0.026016171,26037.79634,0.976613457,25.3093656
7.8,0.799618248,0.026687909,24513.46042,1.056942857,25.89368052
8,1.01979811,0.027357938,23311.52159,1.128104226,26.36638485
8.2,0.986837717,0.028045299,22294.96129,1.20232161,26.91677872
8.4,1.068789676,0.028724792,21580.31154,1.259076078,27.32820642
8.6,1.119931802,0.029406395,20973.53643,1.315393974,27.82060655
8.8,1.001203495,0.03009963,20656.84688,1.354685533,28.25610702
9,1.268014455,0.030766465,20448.02319,1.386118771,28.62814293
9.2,1.493190504,0.031436151,20133.91076,1.425410321,29.05926678
9.4,1.159626061,0.032144096,19953.69772,1.4516047,29.39847546
9.6,1.171631371,0.032828379,19628.73044,1.49002311,29.77160533
9.8,1.798167951,0.033470582,19362.34784,1.520583192,30.07361135
10,1.956728143,0.03414483,19405.92107,1.529751217,30.38437067
10.2,2.111124843,0.034819363,19875.64562,1.516217455,30.8297194
10.4,2.122297455,0.035503702,20645.30368,1.484784211,31.26850262
10.6,2.006067244,0.036196766,22481.23025,1.405764531,31.98521826
10.8,1.236168949,0.036934588,24850.80982,1.314084254,32.74132516
11,1.507143399,0.037601139,27374.03006,1.233318272,33.59810166
11.2,2.271907875,0.038233877,28810.08903,1.198392429,34.23931698
11.4,1.850077428,0.038947866,29669.27653,1.185731826,34.83129085
11.6,2.287591513,0.039603013,29250.54107,1.219784498,35.42326572
11.8,2.297098729,0.040287466,27921.29402,1.286143568,35.79530129
12,2.208347558,0.040978648,26788.73528,1.352939214,36.18484448
12.2,2.338596011,0.041654834,26484.97024,1.381753018,36.53280741
12.4,1.981716024,0.042364376,26329.99803,1.406637679,36.98034389
12.6,2.456701526,0.043016957,26787.72047,1.400089074,37.41912768
12.8,2.056521233,0.043729463,27752.13116,1.372148423,37.97280382
13,2.330826473,0.044395786,28918.81381,1.339405454,38.64684527
13.2,2.170463258,0.045091871,29739.25427,1.320196253,39.18410831
13.4,2.334852337,0.045765719,30654.13018,1.304043054,39.83407669
13.6,2.535047436,0.046437116,31233.73835,1.29793103,40.33960778
13.8,2.596181939,0.047118035,31655.22012,1.300113893,40.88562492
14,2.315077488,0.047822388,31981.38157,1.307972211,41.5038602
14.2,2.631017636,0.048485859,31949.98375,1.323252253,41.94811497
14.4,2.752106407,0.049162672,31678.8626,1.34944662,42.4645882
14.6,2.943974524,0.049834639,31439.65586,1.371275257,42.86945075
14.8,2.939325472,0.050523486,31185.74813,1.395286763,43.30932827
15,2.987137202,0.051201893,30888.29132,1.422354277,43.789692
15.2,2.751831153,0.05190311,30864.47715,1.435451468,44.17266962
15.4,2.789650107,0.052585625,31146.02604,1.43894405,44.68804833
15.6,2.69507005,0.053277206,31357.95169,1.444182926,45.18373101
15.8,2.938565454,0.053945638,31446.71953,1.453787522,45.6312685
16,2.873962532,0.054635167,31593.32,1.460336117,46.0361306
16.2,2.826846271,0.055323498,31486.2853,1.479981895,46.49570404
16.4,3.139455623,0.055987197,31198.42771,1.502683674,46.82068861
16.6,3.097335552,0.056675186,30959.29644,1.525822035,47.211326
16.8,2.926147263,0.057372012,30882.04483,1.540228944,47.57898446
17,3.091369037,0.058045804,30780.09535,1.55419927,47.88646129
17.2,3.204963525,0.05872313,30894.94456,1.559438141,48.31211408
17.4,3.132033621,0.059413229,31151.93868,1.557691852,48.66445361
17.6,3.154864007,0.06009677,31414.35414,1.558128424,49.09995416
17.8,3.321751178,0.060770448,31516.6513,1.565113585,49.47308433
18,3.417859003,0.061448972,31738.64494,1.565986728,49.81448188
18.2,3.176724068,0.062150588,32188.74361,1.562494152,50.27405498
18.4,3.672527016,0.062801743,32473.95263,1.562494138,50.62311284
18.6,3.758642463,0.063480951,33106.15352,1.552016388,51.10894781
18.8,3.560807834,0.064179603,34039.38136,1.528441461,51.6024418
19,3.550746643,0.064865396,34923.11512,1.506612821,52.08280547
19.2,3.641858279,0.065544262,35984.87047,1.481291594,52.68681654
19.4,3.899509548,0.066211725,37486.86758,1.441563461,53.31927759
19.6,3.361101368,0.066933697,38980.72778,1.40532793,53.97690432
19.8,3.829008926,0.067586762,40022.74546,1.386118714,54.61702547
20,3.890559777,0.068267652,41070.83886,1.369528946,55.30966847
20.2,3.310516689,0.068992475,41804.07926,1.361888936,55.93720396
20.4,3.450757517,0.069667977,41440.10061,1.385682151,56.44437635
20.6,3.268327804,0.070365573,40196.09775,1.43719775,56.86784014
20.8,4.272076452,0.070983483,38978.22709,1.487840171,57.20814529
21,4.286578961,0.0716753,37558.65919,1.547214074,57.5090565
21.2,4.465122202,0.072362798,36609.48422,1.589998205,57.73993786
21.4,4.481288487,0.073068422,36666.46624,1.596983369,58.16449625
21.6,4.321754632,0.07379321,37794.66726,1.564240414,58.67549787
21.8,4.51361857,0.074501062,40001.94629,1.500064204,59.40862739
22,4.563090287,0.075225862,42412.12977,1.436761144,60.16364107
22.2,4.748290953,0.075948671,45437.98946,1.366036343,61.139688
22.4,4.399731245,0.076715385,47393.72139,1.330673953,62.02163067
22.6,4.133607762,0.07748412,48212.70867,1.324561941,62.79086857
22.8,4.506162883,0.07821673,47863.83609,1.345954,63.39925712
23,4.542307077,0.07897986,46925.65103,1.384372407,63.98357205
23.2,4.585111974,0.079750123,45990.11253,1.421917668,64.4081305
23.4,4.530490276,0.08053488,44898.60733,1.467321244,64.89943631
23.6,4.524996868,0.081324028,44094.36948,1.502683642,65.25396441
23.8,4.45371938,0.08212563,43516.71997,1.533243741,65.64788437
24,4.681379599,0.082914778,43643.82411,1.54328491,66.2004672
24.2,4.292842237,0.083754235,43847.21177,1.548960368,66.7497661
24.4,4.815275719,0.084539407,44157.20647,1.54852378,67.20386969
24.6,4.68570559,0.085377422,44927.22356,1.536299746,67.85055483
24.8,4.854240431,0.086203363,45532.57337,1.528004858,68.43487011
25,5.010283836,0.087038442,45814.13356,1.53062429,69.02246795
25.2,4.922345699,0.087898674,46452.92555,1.523639128,69.67024763
25.4,5.070060139,0.08875138,46900.25313,1.519709969,70.16811927
25.6,5.008766342,0.089626998,47199.88407,1.523202553,70.791826
25.8,5.148984477,0.090497592,47428.56292,1.527568277,71.3444086
26,5.076863569,0.091391448,47646.08547,1.533243726,71.95279639
26.2,5.014733996,0.092293592,47634.37031,1.54284833,72.40142743
26.4,5.140793149,0.093191925,47552.58482,1.557255229,72.94087949
26.6,5.001220541,0.094117481,47576.42135,1.5690427,73.48908454
26.8,5.16891248,0.095031211,47732.34874,1.575591287,73.994616
27,5.236679566,0.095961018,47752.35383,1.584759315,74.41260904
27.2,5.214514155,0.096906412,48037.0878,1.587815325,74.96081454
27.4,5.157374328,0.097863614,48630.62262,1.581703307,75.55607142
27.6,5.265940317,0.098819048,49114.04413,1.578647295,76.15789409
27.8,5.497744517,0.099775636,49605.08662,1.57428156,76.7268906
28,5.311533115,0.100770584,50147.81418,1.567296401,77.24883426
28.2,5.530011858,0.10174774,50595.72849,1.565550103,77.88020115
28.4,5.438725733,0.102756064,50754.16053,1.571225553,78.45795049
28.6,5.619730732,0.103755798,51163.13866,1.570352402,79.07728099
28.8,5.49346894,0.104786674,51244.20792,1.578210716,79.58937681
29,5.566220807,0.105814228,51389.62102,1.583449588,80.06864657
29.2,6.013685651,0.106826315,51620.62249,1.588251877,80.67156431
29.4,5.570994968,0.107909803,52159.30766,1.584759307,81.3018353
29.6,5.889389152,0.108951788,52574.26752,1.583013007,81.81283826
29.8,5.987949798,0.110019378,53396.89852,1.571225538,82.45077019
30,5.865844179,0.1111129,54643.97483,1.55070662,83.24626979
30.2,5.786204891,0.112214471,55866.6743,1.531933991,84.0330157
30.4,6.134571171,0.113297698,56637.61685,1.522765953,84.67094836
30.6,5.74849641,0.114442242,57503.19651,1.513597935,85.45769341
30.8,5.813742715,0.11556728,58057.83316,1.511851642,86.18097467
31,5.567558598,0.116724962,58263.91941,1.518836814,86.89440715
31.2,6.025003084,0.117845876,58445.84501,1.523639102,87.4677812
31.4,6.368366596,0.118986,58787.57563,1.526695103,88.1877807
31.6,6.274562232,0.12016771,58981.83597,1.53368027,88.91215569
31.8,6.40891579,0.121345556,59025.28773,1.542848296,89.54571114
32,6.430853723,0.122542932,59230.96991,1.548960314,90.24491933
32.2,6.398664876,0.123756064,59400.73184,1.554199189,90.82048041
32.4,6.473891957,0.124980161,59700.86114,1.558128342,91.5164062
32.6,6.760623653,0.126195882,60210.46943,1.557255189,92.25281883
32.8,6.840845512,0.127431767,60943.87467,1.551143168,92.99470195
33,6.716221441,0.128700511,61605.86903,1.545467725,93.64357581
33.2,6.762299013,0.12997024,62286.06807,1.541975141,94.43251046
33.4,7.158108336,0.131228583,62770.84074,1.543284849,95.21159819
33.6,7.148392181,0.132527511,63065.38233,1.546777432,95.84624736
33.8,7.295221762,0.133828711,63339.19795,1.551143156,96.53779664
34,7.276342879,0.135154488,63761.49904,1.55332602,97.34423857
34.2,7.209998672,0.13649667,64293.04358,1.552452877,98.12989026
34.4,7.3218503,0.137840097,64850.18053,1.549396864,98.80283765
34.6,7.241347078,0.139210312,65701.7061,1.542411702,99.65851949
34.8,7.608833853,0.140563529,66258.05714,1.541538546,100.4222881
35,7.616593449,0.141955065,66716.70308,1.544157983,101.2538973
35.2,7.545245089,0.143366068,67144.82363,1.545031131,101.9366919
35.4,7.545507125,0.144786294,67377.38951,1.552016295,102.7310976
35.6,7.788915354,0.146204119,67472.14198,1.561184318,103.4740757
35.8,7.699242677,0.147659019,67733.06922,1.565986621,104.2181468
36,7.785267615,0.149116394,67866.36308,1.572098638,104.8527962
36.2,7.700587731,0.150600145,67740.72742,1.585632397,105.5738888
36.4,7.428549039,0.152111623,67721.29443,1.596546725,106.3059227
36.6,7.962560387,0.153582826,67645.98136,1.606151311,106.8486592
36.8,8.077722839,0.155097701,67507.16701,1.619248492,107.4647069
37,8.192883526,0.156627749,67554.85551,1.62885309,108.1442196
37.2,8.181888648,0.158181925,67820.45393,1.631472527,108.7416653
37.4,8.071800882,0.159758479,68298.83023,1.631035958,109.4605691
37.6,8.267311489,0.161329858,68872.21835,1.627106797,110.1039728
37.8,8.526521663,0.162912684,69539.15399,1.622959348,110.9164341
38,8.523430086,0.164529352,70000.66089,1.622304489,111.628226
38.2,8.543235811,0.166160757,70640.52149,1.619685052,112.4390451
38.4,8.937337435,0.167782838,71093.05672,1.619248468,113.0922974
38.6,8.68359801,0.169465853,71408.69247,1.623614204,113.8505927
38.8,8.750445407,0.171143651,71913.68278,1.623177629,114.5826282
39,8.8814086,0.172833889,72404.10316,1.621867907,115.2544814
39.2,8.635157559,0.174567106,72948.39085,1.620994769,116.0718649
39.4,8.747797401,0.176292939,73405.81185,1.619685046,116.7294931
39.6,9.203506854,0.178012506,73976.01707,1.617938743,117.5611042
39.8,8.930603428,0.179799542,74381.22791,1.618811896,118.3139283
40,9.248080886,0.181563922,74743.79942,1.619685033,118.9759343
40.2,9.141712931,0.183375225,75116.04358,1.622741046,119.8086374
40.4,9.215205658,0.185192321,75316.35112,1.626670199,120.4378158
40.6,9.184609,0.187034804,75608.91454,1.631035929,121.2420693
40.8,9.517066569,0.188870836,75915.11811,1.633655355,121.9751999
41,9.42734404,0.1907544,76181.08014,1.635838221,122.6175083
41.2,9.808093759,0.192624425,76481.52346,1.639330793,123.4305174
41.4,9.765830633,0.194542468,76755.70308,1.641513658,124.0826741
41.6,9.840143013,0.196471664,77180.54218,1.642823374,124.8847396
41.8,9.843673801,0.198425095,77421.48288,1.647625675,125.5905132
42,9.792244222,0.200402013,77554.28276,1.653301123,126.2120316
42.2,9.780781842,0.202396048,77419.47845,1.665961734,126.9243705
42.4,9.537827064,0.204425959,77397.53983,1.673820052,127.4736692
42.6,10.14089119,0.20641812,77401.40928,1.682551489,128.171786
42.8,10.01117865,0.208480735,77595.64635,1.686044076,128.8250365
43,10.21953913,0.210540829,77865.0889,1.687353788,129.4268597
43.2,10.11397001,0.212643264,78479.7188,1.683424636,130.2256422
43.4,10.33731419,0.214744163,78871.22654,1.682988057,130.8493498
43.6,10.30918108,0.216883541,79161.44826,1.686917213,131.5868558
43.8,10.21109883,0.219049125,79245.46927,1.693902381,132.2116566
44,10.63594847,0.221200539,79500.10107,1.696958377,132.7937852
44.2,10.71522589,0.223397178,79607.84411,1.704380112,133.4601671
44.4,11.00683875,0.225601402,79882.50609,1.706126394,134.0346355
44.6,11.06196277,0.227844073,80413.24732,1.703943529,134.7699535
44.8,11.27946029,0.23009816,80993.22906,1.70045094,135.4702569
45,12.01489339,0.232339239,81319.88562,1.700450918,136.0633292
45.2,11.71361475,0.234674134,82056.36795,1.694775482,136.8664874
45.4,12.08015726,0.23698647,82543.13164,1.692592607,137.5077035
45.6,12.07864451,0.239347364,83380.00397,1.686044015,138.3546321
45.8,12.31278255,0.241715784,84299.88624,1.677312553,139.1610754
46,12.50111943,0.244111226,85471.85151,1.664215365,139.9609533
46.2,12.52541198,0.246542016,86803.96975,1.650245036,140.9545076
46.4,12.55802868,0.248996661,88057.62182,1.636274707,141.7784577
46.6,12.61312536,0.25147437,89114.90027,1.628416396,142.8048389
46.8,12.64407089,0.253978742,89821.57164,1.625796958,143.6834999
47,12.83738962,0.256497079,90376.56003,1.626670099,144.656265
47.2,12.92828353,0.259047831,90626.71195,1.630599251,145.39596
47.4,12.88677549,0.261633196,90889.23491,1.636274698,146.3052591
47.6,13.31740423,0.264212044,91240.50762,1.638894122,147.060275
47.8,13.21260509,0.26685375,91628.09965,1.641076989,147.8907896
48,13.2243806,0.269513866,91961.60365,1.645442716,148.8394807
48.2,13.18369302,0.272204333,92246.87696,1.648498727,149.5944944
48.4,13.43777743,0.274901439,92285.39918,1.656793602,150.4600261
48.6,13.60026188,0.277632102,92232.72907,1.664215334,151.1220318
48.8,13.41217727,0.280414233,92215.56597,1.672510222,151.873762
49,13.81863582,0.283183443,92265.06134,1.681241665,152.7119389
49.2,13.83871922,0.286007167,92169.54996,1.690409693,153.3411167
49.4,13.74471969,0.288867004,92370.67345,1.696085141,154.1409936
49.6,13.68069395,0.291753611,93074.30915,1.691719416,154.8609916
49.8,13.98554836,0.294658549,93930.92665,1.686043961,155.713393
50,14.06473991,0.297593464,94919.85869,1.679058795,156.6872518
50.2,14.67602208,0.300521378,95962.06504,1.669890749,157.516676
50.4,14.54869939,0.303514546,97057.1999,1.662469016,158.5441507
50.6,14.35975183,0.306556852,97225.74814,1.667707895,159.2761845
50.8,14.78699725,0.309587472,97298.2113,1.675129619,160.0651219
51,14.65133526,0.312687214,97611.42593,1.679495351,160.9656666
51.2,15.04776368,0.315781621,97890.19986,1.683861066,161.8530835
51.4,15.02367598,0.318936001,98141.21961,1.686480504,162.558857
51.6,15.2069264,0.322107854,99041.82047,1.680805053,163.5403762
51.8,15.1811659,0.325326014,99847.72528,1.676002754,164.4639
52,15.31028348,0.328565745,100322.4282,1.675129604,165.2473645
52.2,15.72667809,0.331818343,100669.9951,1.678185601,166.2102828
52.4,15.40613114,0.335154315,100947.4168,1.680805047,166.9696721
52.6,15.45696366,0.338497915,101072.056,1.686917064,167.8570869
52.8,15.61104683,0.341867951,101037.266,1.694775369,168.6339863
53,15.77345303,0.345271349,101313.9056,1.697394801,169.3725874
53.2,15.87423561,0.348713119,102121.2481,1.693902216,170.3661429
53.4,16.37054571,0.352162415,102932.7909,1.688663328,171.1780589
53.6,16.5729094,0.355666392,103839.3158,1.684297595,172.1902164
53.8,16.75445156,0.359206894,105164.7752,1.673819844,173.2165984
54,16.89685275,0.362785885,106148.9121,1.667707822,174.1105799
54.2,16.95681266,0.366406433,107272.471,1.661595802,175.2354415
54.4,17.06881196,0.370059741,108094.1362,1.658103217,176.1502126
54.6,17.22452365,0.373746737,109122.1333,1.654174058,177.3024304
54.8,17.60339407,0.377455589,109782.4504,1.654174047,178.3145889
55,17.59630463,0.381228279,110597.5686,1.651118038,179.2687513
55.2,17.52634211,0.385042993,111395.7666,1.649808322,180.393612
55.4,17.69286135,0.388879853,111736.7137,1.652864327,181.2854048
55.6,17.72864253,0.392764174,112238.6681,1.655047189,182.3829108
55.8,17.80771949,0.396684363,112445.3377,1.66028606,183.3523931
56,17.96006928,0.400638988,111901.9397,1.674692955,184.099748
56.2,17.94004597,0.404645235,111319.0846,1.691282719,184.9696554
56.4,17.99163,0.408686717,111096.0471,1.70132389,185.6622989
56.6,18.08068073,0.412766239,110775.6371,1.714421069,186.5125106
56.8,18.85836792,0.416839438,110628.6172,1.724025645,187.2631525
57,19.71349125,0.420948247,111258.4699,1.721842755,188.0411506
57.2,19.85748569,0.425147322,112272.5182,1.716167306,189.0916059
57.4,19.77581408,0.429404112,113401.5393,1.708745572,190.1639438
57.6,19.73743779,0.433700592,114517.0455,1.70001412,191.0480758
57.8,19.89640591,0.4380267,116103.9075,1.686480361,192.1751267
58,19.80972307,0.442413067,117321.5799,1.679058628,193.3787715
58.2,20.23014817,0.44680872,118225.1144,1.674256315,194.3373137
58.4,20.19175154,0.451280132,119046.0894,1.672510027,195.5289224
58.6,20.13752843,0.455797579,119388.6461,1.675129464,196.4327504
58.8,19.94090869,0.460370121,119716.1848,1.679058625,197.4273978
59,20.34798964,0.464946994,119879.3538,1.685607203,198.4866086
59.2,20.6076777,0.469580112,120119.0163,1.68953635,199.3576121
59.4,20.62171444,0.474276645,120565.5429,1.692155786,200.4091607
59.6,20.5949435,0.479023094,121254.4263,1.690409496,201.3381557
59.8,20.91623476,0.483793357,121827.2948,1.690846059,202.3568797
60,21.03517485,0.48862539,122445.034,1.691719201,203.4861189
60.2,21.29233714,0.493496524,122689.6668,1.695648348,204.3604048
60.4,21.27720151,0.498435324,122664.8286,1.704379802,205.3856918
60.6,22.42034296,0.503344004,121734.5467,1.723588965,206.1746351
60.8,22.82737368,0.508352679,121101.0938,1.737122706,206.7348802
61,22.91464253,0.513433705,120572.2622,1.751093029,207.5150619
61.2,23.54732259,0.518528298,120803.4194,1.753712446,208.2427247
61.4,23.39226445,0.523728299,121608.2246,1.750219869,209.2406551
61.6,23.58276989,0.528956633,123682.963,1.731447239,210.4541502
61.8,23.83655424,0.534233294,125396.0756,1.715730614,211.4006548
62,23.81304403,0.539581927,127699.6265,1.696521418,212.8056377
62.2,23.85864149,0.544979682,129288.6373,1.684733954,213.9042377
62.4,23.99000053,0.550425693,131428.5616,1.669453907,215.3683096
62.6,23.93316347,0.555939408,132815.9033,1.661159028,216.5314688
62.8,24.24853594,0.561482917,133653.5937,1.660722446,217.7657547
63,24.28578083,0.567101298,134548.2416,1.659849299,219.0864823
63.2,24.33634232,0.572775128,135221.1208,1.659849298,220.1828947
63.4,24.54927327,0.578494806,135207.8614,1.669017318,221.4171801
63.6,24.64395444,0.584280087,134886.1875,1.679495059,222.3231979
63.8,24.66535145,0.590128346,135061.5907,1.684733931,223.4393057
64,25.15888133,0.596003031,135088.6678,1.692592224,224.5937148
64.2,24.89298385,0.601988957,135119.7989,1.699140822,225.510672
64.4,25.2516028,0.607992134,135679.2843,1.701760248,226.713226
64.6,25.57024522,0.614058407,136181.0123,1.703069956,227.6564491
64.8,25.67904069,0.620200063,136865.7401,1.703943098,228.7780288
65,26.00433043,0.626388576,138036.2263,1.700013934,230.0473302
65.2,25.82166723,0.632674157,138562.8282,1.702633376,231.2236193
65.4,26.61075512,0.638956021,138675.4266,1.707872224,232.1241709
65.6,26.54215685,0.645360008,138449.2495,1.717040252,232.9710997
65.8,27.01397202,0.651791116,137930.7942,1.729700844,233.8486704
66,27.13105038,0.658311213,136682.8934,1.750656328,234.6463601
66.2,27.61700628,0.664871468,136548.1493,1.757641475,235.3980955
66.4,27.54921043,0.67153568,137075.6522,1.758514623,236.410251
66.6,28.20002505,0.678217452,138799.0274,1.745853996,237.6445407
66.8,28.33622458,0.68500177,140872.3369,1.730137377,238.923689
67,28.54402818,0.691849395,143307.054,1.710491602,240.176576
67.2,28.66189243,0.698771933,145792.6793,1.693028693,241.7292805
67.4,28.96294211,0.705751462,147298.0718,1.684733804,242.9559073
67.6,28.97253938,0.712821196,148335.8969,1.682987513,244.3499483
67.8,29.3734922,0.71997096,148949.5029,1.684733792,245.5908007
68,29.59374538,0.727169296,148952.4937,1.691718947,246.6160902
68.2,29.85979277,0.734400355,148941.7915,1.700013819,247.8077021
68.4,30.21409343,0.741734548,148904.3491,1.706998971,248.777187
68.6,30.08625348,0.749175605,148910.4096,1.714857282,249.9414393
68.8,31.08754308,0.756613653,149209.9608,1.718786405,251.0422369
69,31.28443791,0.764181659,149799.7824,1.718786399,252.0872221
69.2,32.05838345,0.771786136,150705.6385,1.717040085,253.4254637
69.4,31.96131821,0.779526977,151696.0887,1.713110934,254.5164043
69.6,32.15985164,0.787325253,153146.852,1.706125767,255.9432735
69.8,32.10939931,0.795219015,154271.6234,1.702196615,257.2125722
70,32.49360601,0.803162232,155462.3583,1.697830877,258.4227874
70.2,32.52307416,0.811209639,157131.0941,1.690845715,259.9590769
70.4,32.92724691,0.819312105,158399.2664,1.686043404,261.2207205
70.6,32.88591688,0.827526712,160382.9967,1.676438808,262.8565843
70.8,33.24427219,0.835796208,161825.8759,1.671199926,264.3381661
71,34.00897435,0.844120816,162552.2424,1.671636476,265.6184147
71.2,33.93430745,0.852586668,163209.2135,1.674255914,267.1678348
71.4,34.2942989,0.861107585,163707.2333,1.676438766,268.4021224
71.6,34.14342028,0.869749555,163887.9466,1.682550787,269.8311774
71.8,34.76860587,0.878424983,164696.1824,1.682550768,271.2296004
72,35.34090501,0.887191259,165844.2793,1.67905817,272.5689357
72.2,35.67379329,0.896062121,167103.8861,1.676002152,274.2091803
72.4,35.75977633,0.905039031,167937.7099,1.67600215,275.6376903
72.6,35.85407586,0.914105564,168746.3109,1.676875292,277.0880846
72.8,36.12864385,0.923250789,168722.9949,1.685170163,278.4328881
73,36.3490758,0.932491647,168081.2186,1.698485621,279.5845604
73.2,36.51370626,0.941828745,166911.1093,1.71703995,280.6038312
73.4,37.20750521,0.951223171,166059.4387,1.731883396,281.4857827
73.6,38.07199621,0.96070027,164668.5866,1.752838853,282.4541788
73.8,38.56342755,0.970298253,163682.0672,1.76855545,283.2857933
74,38.62434297,0.980022229,163736.0356,1.773357746,284.164456
74.2,38.71938761,0.989841706,165174.9654,1.76593601,285.509258
74.4,38.95181592,0.999750273,166588.5661,1.757641124,286.6603837
74.6,39.13093998,1.009762151,169285.2622,1.739305072,288.279836
74.8,39.30339076,1.01987506,172315.5547,1.718349584,289.909137
75,39.45168147,1.030091368,174672.0665,1.703942684,291.4071312
75.2,39.5549946,1.040413255,176158.7066,1.699140383,293.0933308
75.4,40.04466737,1.050812344,177142.1768,1.696957506,294.3910852
75.6,40.47270837,1.061320044,177970.6995,1.697830638,296.0006928
75.8,40.98983574,1.071927265,177853.2096,1.706125502,297.2885995
76,41.09143457,1.082669669,177477.8978,1.716166666,298.3718822
76.2,41.23798653,1.093516817,177353.019,1.725771258,299.7309097
76.4,41.23464023,1.10448331,176767.1552,1.737122144,300.6686596
76.6,41.5218926,1.11553995,175992.4038,1.751965601,301.7957131
76.8,42.19383836,1.126681242,176070.7252,1.758514169,302.8844728
77,42.81414383,1.137938113,176825.6107,1.757641005,303.9272746
77.2,43.40695714,1.149309808,178317.6992,1.751965542,305.4001063
77.4,44.07719805,1.160790352,180666.4047,1.737995201,306.8061915
77.6,44.66498844,1.172392049,183694.3493,1.72009571,308.6630957
77.8,45.13035874,1.184118716,186648.8662,1.702632795,310.4915488
78,45.36672349,1.195978899,189263.2097,1.687789322,312.1296048
78.2,45.72714632,1.207949759,192542.6472,1.670326411,314.2644397
78.4,45.91268866,1.220052898,194173.3148,1.664650963,315.8948357
78.6,46.55703322,1.232246174,195817.9774,1.661594937,317.8808589
78.8,46.66760438,1.244598663,196480.5694,1.665524086,319.5550235
79,47.06960527,1.257055163,195962.7094,1.677311531,320.8724738
79.2,47.23094199,1.269653393,194525.4469,1.697830434,322.2993437
79.4,47.78196646,1.282351307,193872.2303,1.710054447,323.4504733
79.6,47.90663495,1.295206053,193504.848,1.720968756,324.8335747
79.8,48.19532983,1.308178793,193469.0811,1.728390479,326.1521177
80,48.64472017,1.321270776,193462.9375,1.73450248,327.3251306
80.2,49.02747941,1.334498896,193326.178,1.742797345,328.738873
80.4,49.10628858,1.347880799,192655.5626,1.753711655,329.6996023
80.6,49.32164452,1.361387738,191744.2703,1.767681968,330.8616708
80.8,49.84508276,1.375009256,191128.2431,1.778596263,331.8694574
81,50.06123968,1.388788806,191534.6635,1.780779119,332.8783344
81.2,50.81530309,1.402669909,193344.5764,1.77292079,334.3741472
81.4,50.97813505,1.416731027,195335.457,1.762443046,335.7353647
81.6,51.52149334,1.430907184,197715.2277,1.750655573,337.4751874
81.8,52.19473586,1.445216964,199788.6868,1.741050957,339.0815162
82,52.68227012,1.459683187,201326.7347,1.734938928,340.4854119
82.2,53.09151392,1.474300034,202424.5521,1.733629198,342.1409784
82.4,53.7672038,1.48904566,203205.2674,1.733629177,343.4704677
82.6,53.87414408,1.503978528,204556.0222,1.731009739,345.1993444
82.8,54.11180042,1.519052333,205759.8622,1.72882687,346.8067624
83,54.72748381,1.534251467,206719.2006,1.727517133,348.183304
83.2,55.35147639,1.549602859,208044.2446,1.725334252,349.9767458
83.4,55.6556952,1.565130503,208768.8875,1.725770815,351.2920069
83.6,56.32794815,1.580788771,209338.2616,1.729263374,352.9530479
83.8,56.96770758,1.596606657,209778.3524,1.733192506,354.4565201
84,57.0953396,1.612618799,209720.5478,1.739741088,355.65032
84.2,57.29706301,1.62878645,209616.0572,1.748035958,357.1406567
84.4,58.28150308,1.645062778,209818.0175,1.752401651,358.3103944
84.6,58.67470896,1.661543341,210366.4422,1.755457646,359.8127692
84.8,59.00877406,1.678193569,211283.5106,1.755021063,361.2516792
85,59.33366003,1.69501174,212832.1927,1.749345612,362.6610445
85.2,60.31469188,1.711953782,215505.6388,1.737558126,364.5879852
85.4,60.34226539,1.729131945,218018.2676,1.72751696,366.5149156
85.6,60.61378898,1.74655341,219817.2173,1.721404939,368.078566
85.8,61.03019167,1.764053031,221594.6238,1.71660263,369.8271425
86,61.48905182,1.781636511,223483.0964,1.712236892,371.8689714
86.2,62.00616989,1.799481631,224333.0509,1.713110021,373.4118348
86.4,62.32591784,1.817519508,225827.2697,1.710490577,375.2982822
86.6,62.95041193,1.835717791,227755.6714,1.705251689,377.4046725
86.8,63.58154632,1.854098441,228543.6061,1.70525167,378.807477
87,64.11440094,1.872670569,228509.3892,1.712673384,380.6184257
87.2,64.4781963,1.891440912,228315.5695,1.720968248,382.3549654
87.4,64.81449071,1.910401692,227907.5249,1.729263112,383.6932063
87.6,65.27483486,1.929544488,227567.2575,1.738431117,385.2885917
87.8,66.03825846,1.9488587,227989.716,1.740613955,386.5458662
88,66.27706019,1.9684031,230264.1379,1.733192218,388.5942589
88.2,66.92968962,1.988115397,232813.4384,1.724024179,390.6207716
88.4,67.35996584,2.008041049,234492.6037,1.719658442,392.3124493
88.6,67.92511574,2.028157551,236276.1421,1.716602418,394.3947666
88.8,68.2312733,2.048493818,237544.1846,1.715729264,396.1564723
89,68.27927093,2.06905232,237639.7738,1.721404703,397.6621264
89.2,69.48927351,2.089737687,237283.4078,1.731009257,399.4227511
89.4,70.26958013,2.110660439,237340.1604,1.736684673,400.8365005
89.6,70.48529358,2.131832254,237413.2359,1.743233251,402.5336461
89.8,71.37921416,2.153170125,237268.3193,1.750654952,404.0174278
90,71.91463365,2.174747075,237712.0834,1.753710942,405.4180431
90.2,72.30638767,2.196550621,238642.4373,1.755020646,407.1699031
90.4,73.10821956,2.218545023,239346.1956,1.755893766,408.5245652
90.6,73.72350163,2.240772812,240431.7475,1.755893746,410.297217
90.8,74.30836435,2.263225375,241714.0403,1.753710866,411.9462239
91,75.12469063,2.285887629,243290.4308,1.750654835,413.8665997
91.2,75.47384732,2.308809606,244463.0863,1.748908535,415.4302528
91.4,76.04364197,2.331946819,246544.9694,1.742796506,417.466613
91.6,76.4543644,2.355327519,248392.7764,1.737121052,419.1933075
91.8,77.25642717,2.37891613,249959.6512,1.734065022,421.0753863
92,77.66876013,2.402768426,252233.709,1.727079854,423.2474292
92.2,78.11104231,2.426858329,254809.3072,1.718784966,425.5124821
92.4,78.98796422,2.451160376,256401.8697,1.715292362,427.3114008
92.6,79.14540743,2.475756168,258320.1565,1.71179978,429.5687891
92.8,80.27707749,2.500532002,260010.0172,1.709616883,431.6554934
93,80.53188856,2.525617114,261352.1434,1.709180304,433.4587806
93.2,81.18719761,2.550926689,262291.0666,1.712672861,435.5651741
93.4,81.87911575,2.57648794,262688.7297,1.717475134,437.1922976
93.6,82.47690925,2.602312567,262818.6534,1.725333415,439.1400278
93.8,83.05218974,2.628398205,263099.6126,1.731008837,440.8765722
94,83.98383407,2.654721418,263737.0313,1.734937958,442.8483805
94.2,84.38418692,2.681345658,264383.3096,1.737120806,444.451427
94.4,85.04764093,2.708219249,266194.0741,1.73406478,446.6322285
94.6,85.54202603,2.735374518,267896.5403,1.730135615,448.4322388
94.8,86.26703646,2.762786726,269868.2889,1.727079587,450.9413074
95,87.18103706,2.790461451,271602.5005,1.723150409,452.7741494
95.2,87.71696089,2.818440115,274578.3021,1.714418949,455.3554369
95.4,88.10713006,2.846709866,276974.5712,1.707433782,457.4169645
95.6,88.87197983,2.875237803,279977.6105,1.699138887,460.0507774
95.8,89.48524539,2.904062926,283646.8382,1.68735142,462.6911535
96,90.12345818,2.933175943,285775.6356,1.682985679,464.8982166
96.2,90.70334815,2.962585458,287588.0761,1.682112517,467.5604771
96.4,91.09168345,2.992303724,288767.2957,1.68298565,469.6942237
96.6,92.16945708,3.02227303,289231.3916,1.688661055,472.1485895
96.8,92.87664555,3.05256892,288580.7331,1.699138765,474.2517026
97,93.41059766,3.08318108,288605.2816,1.704814187,476.112989
97.2,94.1518555,3.114086677,288684.2938,1.711362746,478.4229123
97.4,94.76400922,3.145311483,288839.015,1.717474737,480.679217
97.6,95.80496534,3.176820478,289930.9965,1.717474705,482.5470773
97.8,96.42370731,3.208675194,291721.1138,1.715728397,484.8865421
98,97.40546785,3.240825071,294548.4069,1.71005293,487.5717895
98.2,98.03662546,3.273321979,296929.0948,1.705250617,489.817152
98.4,99.09325316,3.306116085,299289.7647,1.70219458,492.4520653
98.6,99.65605331,3.339273809,301118.2286,1.700448275,494.6481869
98.8,100.6118476,3.372737474,302505.1669,1.701757962,497.0894209
99,101.242851,3.406559738,302265.6549,1.711362528,499.4343597
99.2,101.9820655,3.440714326,301980.2358,1.719220802,501.2223362
99.4,102.8253272,3.475204978,302237.2262,1.725769357,503.5694664
99.6,103.5444767,3.510050757,301815.6984,1.733627632,505.262247
99.8,104.157833,3.545253833,302357.1212,1.737556761,507.3741134
100,104.7203537,3.580814084,302521.9157,1.744105324,509.6063447
100.2,106.0031155,3.616682057,303045.5623,1.747161288,511.3166437
100.4,106.6646435,3.652953237,303101.3404,1.75414642,513.3891194
100.6,107.3560849,3.689771038,303033.2118,1.76113155,515.3401373
100.8,108.0983208,3.726584831,302945.4421,1.767243535,517.1335874
101,108.8921192,3.763951098,304766.2746,1.76287779,519.0178589
101.2,109.4210764,3.801710864,306054.2836,1.762441201,521.2566564
101.4,110.8776135,3.839786249,308364.6706,1.755892575,523.3039799
101.6,111.2957334,3.878315711,312559.2249,1.74235883,526.0887932
101.8,112.3566501,3.917188032,315349.2659,1.736246789,528.5409739
102,113.4216848,3.95645064,316683.662,1.736683327,530.578443
102.2,113.9887211,3.996141987,319340.5096,1.73231759,533.2450842
102.4,114.8513182,4.036211871,319997.1561,1.735810139,535.2136132
102.6,115.8162902,4.076677159,318632.3827,1.749780411,537.1504117
102.8,116.42149,4.117573854,318825.2638,1.755019256,539.1430107
103,117.4446314,4.159060782,319569.1003,1.756328939,540.9331843
103.2,118.1846317,4.200776607,320232.2608,1.759384919,543.1873058
103.4,119.0569818,4.24290353,321261.1807,1.760694607,545.458936
103.6,120.128322,4.285226075,324191.6799,1.751963135,547.681331
103.8,120.872313,4.328426758,326365.2518,1.748470536,550.0831726
104,121.6046463,4.371627558,327918.3867,1.748907085,552.5550452
104.2,122.9764146,4.415436815,329865.7518,1.745851038,554.6450436
104.4,123.9326161,4.459714934,332802.3808,1.739739002,557.4036087
104.6,124.9412257,4.504434367,333884.0998,1.740612114,559.4257588
104.8,125.8681788,4.549608719,335937.486,1.737992653,561.8845048
105,126.7009844,4.595243433,337992.9368,1.73624634,564.5982044
105.2,127.4288169,4.641343852,339286.1474,1.736682889,566.7626007
105.4,128.5787727,4.6878784,340479.6895,1.738865712,569.3329616
105.6,129.5088421,4.734895591,342422.8229,1.736246252,571.524717
105.8,130.7086502,4.782366789,345029.7618,1.731443924,574.158545
106,131.4404275,4.830347103,348430.0746,1.72402218,577.2957086
106.2,132.4094672,4.878793058,350415.6183,1.721402719,579.7271017
106.4,133.3147489,4.927730868,352564.5384,1.719656403,582.6804393
106.6,134.0913216,4.977170801,352574.9794,1.725331813,584.762769
106.8,135.2013316,5.027083317,351267.1356,1.737555789,586.8757449
107,135.9898625,5.077518665,349455.4884,1.752835777,589.0051264
107.2,137.5052783,5.128410782,348490.9946,1.763313452,590.9178677
107.4,138.5530756,5.179846426,347767.6326,1.772481426,592.8349757
107.6,139.529201,5.231803743,348554.1766,1.774664253,594.8954255
107.8,140.5964459,5.284276817,350372.5564,1.772044789,596.9897987
108,141.8468226,5.337264266,352222.931,1.770298461,599.5185849
108.2,142.7394946,5.390806332,354208.1645,1.768115574,602.0714361
108.4,143.8361146,5.444872291,357188.0308,1.761130391,604.3955987
108.6,144.7836189,5.499491683,361105.6663,1.751962355,607.2887555
108.8,145.9833662,5.554642493,364456.4648,1.744977169,610.0352927
109,146.9682134,5.610362087,369334.0719,1.731443415,612.8835885
109.2,148.1636676,5.666626978,375105.3637,1.71659994,616.4639255
109.4,149.2849461,5.723462486,378464.4887,1.709614758,619.1546566
109.6,150.3487022,5.780872958,381814.3054,1.704375865,622.5566339
109.8,151.1667458,5.838877074,384195.9709,1.702629554,625.6872367
110,152.4843392,5.897429601,384530.9178,1.707431802,628.0617398
110.2,153.5770362,5.95658586,384948.9536,1.7131072,631.0227445
110.4,154.5580829,6.016344199,384887.333,1.720528887,633.9126222
110.6,155.8346667,6.076682615,385819.8403,1.722711705,636.3801344
110.8,157.1944496,6.137621512,387535.1605,1.722275092,639.1923306
111,158.4800514,6.199177799,390390.4508,1.718345909,642.5669587
111.2,159.6040381,6.261363606,393166.0566,1.714853299,645.8846837
111.4,161.262543,6.324137391,396687.9447,1.707868101,648.8041216
111.6,162.6986446,6.387557287,400293.6549,1.702192625,652.3483594
111.8,163.6866817,6.451645097,402918.888,1.700009738,655.612465
112,164.9993953,6.516354497,404460.941,1.700882842,658.2999197
112.2,166.15965,6.581724505,405440.9408,1.705685093,661.6067046
112.4,167.6645643,6.647727526,403156.3311,1.722274764,664.3062007
112.6,168.8821213,6.714413539,401027.7069,1.736681587,666.2605207
112.8,170.2836262,6.781756785,397520.0774,1.757200404,668.1688876
113,171.4777111,6.849790953,395452.2046,1.772916941,670.4186515
113.2,172.8265979,6.918497999,395911.8539,1.776846041,672.411273
113.4,174.0171922,6.987906292,400289.2808,1.766804858,675.5801873
113.6,175.3392713,7.058002773,404590.5086,1.755890528,678.3190727
113.8,176.717059,7.128799792,411244.3593,1.737554482,681.8895735
114,177.9348865,7.200319066,417912.4246,1.720528157,685.9404374
114.2,179.2966866,7.272546914,421297.1479,1.714416114,689.0426083
114.4,180.697539,7.345497936,421699.5269,1.720091499,692.2049641
114.6,182.0608349,7.419184324,420932.2865,1.729696028,695.0970451
114.8,183.772944,7.49358716,419040.0737,1.742356546,697.5569128
115,185.2684653,7.568752479,417653.4669,1.752834212,699.6994484
115.2,186.4283225,7.644695966,416872.9949,1.762438746,702.3912809
115.4,187.9802904,7.721375519,418698.1853,1.761128982,704.8172247
115.6,189.1532923,7.798851575,421884.2723,1.756326659,708.1338627
115.8,190.6900915,7.877080881,425613.6498,1.74977804,711.2710553
116,192.306738,7.956090825,429249.5648,1.742792847,714.1609554
116.2,193.7017952,8.035909849,434278.0387,1.732751662,717.9568711
116.4,195.1617093,8.11652627,437083.1247,1.729259045,720.9343067
116.6,196.6015445,8.197953988,439703.7923,1.728385857,724.4358769
116.8,198.39518,8.280175609,440984.3759,1.7314418,727.5752662
117,199.5517075,8.363267039,441064.4225,1.737553762,730.0646689
117.2,201.2785341,8.447154059,440605.407,1.746721704,732.9501955
117.4,202.3765778,8.53192716,439160.5622,1.757635951,735.035826
117.6,204.0632378,8.617511415,436992.5208,1.772042749,737.4475521
117.8,205.57743,8.70396757,436713.7766,1.77902784,739.7553193
118,207.1348211,8.791289312,438763.5049,1.778591218,742.7218174
118.2,208.6554717,8.879490928,442181.6665,1.772042601,745.402721
118.4,210.329235,8.968568214,448792.0743,1.756325983,749.248983
118.6,211.5873793,9.058569014,454954.506,1.741482522,752.5984532
118.8,213.0519268,9.14945986,460173.697,1.731004767,756.3878111
119,215.0001639,9.241230537,463540.2914,1.727075565,760.2461174
119.2,216.6177138,9.333946015,464379.7354,1.729694941,762.9718865
119.4,218.1926878,9.427595984,465923.024,1.731877747,766.6157166
119.6,220.0456725,9.522167661,467903.5755,1.73231426,770.2135963
119.8,222.0309451,9.617680458,471694.2969,1.727075344,773.8399287
120,223.8254189,9.714165925,475845.4112,1.72009015,777.136893
120.2,225.5706508,9.811624431,480492.7368,1.713541528,781.3880258
120.4,227.3532401,9.910059548,481245.7766,1.717034041,784.2790325
120.6,229.1648586,10.00948186,478975.3398,1.73144083,787.5201924
120.8,230.7257196,10.10992154,474993.1455,1.750213335,789.9308244
121,232.470548,10.21084816,471774.1888,1.765929837,791.9738014
121.2,234.4865374,10.31431334,469538.4703,1.779900045,794.5792206
121.4,236.2511124,10.41728457,471635.4261,1.778590274,797.1277333
121.6,237.9396701,10.52234173,477940.3209,1.765929661,800.9641548
121.8,239.8730401,10.62738091,484620.895,1.751959327,804.7940174
122,241.7904044,10.73400763,489862.7066,1.742354705,808.2540299
122.2,243.6743361,10.84170812,497042.5401,1.728384375,812.6890023
122.4,245.5331612,10.95049237,501319.8061,1.723582036,816.9051284
122.6,247.2544644,11.06037918,502650.6006,1.725764836,819.9657413
122.8,248.9906277,11.17136904,505816.2031,1.723581927,823.7222871
123,250.9956216,11.28345533,509394.9153,1.720962438,827.9734352
123.2,253.1545328,11.39665742,510796.7248,1.723145225,831.1336378
123.4,254.7587079,11.41821266,514055.1025,1.721398891,835.4121301
123.6,255.8807744,11.4181362,518612.5638,1.714413723,839.1806963
123.8,256.9170735,11.41806561,521277.2904,1.713103978,843.0521205
124,257.6223764,11.41801769,523498.2216,1.713977098,847.3393397
124.2,258.5616665,11.41795374,525770.4823,1.713540498,850.9010931
124.4,259.3548188,11.4178998,528353.5753,1.713977044,855.2102004
124.6,260.1080016,11.4178486,528616.2927,1.720089012,858.3977216
124.8,260.4823086,11.41782334,529561.7264,1.72532785,861.8817674
125,260.8994993,11.41779514,530463.9808,1.731439829,865.7663036
125.2,261.617709,11.41774634,529529.4531,1.741917506,869.2044006
125.4,262.0224093,11.417719,528674.8492,1.750212338,871.8995072
125.6,262.4566702,11.41768963,530134.105,1.752831749,875.6122508
125.8,262.9392274,11.41765696,530509.098,1.757634013,878.8500977
126,263.0553991,11.41764938,530872.4426,1.761999717,881.7301203
126.2,263.3814098,11.41762743,531686.5859,1.766365415,885.2371429
126.4,263.5050757,11.41761933,531817.2609,1.77160426,887.8643985
126.6,263.9368386,11.41759014,529881.7676,1.783828229,890.7159829
126.8,264.3011531,11.41756556,529751.9572,1.789940208,893.4723633
127,264.6388215,11.41754281,530384.7874,1.793869334,896.5219997
127.2,264.9723264,11.41752035,533296.3645,1.789940187,899.4709617
127.4,264.9386132,11.41752303,538066.1171,1.781645343,903.2942112
127.6,265.190514,11.41750615,541636.6698,1.776406486,906.4149688
127.8,265.3399935,11.41749629,544543.6396,1.774223628,909.8410136
128,265.851695,11.41746162,548167.4437,1.770731046,913.6664636
128.2,265.9853532,11.41745284,548479.1561,1.776843033,917.0268551
128.4,266.0407383,11.41744942,547438.6198,1.785137875,919.492162
128.6,266.3792393,11.41742661,547242.1822,1.791686427,922.5757191
128.8,266.375503,11.41742724,546373.1523,1.79910813,925.1602956
129,266.559123,11.41741504,543485.4521,1.811768676,927.090527
129.2,266.9392587,11.41738938,541797.6177,1.821809791,929.5481847
129.4,266.8922224,11.41739297,541492.9576,1.826612071,931.5889264
129.6,267.2690274,11.41736754,541262.1963,1.832287478,934.1571015
129.8,267.3802029,11.4173603,543565.7426,1.830541193,936.8149953
130,267.6704077,11.4173408,546748.2274,1.825738904,939.3798851
130.2,267.6791618,11.41734057,551747.3408,1.817007488,942.8179663
130.4,267.9102453,11.41732512,554100.3475,1.81613434,945.8818212
130.6,267.7574568,11.41733595,554004.0591,1.820936622,948.0297942
130.8,268.1400906,11.41731012,551596.6033,1.832287449,950.0377252
131,268.2454373,11.41730328,547997.7026,1.847130851,951.8913582
131.2,268.4357188,11.41729062,544166.8796,1.86153768,953.0610993
131.4,268.5843655,11.41728082,542128.9461,1.871142232,954.6510246
131.6,268.5897889,11.41728082,542010.9527,1.875507939,956.597663
131.8,268.5161063,11.41728623,542759.9123,1.877254225,958.3582817
132,268.6580915,11.41727688,542731.9831,1.880746786,959.8015783
132.2,268.8025748,11.41726736,541908.859,1.887295343,961.4111988
132.4,268.9104196,11.41726035,540090.2828,1.895590183,962.4025743
132.6,269.0524048,11.417251,538613.3998,1.903011881,963.674078
132.8,269.1194475,11.41724678,536018.4154,1.913053006,964.5593158
133,269.1340305,11.41724615,534574.6338,1.919164996,965.5517839
133.2,269.3826006,11.4172295,535107.3867,1.918728417,966.6438356
133.9,269.6685823,11.34815023,1.7977E+308,1.868522773,0
134.1,269.4074967,11.23401809,1.7977E+308,1.702189329,0
134.3,269.470329,11.11986377,1.7977E+308,1.472989687,0
134.5,269.2117414,11.00573146,1.7977E+308,1.145125065,0
134.7,268.8973633,10.89160297,1.7977E+308,0.749591974,0
134.9,268.6237872,10.77747168,1.7977E+308,0.426093052,0
135.1,268.2977514,10.66334399,1.7977E+308,0.233565353,0
135.3,268.2731508,10.54919565,1.7977E+308,0.151490051,0
135.5,268.2027521,10.43505045,1.7977E+308,0.125295806,0
135.7,267.776793,10.3209296,1.7977E+308,0.066358755,0
135.9,267.8129791,10.20677711,1.7977E+308,0.019645684,0
136.1,267.40867,10.09265477,1.7977E+308,0.015716547,0
136.3,267.1925498,9.978519552,1.7977E+308,0.021828538,0
136.5,267.1013338,9.864375779,1.7977E+308,0.024884534,0
136.7,267.0592467,9.750228642,1.7977E+308,0.019645684,0
136.9,266.6316221,9.636107905,1.7977E+308,0.009167986,0
137.1,266.5195887,9.521965557,1.7977E+308,0.000436571,0
137.3,266.1968836,9.407837636,1.7977E+308,0.008294845,0
137.5,266.18061,9.293688731,1.7977E+308,0.013970265,0
137.7,266.0419968,9.178977452,1.7977E+308,0.016153119,0
137.9,265.6292943,9.065426445,1.7977E+308,0.018772543,0
138.1,265.519759,8.951283927,1.7977E+308,0.026194247,0
138.3,265.3644255,8.837144544,1.7977E+308,0.030996525,0
138.5,265.0617714,8.722444498,1.7977E+308,0.032742809,0
138.7,264.8564762,8.608308536,1.7977E+308,0.028377101,0
138.9,264.5004634,8.494182895,1.7977E+308,0.02794053,0
139.1,263.9195567,8.380643406,1.7977E+308,0.034489092,0
139.3,263.9474159,8.266491479,1.7977E+308,0.045403362,0
139.5,263.5147952,8.152371084,1.7977E+308,0.051515354,0
139.7,263.3852751,8.038229934,1.7977E+308,0.053698208,0
139.9,263.1708203,7.9240946,1.7977E+308,0.049769071,0
140.1,263.243645,7.809939595,1.7977E+308,0.045403363,0
140.3,262.7710549,7.695821936,1.7977E+308,0.039727943,0
140.5,262.7706025,7.581671949,1.7977E+308,0.034052522,0
140.7,262.342978,7.467551211,1.7977E+308,0.026194248,0
140.9,262.0385921,7.353422035,1.7977E+308,0.018772545,0
141.1,261.7750083,7.239290065,1.7977E+308,0.014843408,0
141.3,261.6671384,7.125147433,1.7977E+308,0.020518828,0
141.5,261.316538,7.011021421,1.7977E+308,0.029686815,0
141.7,261.1528775,6.896882609,1.7977E+308,0.036235378,0
141.9,260.8235108,6.782755143,1.7977E+308,0.038854803,0
142.1,260.5590943,6.66862323,1.7977E+308,0.036235378,0
142.3,260.3637915,6.554486585,1.7977E+308,0.032742812,0
142.5,260.4349508,6.440331694,1.7977E+308,0.026194249,0
142.7,259.7129687,6.326231112,1.7977E+308,0.015498264,0
142.9,259.6758778,6.212083633,1.7977E+308,0.004802279,0
143.1,259.5105519,6.097944935,1.7977E+308,0.012223983,0
143.3,259.1587025,5.983819009,1.7977E+308,0.024011396,0
143.5,259.0100305,5.86967917,1.7977E+308,0.030559958,0
143.7,258.8338796,5.755541213,1.7977E+308,0.031869671,0
143.9,258.5494784,5.641410669,1.7977E+308,0.030123388,0
144.1,258.3042138,5.527277445,1.7977E+308,0.02575768,0
144.3,257.9989953,5.413148325,1.7977E+308,0.019209117,0
144.5,257.8769695,5.299006662,1.7977E+308,0.016589692,0
144.7,257.5159604,5.184881363,1.7977E+308,0.017899405,0
144.9,257.3764481,5.070740898,1.7977E+308,0.019645688,0
145.1,257.0137736,4.956615713,1.7977E+308,0.021828543,0
145.3,256.9325498,4.842471256,1.7977E+308,0.023138255,0
145.5,256.350044,4.728361124,1.7977E+308,0.024011397,0
145.7,256.1031141,4.614228013,1.7977E+308,0.026194251,0
145.9,256.3066718,4.500064056,1.7977E+308,0.028377106,0
146.1,256.0364264,4.385932543,1.7977E+308,0.03055996,0
146.3,255.4972207,4.271819445,1.7977E+308,0.029250248,0
146.5,255.1237212,4.157695002,1.7977E+308,0.029250248,0
146.7,255.0749726,4.043548321,1.7977E+308,0.020955402,0
146.9,254.7797463,3.929418518,1.7977E+308,0.011787413,0
147.1,254.5461395,3.815284495,1.7977E+308,0.003492567,0
147.3,254.4682465,3.70113981,1.7977E+308,0.00523885,0
147.5,254.0397891,3.58701913,1.7977E+308,0.015716552,0
147.7,253.648803,3.472895884,1.7977E+308,0.019209119,0
147.9,253.5742408,3.35875097,1.7977E+308,0.01964569,0
148.1,253.0558525,3.244636448,1.7977E+308,0.020518832,0
148.3,253.0329173,3.130488,1.7977E+308,0.018335977,0
148.5,252.9058954,3.016346679,1.7977E+308,0.017026265,0
148.7,252.5557113,2.902220639,1.7977E+308,0.013970268,0
148.9,252.0731288,2.788103664,1.7977E+308,0.015716552,0
149.1,251.8694989,2.673967589,1.7977E+308,0.020082261,0
149.3,251.4360454,2.559847251,1.7977E+308,0.023138258,0
149.5,251.2948676,2.445706899,1.7977E+308,0.028377108,0
149.7,250.9238662,2.331582284,1.7977E+308,0.029686821,0
149.9,250.840977,2.217437942,1.7977E+308,0.024884541,0
150.1,250.2318249,2.103329634,1.7977E+308,0.017899407,0
150.3,250.0107085,1.989194756,1.7977E+308,0.015279982,0
150.5,249.729638,1.875063983,1.7977E+308,0.009167989,0
150.7,249.2245727,1.760948549,1.7977E+308,0.008294847,0
150.9,248.8319212,1.646825416,1.7977E+308,0.012660557,0
151.1,248.6824165,1.532685635,1.7977E+308,0.017899408,0
151.3,248.5120944,1.418547279,1.7977E+308,0.019209121,0
151.5,247.8663037,1.30444148,1.7977E+308,0.023138259,0
151.7,247.498633,1.190316637,1.7977E+308,0.021828547,0
226.9,247.0930151,1.083182676,1.7977E+308,0.02750397,0
227.1,247.0917964,0.968461989,1.7977E+308,0.029686825,0
227.3,246.624136,0.854914745,1.7977E+308,0.033615963,0
227.5,246.4547129,0.740205575,1.7977E+308,0.033179393,0
227.7,246.0254228,0.626084952,1.7977E+308,0.030996538,0
227.9,245.4969756,0.51254187,1.7977E+308,0.029250255,0
228.1,244.992743,0.398426378,1.7977E+308,0.028377113,0
228.3,244.5068296,0.284309632,1.7977E+308,0.025757687,0
228.5,244.0034296,0.170194083,1.7977E+308,0.027940542,0
228.7,242.8172201,0.056125289,1.7977E+308,0.025757688,0
228.796,242.216247,0.001374431,1.7977E+308,0.024447975,0