File: GB3_Loc1_10um_250nm_test37.csv
Time On Sample,Displacement Into Surface,Load On Sample,Harmonic Contact Stiffness,Harmonic Displacement,Harmonic Load
0,0,0,207.4341205,0.435260931,2.174239133
0.2,0.032055804,0.000688133,4049.474784,0.298614319,2.240987294
0.4,0.235646572,0.001364521,7993.956339,0.253210972,2.293510447
0.6,-0.006253952,0.002071414,11811.12608,0.213483044,2.399650938
0.8,0.870153568,0.00270173,13735.31755,0.193837362,2.500320363
1,0.455885389,0.003420426,15365.89358,0.178557391,2.598801216
1.2,0.437979552,0.00411198,17701.41294,0.160221425,2.699470566
1.4,0.645733789,0.004788083,19598.27925,0.151926582,2.84828615
1.6,0.718591598,0.005473422,21580.15908,0.148870587,3.095582611
1.8,1.058744179,0.006140459,23891.21565,0.144068309,3.345067568
2,1.122442354,0.006826426,26530.71563,0.139266032,3.600023657
2.2,1.047080945,0.007519229,27984.21941,0.141448886,3.847320105
2.4,0.990871791,0.008208192,29479.89284,0.141448886,4.062883822
2.6,0.484175185,0.008928002,31769.64714,0.148434017,4.591397851
2.8,1.487985484,0.009544381,32506.64367,0.160657992,5.075048607
3,1.332685747,0.010240129,32481.60198,0.175937965,5.551039552
3.2,0.751046684,0.010965071,33105.71277,0.187288803,6.027030405
3.4,1.609135532,0.011591428,33606.03697,0.196893354,6.436273397
3.6,1.047481128,0.012315001,35250.80738,0.209990475,7.230685785
3.8,0.720646426,0.013022495,36794.83245,0.219595031,7.968198143
4,0.880105017,0.013696691,38354.57634,0.228326443,8.721029859
4.2,0.724805278,0.014392439,38632.83349,0.244479557,9.456353795
4.4,1.383880264,0.015032423,38417.12707,0.26237895,10.05380472
4.6,1.597463962,0.015702912,39384.03176,0.284644051,11.12724653
4.8,1.139063613,0.016419415,40197.19341,0.304289732,12.09126482
5,1.022067798,0.017112541,39686.14241,0.332666824,13.02245633
5.2,1.003329874,0.017798938,39006.95243,0.36366334,13.95364781
5.4,0.983759256,0.018485392,38341.62682,0.390730719,14.74149496
5.6,1.389695267,0.01914271,37495.52246,0.431768356,15.91013502
5.8,1.052035545,0.019850946,36575.2309,0.471932857,16.93324187
6,1.300592392,0.02051904,36262.33126,0.505112223,17.94868941
6.2,1.021221249,0.021223284,35990.15074,0.531743034,18.74857291
6.4,1.157364408,0.021899076,35561.68524,0.567105255,19.76511459
6.6,1.07950521,0.022589521,34940.64792,0.60465033,20.73132147
6.8,0.957513231,0.023282989,33559.52028,0.657475379,21.67017257
7,0.912961793,0.023971154,31205.49979,0.734311811,22.50944856
7.2,0.901718115,0.024657038,28956.31403,0.816823662,23.24039557
7.4,1.133621084,0.025326273,26906.82115,0.90064522,23.80939648
7.6,1.328052821,0.025998073,24920.49172,1.002366175,24.52502441
7.8,0.918781415,0.026711212,23696.95187,1.075273479,25.01961697
8,1.40881952,0.027362771,22828.54439,1.142068776,25.64880084
8.2,1.224375492,0.028060515,22360.54143,1.185289273,26.1258859
8.4,1.27891464,0.028741895,22139.86285,1.218905211,26.65440005
8.6,1.459190579,0.029414665,21956.61042,1.253830858,27.27701827
8.8,1.235609934,0.030115088,21950.91574,1.271730259,27.74863209
9,1.507482212,0.030781586,21983.10005,1.293995355,28.32419845
9.2,1.188141758,0.031488567,22006.28351,1.312331329,28.78049296
9.4,1.571595031,0.032147425,21971.23189,1.333723281,29.21271497
9.6,1.302216217,0.032850984,21882.76427,1.36297352,29.73028643
9.8,1.380070796,0.033530768,21842.55597,1.38436548,30.10013706
10,1.520377424,0.034206274,21742.18075,1.412742567,30.53892429
10.2,1.561593467,0.034888566,21594.59818,1.44286594,30.94597868
10.4,1.291381959,0.035592183,21441.2623,1.467750473,31.26987111
10.6,1.713139154,0.036248418,21245.72676,1.4939447,31.57187957
10.8,1.709389722,0.036933789,20857.66775,1.532799487,31.86951071
11,2.091177604,0.03759276,20550.47815,1.564232561,32.09054603
11.2,2.141552883,0.038277849,20367.02548,1.59173651,32.36519834
11.4,2.202753979,0.038955348,20477.68657,1.599158209,32.63000257
11.6,1.958355987,0.039657198,20850.11068,1.590863374,32.93748153
11.8,2.131137281,0.040333905,21719.84961,1.555937719,33.37408033
12,2.119061307,0.041016422,23148.39429,1.492198408,33.93870407
12.2,2.642407162,0.0416657,24526.63101,1.434571071,34.45846491
12.4,2.283097403,0.042375418,26041.01736,1.376507187,35.02855949
12.6,2.221059393,0.04306478,27883.16976,1.31451416,35.75294111
12.8,2.661968543,0.043719704,29017.57396,1.282644494,36.29130388
13,2.26602025,0.04443193,29966.49487,1.262998825,36.92048682
13.2,2.33804597,0.045112112,30481.94212,1.26081597,37.50918378
13.4,2.807266714,0.045765097,30545.03843,1.273039937,37.96000804
13.6,2.420478055,0.046476696,30206.49976,1.304473031,38.48305051
13.8,2.186905086,0.047177804,29993.6898,1.326738139,38.86493721
14,2.509571693,0.047840824,29615.20644,1.359480928,39.29825354
14.2,2.669030279,0.04851502,29192.44846,1.394406574,39.70968507
14.4,2.786854167,0.049192066,28934.89358,1.419727668,40.06749916
14.6,2.466681026,0.049899104,29033.76227,1.428459089,40.45266839
14.8,2.695253213,0.050568567,29144.53143,1.438500207,40.90677505
15,2.848050247,0.051243218,29390.27129,1.441556198,41.37510661
15.2,2.774354522,0.051933379,29686.00739,1.438500205,41.7504281
15.4,2.669016426,0.052625706,30162.78221,1.429332225,42.20562859
15.6,2.730217124,0.053306629,30652.38497,1.423220235,42.76149854
15.8,2.94213543,0.053977233,31207.71297,1.414052247,43.29657838
16,3.14655949,0.054648349,31731.29633,1.404884258,43.74630822
16.2,3.129486955,0.055334632,32349.04745,1.396589417,44.29670688
16.4,3.208174226,0.056014359,32756.16223,1.394843133,44.75628457
16.6,3.145303522,0.056703778,33250.4524,1.393533423,45.33622746
16.8,2.8917459,0.057406254,33416.21195,1.40095513,45.75860065
17,2.9387908,0.058088147,33409.5719,1.417544813,46.24225138
17.2,2.856768136,0.058778878,33294.78319,1.437190493,46.69964025
17.4,3.422581377,0.059425248,33233.75643,1.452033879,47.08590513
17.6,3.42632619,0.060110106,33139.75704,1.468186992,47.47216911
17.8,3.191920531,0.060811271,33053.00519,1.485213253,47.91095587
18,3.3122425,0.061488146,33068.49824,1.497000656,48.34208346
18.2,3.281846861,0.062175342,33151.78269,1.503985787,48.70318001
18.4,3.308907106,0.062858603,33223.10796,1.514900052,49.17807685
18.6,3.136953493,0.063555492,33287.43866,1.522321758,49.53370201
18.8,3.237290807,0.064233736,33473.02835,1.526687461,49.97030067
19,3.559957409,0.064896755,33734.22037,1.527997164,50.41565385
19.2,3.441296211,0.065589995,33931.30834,1.528870308,50.76471371
19.4,3.90052462,0.066243664,34096.80738,1.534109143,51.22429202
19.6,3.632811204,0.06694711,34256.25718,1.538038286,51.6105555
19.8,3.421720976,0.067646678,34339.09559,1.546769706,52.03839991
20,3.597000746,0.06831979,34299.21142,1.56030339,52.44764305
20.2,3.630722542,0.069002595,34231.8033,1.572527367,52.75840504
20.4,3.500403628,0.069696633,34291.6448,1.579949071,53.08667445
20.6,3.687341114,0.070368947,34476.35691,1.585187913,53.52546189
20.8,3.462927782,0.071069428,34788.45961,1.584314778,53.95440048
21,3.814738671,0.071730452,35202.42623,1.577329638,54.31987465
21.2,3.725221762,0.072421696,35745.50763,1.567725088,54.78164048
21.4,3.592404767,0.073115904,36296.53117,1.556374255,55.20948501
21.6,3.686913222,0.073794547,36936.45066,1.544150276,55.75003587
21.8,3.749779307,0.074475357,37262.32814,1.54153085,56.16256158
22,3.675250862,0.075165808,37438.73356,1.545896559,56.62651572
22.2,3.72062977,0.075853002,37533.66198,1.552881687,57.06311443
22.4,4.002492976,0.076530767,37464.95094,1.564669086,57.41983477
22.6,4.105326167,0.077227786,37380.46668,1.579075914,57.8411143
22.8,3.950856095,0.077949572,37486.56745,1.583441625,58.18360872
23,4.153610915,0.078653891,37837.50978,1.580822195,58.65631741
23.2,4.124043276,0.079381399,38237.19291,1.576019919,59.12136594
23.4,4.121121007,0.08011427,38617.69284,1.570344502,59.50981838
23.6,4.353017571,0.080838471,39119.56653,1.563795936,60.05255809
23.8,3.951233175,0.081613473,39558.48429,1.557247388,60.47821354
24,4.402126507,0.082337662,40112.42054,1.549389105,60.99688049
24.2,4.31676407,0.083105986,40653.74487,1.542840548,61.53086567
24.4,4.393776057,0.083870906,41067.93801,1.53891141,61.98716072
24.6,4.406669716,0.084647892,41518.71018,1.534545704,62.46752863
24.8,4.449539453,0.085430604,41747.50209,1.53934798,62.99823132
25,4.27174437,0.086236364,41679.89178,1.552881674,63.46984502
25.2,4.507797253,0.087021764,41600.05837,1.564232503,63.8396959
25.4,4.659747121,0.087820872,41579.0733,1.573837053,64.21939488
25.6,4.601024479,0.08864251,41585.46601,1.58475132,64.71289351
25.8,4.682193475,0.089462685,41797.95682,1.588243882,65.19326158
26,4.342851053,0.090320037,42152.85194,1.585187898,65.60906908
26.2,4.627195414,0.091143143,42553.75703,1.583005037,66.1167934
26.4,4.585122782,0.091996896,42833.55793,1.583441609,66.53369584
26.6,4.595508863,0.092855714,43229.23407,1.583005038,67.09941384
26.8,4.416872417,0.09373607,43420.5816,1.585624467,67.49552549
27,4.797805293,0.094586804,43550.03064,1.592173016,67.97480009
27.2,4.626661064,0.095484098,43678.41337,1.59872158,68.44750791
27.4,4.826064612,0.096364865,43893.40361,1.600031286,68.86878773
27.6,4.823122482,0.097268502,44093.74631,1.60265071,69.30648062
27.8,5.085808685,0.098162853,44371.04928,1.603523844,69.80873386
28,4.973781534,0.099092154,44812.52979,1.599594712,70.3339651
28.2,4.835939803,0.100032387,45297.14766,1.592173015,70.77603452
28.4,4.922091657,0.10096663,45672.99533,1.589117019,71.22795265
28.6,4.880007541,0.101919128,46170.92278,1.585624455,71.82540343
28.8,5.035270784,0.102867624,46655.70232,1.582131886,72.37580252
29,4.959876683,0.103841553,46804.71526,1.586497594,72.78832794
29.2,5.10514535,0.104810064,46955.47406,1.59304615,73.28510964
29.4,5.020589917,0.105799227,47066.32835,1.599594711,73.71186011
29.6,5.120056959,0.106800608,47165.62703,1.608326121,74.2349033
29.8,4.959724652,0.107809796,47073.57522,1.622296385,74.70323425
30,5.237385835,0.108819287,47094.32136,1.629718077,75.05776614
30.2,5.051237082,0.109855473,47078.2033,1.640195778,75.50421244
30.4,5.503762787,0.110863346,47195.45705,1.64456147,75.9014199
30.6,5.330101444,0.111924468,47433.28041,1.647180899,76.41789706
30.8,5.288837204,0.112987122,47721.28664,1.645434618,76.81729167
31,6.041129083,0.114005756,48028.39019,1.644998025,77.32611164
31.2,6.437026748,0.115059167,48655.88992,1.634520319,77.88088841
31.4,6.266691289,0.116162149,49384.56376,1.620113495,78.38642329
31.6,6.41527633,0.117254226,50439.20308,1.597411819,78.99591114
31.8,6.63880255,0.118352131,51961.83108,1.564232448,79.76296848
32,6.734925293,0.119469991,53683.97703,1.528433656,80.57926585
32.2,6.758602378,0.120603879,54849.36617,1.507478267,81.23252282
32.4,6.765624249,0.121750392,55827.04867,1.493071437,81.92298337
32.6,6.881727699,0.122900822,56718.44422,1.484776593,82.80055797
32.8,7.051954907,0.124059117,57309.73153,1.482593736,83.56542684
33,7.021501523,0.125242832,57845.66988,1.479537742,84.19461034
33.2,7.294980041,0.126417576,58518.05385,1.476481741,85.0076256
33.4,7.195410304,0.127629745,59193.17303,1.471679467,85.69152046
33.6,7.284860664,0.128841183,60086.39461,1.466004047,86.61942979
33.8,7.341834548,0.130067009,60656.51425,1.464257764,87.29675969
34,7.567011173,0.13129359,61127.87158,1.467750322,88.13931931
34.2,7.570689793,0.132547598,61587.02983,1.469933175,88.92607235
34.4,7.701769107,0.133805548,61987.51878,1.472116025,89.65264289
34.6,7.648821599,0.135088733,62610.8976,1.469933174,90.44377268
34.8,8.127131314,0.136348314,63486.27656,1.463821173,91.3880966
35,7.776076382,0.137677769,64567.26453,1.452906918,92.33241795
35.2,8.022894168,0.138979212,65450.06418,1.444175499,93.10932395
35.4,7.619376467,0.140338507,66576.04667,1.432388104,93.98361424
35.6,7.952791304,0.141660809,67711.95542,1.424093255,95.10629749
35.8,7.911492328,0.143022149,68662.70859,1.41972755,96.14800673
36,8.061711365,0.144383999,69317.63206,1.421910399,97.12843939
36.2,7.818064581,0.145786625,69750.78987,1.42540297,97.88345886
36.4,8.047386313,0.147170784,69864.46991,1.435444088,98.68115499
36.6,8.10766956,0.14858048,69571.54448,1.456399476,99.62657192
36.8,8.220410863,0.150000857,69193.8473,1.477354859,100.482262
37,8.432241094,0.151428589,68734.13706,1.496127389,101.1158232
37.2,8.616590754,0.152872577,68204.64003,1.517955913,101.8675615
37.4,8.752642473,0.154334444,68159.49713,1.528870175,102.578813
37.6,8.411558885,0.155843665,68524.23145,1.53323589,103.5034381
37.8,8.77659798,0.157319474,69157.3137,1.531489597,104.424783
38,9.060031327,0.158815869,69949.11231,1.52494103,105.215914
38.2,8.779729157,0.160365963,71034.1687,1.514899916,106.1755548
38.4,9.106459025,0.161890012,71767.92029,1.511407342,107.0159264
38.6,9.122592281,0.163450738,72804.97019,1.505731924,108.0948396
38.8,9.072940899,0.165031627,73521.81672,1.506168497,109.0916851
39,9.038276155,0.166627416,73857.41561,1.511407345,109.8631186
39.2,9.356671786,0.168214776,74047.07446,1.52188503,110.8107251
39.4,9.500199831,0.169830184,74152.92815,1.531489579,111.6434362
39.6,9.665376034,0.171460302,73973.56601,1.545023262,112.3568766
39.8,9.92547742,0.173100407,73687.44685,1.560303225,113.0309246
40,9.792545359,0.174784098,73478.50552,1.575146628,113.8483157
40.2,9.707907594,0.176481227,73290.99402,1.589116889,114.6252203
40.4,9.851425973,0.178179737,73053.09798,1.602650573,115.2358023
40.6,10.01242893,0.179894163,73110.4108,1.610945409,115.9251695
40.8,9.743759849,0.181655258,73454.83702,1.614437982,116.7381832
41,9.946393446,0.183401719,73854.27487,1.617930541,117.5851197
41.2,10.29141565,0.185155997,74140.10544,1.620986525,118.2329067
41.4,10.22092156,0.186956424,74585.45989,1.620986527,118.9397804
41.6,10.00970009,0.188784587,74913.76344,1.625352239,119.8020349
41.8,10.27894088,0.190598033,74933.34379,1.633647072,120.4257484
42,10.61229696,0.192425368,74996.18136,1.642378473,121.1763934
42.2,10.67752347,0.194289539,75204.0886,1.646307607,121.8055768
42.4,10.70610927,0.196174958,75397.57083,1.650673312,122.4435144
42.6,10.9761741,0.198062719,75896.64455,1.651546445,123.2981111
42.8,10.89567259,0.199993549,76765.43015,1.642378466,124.0235871
43,10.97421337,0.201932732,78091.38695,1.627535064,125.0083967
43.2,11.0352653,0.203892755,79228.37019,1.614874516,125.8290711
43.4,10.92228193,0.205884338,80612.81435,1.599157979,126.7427547
43.6,11.03995242,0.207880151,82223.35551,1.582568295,127.8993588
43.8,10.99940875,0.20990687,82755.98099,1.582568296,128.6893946
44,11.07377447,0.211946032,83158.74144,1.586934,129.645754
44.2,11.01407408,0.214014971,83106.98387,1.596975124,130.3591931
44.4,11.26163533,0.216083471,82806.48359,1.613128228,131.1897166
44.6,11.18361085,0.218195165,82228.91997,1.632337335,131.8320307
44.8,11.30376504,0.220314492,81716.87087,1.651109866,132.5586015
45,11.44723218,0.222453544,81352.39107,1.66508012,133.1286972
45.2,11.32340209,0.224632414,81089.36508,1.678177241,133.8454192
45.4,11.22121949,0.226831677,80995.0248,1.686472085,134.4330214
45.6,11.48625233,0.229027788,81375.48805,1.686472077,135.1147295
45.8,11.45567627,0.2312663,82189.20846,1.679923519,135.9671362
46,11.27438001,0.233537655,82901.50556,1.674248108,136.6827635
46.2,11.68429376,0.23579105,83971.57176,1.664643543,137.6183342
46.4,11.75363305,0.238090725,84718.80437,1.659404695,138.3996163
46.6,11.63478086,0.240426348,85087.3749,1.661150981,139.1415053
46.8,11.5600587,0.242782432,85216.83116,1.66638983,139.8057041
47,11.62938985,0.245152178,85204.50594,1.675557809,140.5902691
47.2,11.75700538,0.247553898,85020.8165,1.686035499,141.171307
47.4,12.33510687,0.249936899,84925.92326,1.695203463,141.7600068
47.6,13.0472693,0.25233447,84820.83131,1.706117705,142.5029942
47.8,13.15655856,0.254797681,85019.30372,1.709610266,143.0993513
48,13.20755783,0.257277065,85433.7531,1.710919976,143.8499951
48.2,13.37596259,0.259785813,86114.16957,1.705244554,144.5295143
48.4,13.73088782,0.262307022,87095.51271,1.69476685,145.3042327
48.6,13.59785152,0.26488705,89160.8904,1.669009192,146.4487994
48.8,13.61802787,0.267482491,90950.53163,1.646744094,147.40297
49,13.97377681,0.270080929,93064.02211,1.622296133,148.5880255
49.2,14.10719344,0.272720888,95031.58463,1.602650455,149.8091898
49.4,14.34302833,0.27538024,96344.94582,1.593045897,150.8891985
49.6,14.49225996,0.278072291,96879.66957,1.593919033,151.8017892
49.8,14.47744778,0.280802476,97008.95275,1.600904163,152.6487251
50,14.83567924,0.283534481,96895.30768,1.613128127,153.6422902
50.2,14.90079925,0.28631428,96932.48981,1.620549825,154.439986
50.4,14.72110403,0.289138865,96707.07661,1.631900664,155.2004768
50.6,14.88697347,0.291967904,96511.5595,1.644997775,156.1787212
50.8,15.16691864,0.294817662,96628.4171,1.650673184,156.9249897
51,15.13293493,0.297717428,96929.07062,1.655475461,157.8955737
51.2,15.05065158,0.300649701,97001.53822,1.661587451,158.6133899
51.4,15.17986905,0.303596804,97615.06675,1.661150877,159.6288386
51.6,15.40484286,0.306566967,98361.91614,1.657658306,160.5315816
51.8,15.33920305,0.30958699,98767.94024,1.660277731,161.5109189
52,15.29854054,0.312635555,99429.2067,1.657658309,162.3600434
52.2,15.57096733,0.315693273,100275.4779,1.654165737,163.409414
52.4,15.76012116,0.318787532,100537.6255,1.658531437,164.2421261
52.6,15.78689608,0.321924041,100626.5335,1.665516565,165.0540464
52.8,15.94273488,0.325083179,100941.9993,1.670755406,166.0038414
53,15.72385776,0.328299826,100726.2041,1.682106247,166.6888299
53.2,15.87052948,0.331523644,100475.9806,1.695203358,167.4941858
53.4,15.65580833,0.33480455,100717.6481,1.699132499,168.2240379
53.6,15.95568811,0.338083125,101032.4534,1.702188484,168.9921908
53.8,15.88085186,0.341420314,101255.4455,1.707427333,169.8708595
54,16.02417752,0.344775734,101527.8327,1.709610182,170.5460018
54.2,16.40564967,0.348148587,101649.3853,1.715722157,171.3743375
54.4,16.59310021,0.351568833,101504.0769,1.724453561,172.0308788
54.6,16.49743087,0.355042829,101547.3013,1.730128981,172.7147736
54.8,16.54997697,0.358541475,101801.3083,1.733621543,173.5463906
55,17.24202783,0.362031279,102234.9456,1.732748381,174.2445152
55.2,17.81833016,0.36556413,103246.5783,1.725326665,175.2008779
55.4,18.08902974,0.369153411,104118.3749,1.719214668,176.0062348
55.6,18.2847827,0.372783836,104650.5197,1.718778093,176.7929892
55.8,18.54381612,0.376446585,105458.5584,1.716158662,177.7515386
56,18.4764293,0.380168581,105982.727,1.715722093,178.4857683
56.2,18.79957152,0.383901021,106381.2501,1.718341507,179.3458365
56.4,18.55314684,0.387710141,107087.143,1.715285521,180.1676044
56.6,18.77968776,0.391525065,108109.3946,1.707863816,181.0911382
56.8,18.74725647,0.395396079,109347.4214,1.698259266,182.1755222
57,18.96171434,0.399289146,110245.822,1.692147272,183.0640403
57.2,19.00796353,0.403232826,111349.1054,1.684725572,184.1757811
57.4,19.01798593,0.407218622,111843.3637,1.684725572,185.0719577
57.6,19.05631526,0.411242506,111950.9599,1.690400988,185.9407788
57.8,19.58093305,0.415273404,111640.6906,1.703061516,186.8391472
58,19.52599127,0.41938458,111515.2231,1.711356358,187.5493036
58.2,19.77247983,0.423516331,111517.1573,1.719214619,188.4137488
58.4,20.07808482,0.42768549,112052.1617,1.718341469,189.2191064
58.6,20.05060745,0.431919384,112953.7064,1.713102624,190.1262254
58.8,20.33705066,0.436174336,114457.3936,1.701315211,191.2970561
59,20.50857718,0.440479826,115322.3621,1.696512931,192.1801028
59.2,20.63679859,0.444831512,116327.126,1.691710652,193.2929385
59.4,21.18469254,0.449198207,116997.5839,1.690400923,194.2274168
59.6,21.16968043,0.45364747,117945.1962,1.685598649,195.2341111
59.8,21.31953648,0.458130031,119191.7758,1.678613517,196.4662184
60,21.04221541,0.462686978,120571.5538,1.668572404,197.5287166
60.2,21.54928651,0.467235869,122405.5451,1.655038704,198.8877566
60.4,21.74825559,0.471851736,123502.1389,1.649363282,199.9907448
60.6,21.72405737,0.476529241,123785.5676,1.654165558,201.0247945
60.8,21.79228269,0.481247393,124068.2365,1.660714113,202.218603
61,22.0053912,0.486003024,124035.5037,1.669008946,203.1125926
61.2,22.01781496,0.490820263,123606.5772,1.683415771,204.1083445
61.4,22.30668741,0.495666883,123816.4906,1.688218038,205.0067117
61.6,22.21001702,0.500588598,124312.8638,1.691274034,206.2092733
61.8,22.99932699,0.505498818,124348.4549,1.697385997,207.0408954
62,22.93928362,0.510516857,124420.3097,1.704371126,208.0661911
62.2,23.40299874,0.515549249,125091.4701,1.70262483,208.9941038
62.4,24.00826591,0.520622431,125571.4356,1.703497953,209.8924735
62.6,24.03397233,0.525786412,126405.4097,1.70218824,211.0961299
62.8,24.2869981,0.530986689,127813.2888,1.692147112,212.173951
63,24.41594641,0.536247857,129681.9349,1.678613424,213.5603452
63.2,24.45079421,0.541568243,130398.9208,1.677303712,214.5889242
63.4,24.46315305,0.546943669,131095.568,1.676430571,215.6393879
63.6,24.55377881,0.552367768,131914.1751,1.676430568,216.9984257
63.8,24.44621716,0.557859793,132051.3953,1.682105987,217.9547845
64,24.99647708,0.563361948,132237.8449,1.689091098,219.1201468
64.2,25.1062356,0.568949746,132826.963,1.689527665,220.1104283
64.4,25.47412265,0.574575793,133358.6247,1.690837365,221.1444811
64.6,25.93609751,0.58025192,133895.577,1.693893344,222.4280201
64.8,25.95507268,0.586015657,134602.1312,1.693893344,223.6065088
65,26.16139381,0.591853538,135212.3727,1.693456767,224.5661531
65.2,26.3926923,0.597719349,136141.5693,1.691273908,225.8332764
65.4,26.39332779,0.603659997,136967.4822,1.689527626,226.9362633
65.6,26.61878362,0.609644895,138215.0364,1.683415633,228.1410158
65.8,26.59775867,0.615676474,139545.8857,1.678176789,229.5668005
66,26.68080983,0.62179199,140458.5417,1.675557364,230.6686938
66.2,26.84462514,0.627963262,140653.1104,1.682542486,231.8997073
66.4,26.94931199,0.63420066,140492.7007,1.691710462,232.8878009
66.6,27.2296899,0.64048867,140012.9872,1.704370996,233.8135239
66.8,27.06790014,0.646870298,139145.3669,1.72227039,234.7687879
67,27.48565772,0.653276014,138406.4014,1.736677201,235.4701952
67.2,28.18985441,0.659726476,138391.2657,1.744535447,236.4779888
67.4,28.9789783,0.666235887,138705.9707,1.747154844,237.3457225
67.6,29.1385782,0.672854032,139628.761,1.743225705,238.3797736
67.8,29.40808593,0.679531083,141127.422,1.733621148,239.6523689
68,29.68091664,0.686274917,142703.1012,1.722270308,240.7859965
68.2,29.80385461,0.693096865,144103.4883,1.714412037,242.1505059
68.4,29.62368412,0.700008306,145469.8244,1.706117205,243.3585385
68.6,29.90315244,0.706957467,147006.6579,1.696949217,244.6355106
68.8,29.94529499,0.713992537,148547.5533,1.68996409,246.064579
69,30.43458579,0.721067503,149581.4414,1.687344652,247.2288474
69.2,30.57913316,0.728237293,151307.2759,1.679922951,248.769529
69.4,30.8610666,0.735469662,152205.0248,1.679049801,249.9753761
69.6,31.19961476,0.742770712,152447.3593,1.684725207,251.168093
69.8,31.24338086,0.750165409,152341.2002,1.694329754,252.4581948
70,31.65435617,0.757609222,152387.0156,1.700005155,253.4616103
70.2,31.62732596,0.765157961,151684.3857,1.714411981,254.5689733
70.4,31.90588548,0.772761545,151040.4531,1.727072514,255.4629643
70.6,32.03371856,0.780451899,151020.7099,1.733621066,256.4423047
70.8,31.975852,0.788232237,151061.3997,1.741042765,257.5704579
71,32.13447668,0.796075843,151104.2969,1.746718176,258.4261494
71.2,32.43881357,0.803988288,151873.3055,1.746281596,259.6046411
71.4,32.18690191,0.812018375,152771.6178,1.743225611,260.6518206
71.6,32.78849177,0.820070551,153299.0839,1.744098731,261.6847825
71.8,33.76811508,0.828177681,154549.8863,1.738423286,263.0033423
72,34.25227625,0.836400222,155555.8248,1.734057566,264.0964857
72.2,34.26429057,0.84473792,156718.5137,1.729691864,265.4412985
72.4,34.73427659,0.853127905,157469.5883,1.728382136,266.5147455
72.6,34.63469042,0.861641367,158324.269,1.72794557,267.9252113
72.8,34.89898139,0.870215258,158546.8719,1.731874696,268.8968929
73,35.28733368,0.878866753,158588.938,1.738859809,270.0589722
73.2,35.2826445,0.88763227,158326.2488,1.747154646,270.9070029
73.4,35.25546237,0.89648729,158625.8512,1.75021064,271.9016607
73.6,35.49473182,0.905412952,159495.0432,1.749337493,273.2322506
73.8,35.51499243,0.914443436,160427.9661,1.746281499,274.298034
74,35.70927545,0.923552592,162223.8819,1.736676945,275.7281988
74.2,35.90438051,0.932753248,163888.4053,1.727072391,276.9427996
74.4,36.5757755,0.942013664,165070.2443,1.722706666,278.1913262
74.6,36.56601635,0.95141417,166001.389,1.722706667,279.6827655
74.8,36.65283869,0.960902238,166336.3126,1.725762657,280.7332309
75,36.92867138,0.9704726,165842.956,1.737986618,281.9040627
75.2,38.05717102,0.980080398,165351.7741,1.748464271,282.7783653
75.4,38.60277399,0.989824831,164756.1915,1.759815083,283.6187421
75.6,39.06925967,0.9996727,164740.8959,1.766800194,284.8169325
75.8,39.07192357,1.009651399,165037.6243,1.768983045,285.7492192
76,39.23028951,1.019719528,165796.8963,1.767673329,286.9889878
76.2,39.77667884,1.029862161,166108.3838,1.769856164,287.9201851
76.4,40.09073483,1.04012271,167151.1512,1.76592702,288.9903491
76.6,40.55882713,1.050475647,168221.1708,1.763744154,290.3132815
76.8,41.29669999,1.060914165,169167.0296,1.761124708,291.3725073
77,41.66317937,1.071483094,170482.4101,1.756322423,292.6823079
77.2,41.99550597,1.08216058,172171.1774,1.746717865,293.9133242
77.4,42.39610095,1.092940636,173684.0742,1.738859587,295.2121839
77.6,42.25626529,1.103866183,175824.3491,1.727072193,296.942165
77.8,42.68597918,1.114862333,177211.7699,1.720087054,298.2388362
78,42.90667416,1.125983383,178009.4456,1.719650477,299.7368443
78.2,43.27057942,1.137206177,178689.7135,1.719650466,300.9569183
78.4,43.57784841,1.148545707,179097.7876,1.722269878,302.1583895
78.6,43.99418698,1.159991648,179117.3256,1.730128131,303.6005939
78.8,44.22065807,1.171565727,179645.9394,1.731874405,304.7637672
79,44.67693903,1.183240127,181297.7797,1.725762406,306.3843318
79.2,44.95334457,1.195044265,182633.7555,1.720523554,307.7149231
79.4,45.35464031,1.206958436,184162.0274,1.714411557,309.1505606
79.6,45.62269118,1.219001558,186337.1445,1.705243573,311.0578134
79.8,46.41199404,1.231129696,186734.5097,1.708736111,312.291023
80,46.60507427,1.24342071,186728.7902,1.717467511,313.7605813
80.2,47.25029263,1.255804052,187016.1339,1.721833193,314.9171933
80.4,47.5082941,1.268338622,187150.0032,1.727508599,316.0978738
80.6,47.7179847,1.281002413,187126.9723,1.735803428,317.5269448
80.8,48.13250307,1.293779332,188466.5466,1.731001142,318.8630097
81,48.59447003,1.306681352,189862.993,1.727508565,320.5098363
81.2,48.80661391,1.319730162,190784.6819,1.726635418,321.8010345
81.4,48.86969045,1.332920265,192153.9075,1.722706284,323.2311992
81.6,49.88868351,1.346177113,194046.4805,1.716594268,325.1001615
81.8,50.10994087,1.359622026,195753.176,1.710045707,326.5959815
82,50.78500037,1.373170803,198177.2405,1.699568,328.5294997
82.2,51.13196285,1.386878437,200072.0754,1.691709725,330.1402164
82.4,51.39564001,1.400729337,201528.9018,1.687780585,331.7826651
82.6,51.91244791,1.414631724,202682.7325,1.688217139,333.7697992
82.8,52.05450283,1.428912423,202198.1426,1.698694821,335.0161328
83,52.42554823,1.443178889,201519.8913,1.712228487,336.4933531
83.2,52.76411033,1.457518567,200991.5813,1.722706162,337.6237005
83.4,53.1809204,1.472069443,200388.1184,1.734056975,338.7912533
83.6,53.47280949,1.486775059,201077.1222,1.736676387,340.4260417
83.8,54.20933957,1.501597949,203516.352,1.725325538,342.3114158
84,54.72102515,1.516585248,205942.8601,1.713101556,343.9396417
84.2,54.78636964,1.531753756,209832.87,1.692582753,346.1871991
84.4,55.14230635,1.547054679,213535.7093,1.673373653,348.2279497
84.6,55.48823286,1.562510008,215726.1852,1.665951949,350.1844452
84.8,55.49023899,1.578144408,216984.4456,1.666388519,352.2273795
85,56.13506602,1.593891594,217368.583,1.671190772,353.8282517
85.2,56.75406116,1.609798762,216918.1374,1.682978149,355.6052951
85.4,56.82845635,1.625903275,216403.1791,1.693455831,356.9829369
85.6,57.36331206,1.642137803,217264.2107,1.696511806,359.0204077
85.8,57.6899755,1.658549841,218299.7732,1.696511796,360.625653
86,58.28557966,1.675108201,219486.7675,1.696948348,362.5340047
86.2,59.17177438,1.691812996,220508.5278,1.696948321,364.0954878
86.4,59.29103917,1.708738296,221600.4511,1.696948317,365.7893636
86.6,59.71921342,1.725811734,222129.3804,1.702623716,367.8377753
86.8,59.85675782,1.743076661,222245.1716,1.707862554,369.2307373
87,60.67209427,1.760468395,222481.6664,1.713974511,371.0077841
87.2,60.74464809,1.778085989,222948.6555,1.717467071,372.4762475
87.4,61.5141455,1.795832553,223271.719,1.722269318,373.9293998
87.6,61.9380545,1.813781342,224711.3588,1.721396165,375.9624928
87.8,61.91395363,1.831941256,226283.5957,1.717467034,377.5710171
88,62.61510725,1.850233648,228674.5457,1.709608749,379.7025935
88.2,63.15303164,1.868721009,230359.4373,1.704806459,381.4369638
88.4,63.84498263,1.887383718,231930.5049,1.700877308,383.2720027
88.6,64.58104455,1.906230755,232738.1128,1.703496706,385.3784128
88.8,65.0572842,1.925285022,232702.7631,1.710918384,387.1926608
89,65.62093434,1.944524805,232398.0038,1.719213198,388.6151736
89.2,65.79486165,1.963984652,232210.3298,1.727944596,390.2805991
89.4,66.14113368,1.98362811,233263.2126,1.727508014,391.881469
89.6,66.63393673,2.003458895,235110.6377,1.723578867,394.0152341
89.8,67.14337046,2.023487788,237050.4007,1.717466868,395.7430355
90,67.42379021,2.043733601,239912.0584,1.707425747,398.0759489
90.2,68.20380211,2.064148533,242086.2763,1.700440602,399.9252158
90.4,68.65820716,2.084791028,242861.2446,1.703060009,401.6989762
90.6,69.02099187,2.105647139,243183.6176,1.710045118,403.7583306
90.8,69.38208682,2.126712917,242889.4768,1.718339939,405.2081963
91,70.07623433,2.147967561,242055.1055,1.731437021,406.8418982
91.2,70.44144329,2.169458236,241212.9153,1.744097541,408.3858682
91.4,71.13554086,2.1911422,241741.8345,1.74671694,409.9178064
91.6,71.14847023,2.213090841,242539.1372,1.748026651,411.5536873
91.8,71.88082069,2.235210476,244102.2522,1.744970637,413.4259331
92,72.20096222,2.257581221,245909.9235,1.739295215,415.0957397
92.2,73.09896657,2.28013655,249078.9715,1.727071226,417.3498759
92.4,73.82957326,2.30293005,250835.3637,1.722705502,419.1400527
92.6,74.53683792,2.325954095,253695.8594,1.713974079,421.6009971
92.8,74.98594085,2.349227271,254691.9837,1.714410635,423.3178569
93,75.71646679,2.372714824,254277.4763,1.724888293,425.2294959
93.2,76.21464397,2.396454269,252594.9254,1.74104137,426.4681779
93.4,76.78856844,2.420427154,251185.1875,1.755448163,427.6576189
93.6,77.04937237,2.44466236,247946.4203,1.782515498,428.8908257
93.8,77.96797535,2.469095977,246857.6519,1.794302859,429.8778395
94,78.45688024,2.493804592,247086.2848,1.798668543,431.2598648
94.2,79.15476217,2.518746994,248311.2439,1.79648567,432.8815309
94.4,79.45791854,2.543967163,249920.1008,1.79124682,434.397051
94.6,80.1465822,2.569414346,252231.2743,1.782515397,436.1204806
94.8,80.36974083,2.595149193,253250.6286,1.78207882,437.8110779
95,80.97424271,2.621116289,253445.3319,1.78557136,439.1022836
95.2,81.36471218,2.647359,253903.7653,1.788627337,440.6550099
95.4,82.18148974,2.673835888,253914.9816,1.793429581,441.9046377
95.6,82.91996321,2.700584226,254217.3052,1.796048977,443.2768197
95.8,83.55515149,2.727608516,255964.6674,1.790810116,445.0582436
96,84.32187365,2.754895282,259091.5473,1.777276421,447.1088519
96.2,84.70385986,2.782482633,262103.8766,1.764179309,448.9646814
96.4,85.54462756,2.810315476,265537.5033,1.749772473,450.9890298
96.6,86.30625688,2.838433583,270218.1185,1.73143651,453.7388528
96.8,87.00290332,2.866838543,273812.2028,1.717466249,455.8518326
97,87.83274739,2.89551986,277095.3848,1.708298253,458.4342405
97.2,88.00223259,2.924534737,279946.7265,1.700003419,460.5636248
97.4,89.1217863,2.953775646,283210.8869,1.689962275,462.9206247
97.6,89.66758053,2.983349991,285998.6978,1.684723419,465.8488077
97.8,90.11175169,3.013228418,287053.9743,1.687779395,468.3097494
98,90.88896501,3.043384096,287115.5939,1.69389135,470.1798109
98.2,91.62117767,3.073845903,284101.2872,1.717029534,471.9185625
98.4,92.17349313,3.104626039,282429.3466,1.732309464,473.4548786
98.6,92.91479384,3.135702432,281460.9474,1.743660258,475.0535678
98.8,93.92418525,3.167072688,281672.1115,1.749335635,477.0024169
99,94.56965331,3.198783101,282345.6484,1.752828173,479.0212925
99.2,95.34998054,3.230802661,283988.1739,1.749772159,480.8443009
99.4,96.06365492,3.263148621,284530.2765,1.752828125,482.5950903
99.6,96.50333562,3.295838434,283977.8246,1.761996079,484.1500062
99.8,97.50837639,3.328817783,282305.0082,1.777712562,485.6863296
100,98.119515,3.362155773,282997.9995,1.779458822,487.5049599
100.2,98.91045654,3.395985702,283918.511,1.779022226,489.0927077
100.4,99.94369173,3.429969854,285340.6345,1.776402773,490.8818009
100.6,100.3398773,3.46433996,289360.4414,1.761122815,493.5211039
100.8,101.1382132,3.499028049,293163.9383,1.745842845,495.6658209
101,101.7250251,3.53390297,297349.3116,1.731872591,498.4637904
101.2,102.7730874,3.569273028,300612.6717,1.721831451,500.685107
101.4,103.6279237,3.605011736,304595.2634,1.709607469,503.2303145
101.6,104.1604662,3.641131528,308472.1125,1.700439486,506.3664033
101.8,104.9735839,3.677595088,309921.6383,1.70087603,508.5078367
102,106.0830975,3.714404609,310440.111,1.706987973,510.9283057
102.2,106.5688813,3.751626913,310617.186,1.712663365,512.8432279
102.4,107.1553775,3.789216108,311056.7026,1.717029045,514.9321343
102.6,108.2406125,3.827148763,311206.018,1.724450697,517.5189272
102.8,109.4090724,3.865456782,312590.2693,1.723577521,519.6362944
103,109.9637932,3.904191977,314040.0518,1.723577503,522.2055707
103.2,110.9980996,3.943283273,315172.9895,1.72401404,524.2846378
103.4,111.8283507,3.982781384,315829.2114,1.727070003,526.3286857
103.6,112.4303978,4.022691914,316486.958,1.731872251,528.9209429
103.8,113.4062772,4.062977859,316035.0163,1.739730475,530.6093662
104,114.1273058,4.103685111,315539.3423,1.749771557,532.7518938
104.2,114.5485176,4.144821224,315509.3364,1.75588352,534.4217057
104.4,115.3418948,4.18634507,315298.1579,1.764614889,536.5171829
104.6,116.380035,4.228269178,316369.9452,1.765487995,538.3970999
104.8,117.2124513,4.270628717,319035.9183,1.759812561,540.8689952
105,118.0889507,4.313410794,322453.4913,1.74933486,543.16472
105.2,118.995377,4.356620624,326724.5013,1.736237739,546.1443415
105.4,119.8842663,4.400265673,329674.8367,1.728379456,548.5866947
105.6,121.1111776,4.444326046,331581.5443,1.725759999,551.0082625
105.8,122.1973124,4.488838721,332170.9034,1.730125659,553.6202255
106,122.9478202,4.533821748,331122.5727,1.74016674,555.3009871
106.2,124.062162,4.579231678,329517.5301,1.754573504,557.3100274
106.4,124.9391333,4.62511431,328656.6589,1.764614578,559.0772356
106.6,125.7186261,4.671464525,328720.9422,1.769853388,560.8674221
106.8,126.8652819,4.71825514,330945.0807,1.766360793,563.3196299
107,127.6904639,4.765538017,334202.4003,1.757192803,565.6000352
107.2,128.8511655,4.813272806,339353.0589,1.741476258,568.6682957
107.4,129.628773,4.861513608,344134.7565,1.727069436,571.479407
107.6,130.8343278,4.910209753,349223.339,1.713535741,574.966759
107.8,131.9157546,4.959403577,351191.6236,1.711352858,577.3927079
108,132.4891817,5.00912664,352373.7075,1.713972259,580.2574315
108.2,133.3281794,5.059330912,352382.672,1.719647636,582.3726081
108.4,134.6126088,5.110008939,353321.8766,1.721830442,584.7744839
108.6,135.9119673,5.161195038,355648.3756,1.719647555,587.8591641
108.8,136.8074104,5.212923279,359513.6947,1.710042994,590.5969633
109,138.0966563,5.265144158,364745.5272,1.696945869,594.1926525
109.2,138.9120394,5.317922374,370003.0256,1.684285325,597.9043215
109.4,139.9076387,5.371218629,371530.6068,1.685595003,600.6541599
109.6,140.685843,5.425065912,371829.4169,1.691706952,603.2661202
109.8,141.6400988,5.479441094,370374.1337,1.70480401,605.9743771
110,142.9398581,5.534338962,369341.4727,1.714845068,608.1705383
110.2,144.1196457,5.589796627,368487.1049,1.725759269,610.8700442
110.4,145.1661377,5.645820751,368676.6164,1.730998069,613.2150168
110.6,146.22672,5.702406724,369057.2933,1.73536373,615.4735453
110.8,147.547036,5.759543304,369428.1593,1.7423488,618.1686794
111,148.3485182,5.817289528,369940.9111,1.746714469,620.2543124
111.2,149.382254,5.875600049,370542.4005,1.752389839,622.8684698
111.4,150.5932849,5.934484264,372909.7017,1.749333813,625.3655447
111.6,151.9816104,5.993947966,377169.1198,1.74016581,628.7292605
111.8,153.2299741,6.054018634,380820.006,1.731870951,631.4944267
112,154.3641888,6.114700815,384317.6637,1.725322373,634.8220263
112.2,155.5299749,6.175990416,386729.092,1.721393211,637.3957019
112.4,156.7414873,6.237892658,386983.4087,1.726632006,639.9606207
112.6,157.9629197,6.300416061,388677.879,1.727505106,643.2181937
112.8,159.4365846,6.363550343,389348.0608,1.730561044,645.5839687
113,160.6761894,6.427334951,390377.2717,1.734490129,648.5165537
113.2,161.941533,6.491758654,391521.0435,1.736672935,650.8549682
113.4,163.1385206,6.556834317,393793.3681,1.73492662,653.4953908
113.6,164.6943222,6.622539215,393747.1376,1.743657957,656.4312666
113.8,165.5281034,6.688953967,393965.3975,1.748896762,658.6657188
114,166.8905661,6.755999592,396037.1144,1.748023579,661.5895532
114.2,168.0730891,6.823731225,397651.4223,1.74846011,664.4761816
114.4,169.5944383,6.892120003,399714.8094,1.746277215,667.1374041
114.6,171.0840653,6.961198083,402497.6332,1.741474904,669.9266513
114.8,172.7284921,7.030959578,407012.418,1.731870327,673.4950015
115,174.1530068,7.101437114,409772.5557,1.727504589,676.3542778
115.2,175.0270302,7.172660537,412502.5717,1.724885146,679.6873489
115.4,176.228218,7.244576913,414245.5418,1.724885107,682.4711208
115.6,177.819854,7.317189163,416677.698,1.724448487,686.0318099
115.8,178.912623,7.390565253,416974.327,1.729687283,688.4905894
116,180.4982595,7.464644516,417502.8684,1.735362632,691.4494486
116.2,181.7090982,7.539493997,418931.1674,1.736235732,694.0767435
116.4,183.2279453,7.615074226,421598.1267,1.734489406,697.4875232
116.6,184.3794872,7.691439074,423042.0173,1.735799077,700.3150628
116.8,185.7207934,7.768558122,425891.0128,1.733179619,703.7542878
117,187.0603441,7.846452154,427800.7416,1.732743007,706.5260281
117.2,188.1799733,7.925143868,429439.8823,1.734489247,709.7277991
117.4,189.702533,8.004598293,430182.7155,1.738418321,712.4240413
117.6,190.9993405,8.084866777,431130.1071,1.741474263,715.1005801
117.8,192.3227003,8.165940077,432924.2674,1.742783928,718.4380436
118,193.7075844,8.24782391,434701.7354,1.742347314,721.0872308
118.2,195.296382,8.330517488,436368.5304,1.74365697,724.2594691
118.4,196.8608859,8.414465299,437882.3203,1.744530058,727.0607598
118.6,198.6202394,8.498399351,440058.3523,1.744530001,730.573312
118.8,200.113817,8.58361973,440355.651,1.748895643,732.9434718
119,201.6639179,8.669692466,439454.1236,1.758500112,735.6758268
119.2,203.3729622,8.756619041,440029.2563,1.762865746,738.6226563
119.4,204.744665,8.84444222,440968.8274,1.764611978,741.0803544
119.6,206.108771,8.933148242,442613.2022,1.764611933,743.860852
119.8,207.6526345,9.022733156,445760.2982,1.760246192,747.1654946
120,209.0806492,9.113226076,450216.5638,1.751078197,750.2501931
120.2,210.7733538,9.204610135,455145.8852,1.741910194,753.9794069
120.4,212.6091744,9.296902653,459165.6416,1.7353616,757.2971898
120.6,214.0027283,9.390152649,463480.8689,1.727939883,760.7232908
120.8,215.7434053,9.484315511,467574.6794,1.722701,764.8026631
121,217.4156915,9.579429496,470165.4244,1.721827809,768.6391116
121.2,219.0720454,9.67549992,472642.0765,1.719644912,771.6811439
121.4,220.7474389,9.772534264,475624.6237,1.717025445,775.2123
121.6,222.2753327,9.8705537,477287.4236,1.720081378,779.2500893
121.8,224.4617703,9.969511795,480291.1949,1.717025326,782.4289152
122,225.8970056,10.06951285,485384.5276,1.710040179,786.8431187
122.2,227.8633806,10.17048157,488398.2871,1.707857272,790.1816991
122.4,229.6939091,10.27247421,490405.607,1.709166921,793.6307957
122.6,231.153771,10.37551708,496240.3192,1.700872067,798.4531543
122.8,232.611847,10.47959531,498282.723,1.701745159,801.9098993
123,234.6085522,10.58468202,497289.1039,1.712659315,805.566907
123.2,236.189622,10.69085302,495513.8574,1.724010052,808.300364
123.4,238.2152243,10.79806027,493743.0287,1.735360775,811.1771803
123.6,240.158265,10.90635031,488884.5765,1.757189149,813.9730188
123.8,241.8513719,11.01574559,487045.2406,1.768103312,816.1757735
124,243.5385221,11.12624047,487712.0053,1.772468941,819.3108209
124.2,245.09148,11.23785464,491249.6318,1.766356929,822.3003349
124.4,246.9907066,11.35056654,496572.4937,1.755442651,825.7910151
124.6,248.6749673,11.46442554,505593.7822,1.735797006,830.8420802
124.8,250.7879304,11.57939892,512221.0635,1.721826739,834.775941
125,252.5959945,11.6955485,521742.2104,1.701744525,840.1968647
125.182,254.3913405,11.80224817,527147.5791,1.693013096,844.1361857
125.4,256.0257234,11.80508506,532326.7937,1.688210791,849.3273145
125.6,256.9280205,11.80502365,535651.2798,1.686901055,853.3070971
125.8,257.7845197,11.80496537,537791.8028,1.691266713,857.9554603
126,258.6443495,11.80490687,536904.6676,1.701307764,861.0281158
126.2,259.4025912,11.80485533,535445.8685,1.714404799,864.9137901
126.4,259.8177645,11.80482728,535396.9957,1.721826451,868.2337315
126.6,260.6467848,11.80477089,536039.2578,1.728374955,872.292293
126.8,260.995343,11.8047474,536324.5424,1.733613767,875.3660337
127,261.3530607,11.80472328,536320.535,1.741035421,879.1729087
127.2,261.8107012,11.80469232,536821.2917,1.74540109,882.1437912
127.4,262.5348026,11.80464311,534891.5804,1.75675185,884.91881
127.6,262.5003233,11.80464585,532794.6392,1.769848909,888.1621395
127.8,263.0387347,11.80460935,532049.1784,1.777270557,890.6340451
128,263.3206777,11.80459042,531069.1704,1.786438486,893.6355635
128.2,263.7649951,11.80456038,529586.3049,1.795606412,895.8645445
128.4,263.9578402,11.80454755,528915.133,1.802591503,898.2554698
128.6,264.140693,11.8045354,527732.5698,1.811759436,901.0906553
128.8,264.317717,11.80452366,527024.525,1.81787139,903.1357976
129,264.508064,11.804511,528009.3989,1.820054226,905.876879
129.2,264.7208937,11.8044968,531541.3884,1.814815397,909.0644142
129.4,265.1202459,11.80446983,534476.5412,1.810449698,911.8656855
129.6,265.1673702,11.80446698,538470.3462,1.8034646,914.9919341
129.8,265.6033608,11.8044375,540566.2911,1.803028017,918.260447
130,265.7379175,11.80442866,540449.6035,1.807830267,920.6065073
130.2,265.8824666,11.80441914,538695.9921,1.818307907,923.0849708
130.4,266.2768227,11.80439252,537360.1509,1.827039264,925.0425798
130.6,266.1107784,11.80440426,534678.136,1.839699757,926.7123893
130.8,266.4651653,11.80438037,533245.7336,1.848867684,928.7509721
131,266.5097916,11.80437769,534195.5684,1.850613957,931.0860847
131.2,266.8208786,11.80435677,535196.391,1.851050515,933.0338462
131.4,267.0178872,11.80434365,536180.8118,1.851487077,935.0220905
131.6,267.1890823,11.8043323,538538.7074,1.84886766,937.7938105
131.8,267.2553585,11.80432814,539858.0689,1.84843109,939.9013218
132,267.4948342,11.80431212,540463.7982,1.850613924,942.2889646
132.2,267.5036548,11.80431189,540894.9412,1.852796767,944.1349511
132.4,267.7614497,11.80429462,541384.6676,1.8549796,946.117727
132.6,267.7586127,11.80429519,541281.1327,1.859781854,948.4090686
132.8,267.7241334,11.80429792,540909.7211,1.864147541,950.0077552
133,268.0602011,11.80427529,539975.3972,1.870696057,951.7158778
133.2,268.0382122,11.80427717,538942.1066,1.877244586,953.4152344
133.4,268.0736789,11.80427512,537353.2526,1.885102818,954.6550116
133.6,268.2082356,11.80426628,534572.9408,1.896890163,955.860869
133.8,268.3894231,11.80425425,533151.3683,1.903875253,956.7876992
134,268.3649361,11.8042563,532165.3385,1.910423781,957.9705734
134.2,268.732646,11.8042315,532283.5196,1.91304318,959.2672622
134.4,268.6057382,11.80424056,533758.8022,1.910860342,960.6350609
134.6,268.6903336,11.80423515,537008.1165,1.903438674,962.4274312
134.8,268.7058157,11.80423446,540365.1349,1.896017009,964.5633916
135,268.89533,11.80422186,542414.5803,1.891651318,966.3065255
135.188,269.0303901,11.80421297,543794.8925,1.890341608,968.1973866
136,268.8955048,11.64495635,1.7977E+308,1.764173317,0
136.2,268.841439,11.52698459,1.7977E+308,1.563351808,0
136.4,268.7207581,11.4090174,1.7977E+308,1.295735319,0
136.6,268.3268862,11.29165879,1.7977E+308,0.96219699,0
136.8,268.2037072,11.17369176,1.7977E+308,0.61468846,0
137,267.9706131,11.05573226,1.7977E+308,0.372392939,0
137.2,267.7275268,10.93777345,1.7977E+308,0.212608866,0
137.4,267.6234996,10.81980511,1.7977E+308,0.131407123,0
137.6,267.0215239,10.70187087,1.7977E+308,0.083821156,0
137.8,266.8841891,10.58390482,1.7977E+308,0.021828426,0
138,266.6827372,10.46594315,1.7977E+308,0.013097056,0
138.2,266.5345775,10.34797784,1.7977E+308,0.010914213,0
138.4,266.1157936,10.23003105,1.7977E+308,0.010477645,0
138.6,266.0217587,10.11206203,1.7977E+308,0.009167939,0
138.8,265.9002451,9.994094891,1.7977E+308,0.013970193,0
139,265.4464881,9.876150502,1.7977E+308,0.024884406,0
139.2,265.5231547,9.758169793,1.7977E+308,0.031432934,0
139.4,265.2967221,9.640209838,1.7977E+308,0.02968666,0
139.6,265.1394028,9.52224515,1.7977E+308,0.019209016,0
139.8,264.6090384,9.404306007,1.7977E+308,0.010914213,0
140,264.473369,9.286339837,1.7977E+308,0.010914214,0
140.2,264.2919017,9.168376803,1.7977E+308,0.020518722,0
140.4,264.1145978,9.050413484,1.7977E+308,0.02706725,0
140.6,263.8640172,8.932455183,1.7977E+308,0.02706725,0
140.8,263.6783864,8.814492434,1.7977E+308,0.027940387,0
141,263.459448,8.696531966,1.7977E+308,0.025757544,0
141.2,263.2704865,8.578569445,1.7977E+308,0.024447839,0
141.4,262.6934914,8.460633495,1.7977E+308,0.021391859,0
141.6,262.5836354,8.342665557,1.7977E+308,0.021828428,0
141.8,262.2639415,8.224711988,1.7977E+308,0.023138134,0
142,262.2090431,8.106740288,1.7977E+308,0.027940388,0
142.2,262.1000198,7.988772293,1.7977E+308,0.029686662,0
142.4,261.9993234,7.870803729,1.7977E+308,0.032742642,0
142.6,261.5663837,7.752857914,1.7977E+308,0.034052348,0
142.8,261.2500205,7.634904117,1.7977E+308,0.031869506,0
143,260.8212443,7.516958018,1.7977E+308,0.026194114,0
143.2,260.9087358,7.398976567,1.7977E+308,0.020518723,0
143.4,260.5232594,7.281027502,1.7977E+308,0.0152799,0
143.6,260.4875128,7.16305449,1.7977E+308,0.010914214,0
143.8,260.2044573,7.045098413,1.7977E+308,0.00611196,0
144,259.990515,6.927137602,1.7977E+308,0.008731372,0
144.2,259.6999653,6.809182038,1.7977E+308,0.011350783,0
144.4,259.6025996,6.691213245,1.7977E+308,0.015716469,0
144.6,259.1305235,6.57327011,1.7977E+308,0.02488441,0
144.8,259.0289944,6.455301603,1.7977E+308,0.029250095,0
145,258.6851524,6.337349687,1.7977E+308,0.031869507,0
145.2,258.3204933,6.219399197,1.7977E+308,0.032306076,0
145.4,258.1265356,6.101437019,1.7977E+308,0.026194116,0
145.6,257.9517297,5.983473529,1.7977E+308,0.017462744,0
145.8,257.8318815,5.865506275,1.7977E+308,0.010477646,0
146,257.492203,5.747554075,1.7977E+308,0.010914215,0
146.2,257.2491166,5.62959526,1.7977E+308,0.015279901,0
146.4,257.1092837,5.511629376,1.7977E+308,0.011787352,0
146.6,256.5464443,5.393692456,1.7977E+308,0.006548529,0
146.8,256.437421,5.275724461,1.7977E+308,0.007858235,0
147,256.2559536,5.157761428,1.7977E+308,0.011787353,0
147.2,256.0686574,5.039798793,1.7977E+308,0.008294804,0
147.4,256.0712146,4.921823158,1.7977E+308,0.002619412,0
147.6,255.4717368,4.803888747,1.7977E+308,0.001746274,0
147.8,255.6033609,4.685904274,1.7977E+308,0.00305598,0
148,255.1462731,4.567960113,1.7977E+308,0.005238823,0
148.2,254.700843,4.450015154,1.7977E+308,0.013533627,0
148.4,254.3878106,4.332061129,1.7977E+308,0.023138137,0
148.6,254.3537294,4.214088003,1.7977E+308,0.025757549,0
148.8,253.9424395,4.096140706,1.7977E+308,0.022265,0
149,253.6152513,3.97818765,1.7977E+308,0.018772451,0
149.2,253.3971456,3.860227125,1.7977E+308,0.00960451,0
149.4,253.0782844,3.742273499,1.7977E+308,0.009167941,0
149.6,252.8551825,3.624313316,1.7977E+308,0.010477647,0
149.8,252.2623662,3.506378449,1.7977E+308,0.013533628,0
150,252.1525101,3.388410512,1.7977E+308,0.017026177,0
150.2,251.9077583,3.270451811,1.7977E+308,0.014406765,0
150.4,251.352413,3.152514378,1.7977E+308,0.012223922,0
150.6,251.4282469,3.034533726,1.7977E+308,0.007421667,0
150.8,250.896217,2.916594697,1.7977E+308,0.003055981,0
151,250.7813648,2.798627101,1.7977E+308,0.010477648,0
151.2,250.2118638,2.680690638,1.7977E+308,0.015716472,0
151.4,250.1153308,2.562721788,1.7977E+308,0.018772453,0
151.6,249.6707333,2.444776772,1.7977E+308,0.017899315,0
151.8,249.5067524,2.32681254,1.7977E+308,0.015716472,0
152,249.2961409,2.208851502,1.7977E+308,0.013970198,0
152.2,248.9314816,2.090901012,1.7977E+308,0.020518728,0
152.4,248.2837077,1.972969908,1.7977E+308,0.028813533,0
152.6,247.90406,1.855020445,1.7977E+308,0.037981476,0
152.8,247.7009427,1.737058893,1.7977E+308,0.037544907,0
153,247.356268,1.619107035,1.7977E+308,0.034488926,0
153.2,247.1273372,1.501147251,1.7977E+308,0.02663069,0
153.4,246.5803188,1.383209248,1.7977E+308,0.012660492,0
153.6,246.4112732,1.265835243,1.7977E+308,0.005238824,0
153.734,246.0412442,1.185637264,1.7977E+308,0.01353363,0
229,245.3243926,1.035408627,1.7977E+308,0.007421668,0
229.2,244.6100033,0.917482084,1.7977E+308,0.008294806,0
229.4,244.2961381,0.799528116,1.7977E+308,0.020955299,0
229.6,244.1388188,0.681563429,1.7977E+308,0.02750383,0
229.8,243.6659097,0.563620351,1.7977E+308,0.024884418,0
230,242.702546,0.445710857,1.7977E+308,0.020082162,0
230.2,242.6901148,0.327736249,1.7977E+308,0.015279906,0
230.4,241.7034357,0.209828351,1.7977E+308,0.019645594,0
230.6,241.0706501,0.091896221,1.7977E+308,0.025757557,0
230.746,239.7565329,0.005864119,1.7977E+308,0.025757557,0