File: GB3_Loc1_10um_250nm_1.csv
Displacement Into Surface,Load On Sample,Harmonic Contact Stiffness,Harmonic Displacement,Harmonic Load
nm,mN,N/m,nm,uN
0,0,290.9871696,0.375012089,2.205994437
0.504159726,0.000655383,4961.937534,0.237493102,2.297910909
0.311358462,0.001358449,11466.376,0.183358646,2.377790654
0.277600865,0.002050635,15584.11358,0.154545144,2.439068271
0.407050381,0.002731654,18967.9259,0.137082416,2.515665317
0.51901342,0.00341387,20513.25655,0.130970461,2.596639325
0.512734571,0.004104175,22908.01311,0.127477915,2.842844064
0.546424811,0.004791746,25241.03241,0.124858506,3.075917891
0.849074037,0.005458114,26593.07661,0.127477914,3.307897505
0.960205007,0.006135051,28514.88892,0.126604778,3.540971336
0.93977106,0.006820988,29618.67279,0.12835105,3.743406355
1.045905894,0.007498266,32800.24474,0.132716732,4.271925877
0.94470108,0.008189729,35582.94303,0.136645846,4.761052622
1.072485837,0.008865526,38353.53575,0.139265255,5.251273644
0.676508995,0.009577157,39518.86159,0.146686916,5.734929109
0.915041435,0.010245377,40298.63959,0.156291415,6.248129253
1.083627571,0.010921803,41879.40473,0.171134734,7.164010939
1.272199048,0.01159002,42632.53362,0.185978052,7.966091342
1.1268617,0.012284502,43187.00447,0.199075098,8.600752416
1.141400705,0.012968045,42548.80921,0.223522917,9.432377345
1.330804473,0.013639625,41894.46476,0.250153576,10.35263605
1.076384821,0.01434157,42230.56679,0.269362578,11.21489965
1.518093459,0.014995887,42231.89023,0.295993236,12.29272949
1.316132838,0.015697663,41470.24691,0.326989579,13.3125642
1.251566755,0.016383199,41121.67876,0.354929944,14.32145651
0.944687673,0.017088733,40445.11302,0.381560606,15.1355734
0.910930697,0.017775582,39775.19157,0.419105472,16.35784307
1.057867309,0.018450069,38199.64727,0.4653817,17.45536919
0.763478566,0.01915475,36346.68032,0.518643023,18.5222562
1.053637746,0.019819437,34385.4617,0.577143159,19.49941567
0.598539959,0.020535115,32564.56014,0.634770167,20.30258994
0.546463816,0.021223218,30333.80773,0.71422558,21.26661828
0.552675928,0.021907334,28416.59445,0.792371289,22.10371438
0.538903496,0.022592818,26656.23486,0.873572975,22.86093072
0.384406562,0.023287929,25232.44568,0.946479867,23.46276437
0.47305492,0.023966405,23786.75962,1.026371847,24.02520549
0.793190918,0.024629043,22386.59977,1.117178027,24.66314962
0.657845841,0.025322843,21741.33937,1.170875919,25.14571077
1.016285547,0.025982861,21220.30908,1.223264095,25.73003701
1.190700907,0.026655467,20905.49018,1.260372388,26.19180784
0.725610849,0.027371828,20895.82803,1.281327673,26.69953626
1.05240836,0.028034009,20900.20461,1.303592643,27.30903012
1.135227892,0.028712882,20774.17386,1.326294188,27.73031383
1.037353836,0.029404118,20520.7406,1.359473374,28.23147712
1.044398638,0.030088176,20289.22975,1.386104034,28.586012
1.321234787,0.030753774,20003.02048,1.417536937,28.95258378
1.277485539,0.031441306,19785.21447,1.447660144,29.37277316
1.013073613,0.032143936,19754.11023,1.463376606,29.70979985
1.168337119,0.032817852,19825.1079,1.476037079,30.12889519
1.130416696,0.033504986,19981.06493,1.480402762,30.48452422
0.918464199,0.034204026,20045.54374,1.490880406,30.8357761
1.216117582,0.0348682,20055.31212,1.509216262,31.21766731
1.472136498,0.035535223,19807.68039,1.542395437,31.51858449
1.525811902,0.036216089,19735.13095,1.56291414,31.7626008
1.293042174,0.036916551,19997.7904,1.567716398,32.10619294
1.753069977,0.037569614,20628.02564,1.546324543,32.46619949
2.057384871,0.03823333,21768.24272,1.496992329,32.92359354
1.796303707,0.038935729,24201.16277,1.39221597,33.66549022
1.8274965,0.039618131,26609.78041,1.300973217,34.33297868
1.553092305,0.040321442,29825.96157,1.198379697,35.23463484
1.742496072,0.040993021,31882.33896,1.146428078,35.93932776
1.721229437,0.041679013,32787.71581,1.138569852,36.69982684
1.071282347,0.042408019,32263.4386,1.169129639,37.15065426
1.189491176,0.043084469,30354.63783,1.252077596,37.5522417
2.121237489,0.043705258,28347.32787,1.344193462,37.75030091
2.232368458,0.04438219,26759.77717,1.428451121,37.94507638
2.184455764,0.045070003,26009.15504,1.482149009,38.2864802
2.228138896,0.045751549,25941.03919,1.496992327,38.59177416
2.18896944,0.046438764,26990.81314,1.460757168,39.15421515
2.311758059,0.047114899,28807.93552,1.392652528,39.74838949
2.27133957,0.047802199,30901.02071,1.323238186,40.43338573
2.298368915,0.048484885,33088.32687,1.263428344,41.27485886
2.155945983,0.049179165,34464.60591,1.23374171,41.90295435
2.309544107,0.049853191,35115.64586,1.231558866,42.56934874
2.339487865,0.050535677,34866.22182,1.25687982,43.15476898
2.234119608,0.051227421,34434.14376,1.286129892,43.60450278
2.183708846,0.051915405,34057.26479,1.314506825,44.06517914
2.274022581,0.052593762,33599.21613,1.347249438,44.55649459
2.283565451,0.053277644,33314.71428,1.373880097,45.05328108
2.26979302,0.053963121,33129.96678,1.396145075,45.52927686
2.134031601,0.054656945,33045.7961,1.411861534,45.93414669
2.325100746,0.055328408,32983.11054,1.426704848,46.36090186
2.359207951,0.056010609,33161.39696,1.433689938,46.87738482
2.528627172,0.056683553,33430.65043,1.436309343,47.40809311
2.535255629,0.057367633,33571.72419,1.441111593,47.83922494
2.385754838,0.058062396,33738.39768,1.445040711,48.28239326
2.495220427,0.058739441,33936.10963,1.451589231,48.85249426
2.372782039,0.059432352,33958.54995,1.461193734,49.26721226
2.373581671,0.060116832,33852.31023,1.478656462,49.73883111
2.490541464,0.060793364,33868.56391,1.490007232,50.11196831
2.677447161,0.06146511,33880.13218,1.502231136,50.50589621
2.657013216,0.062151043,33808.92083,1.519693864,50.97423233
2.543318065,0.062843355,33707.56388,1.534973754,51.32001302
2.440447876,0.063534927,33642.47962,1.55112678,51.73582535
2.604038272,0.064208269,33521.95001,1.565533526,52.05862738
2.706842347,0.064885769,33330.70467,1.582996251,52.37814661
2.575660721,0.065579278,33064.15412,1.607007505,52.74800057
2.929936971,0.066239572,32939.39418,1.62272395,53.02375054
3.067713997,0.066914679,32934.53376,1.635384423,53.36843738
3.174681517,0.067591892,33130.32772,1.637567261,53.67373148
2.94857331,0.068291894,33685.39132,1.625343359,54.04467957
2.9955872,0.06897321,34750.90678,1.596093289,54.58523593
3.239115769,0.06964108,36180.02487,1.5533096,55.17612781
3.165389708,0.070330656,37501.27874,1.515764738,55.71011833
3.292341772,0.071006502,39119.2639,1.473417621,56.3951149
3.158662079,0.07170018,40198.84696,1.449406374,56.96959255
3.363886939,0.072370671,41211.41547,1.431070505,57.67428552
3.276837823,0.073061378,41412.07083,1.434999621,58.14371585
3.369649007,0.073744875,41185.26575,1.454645187,58.68536636
3.335057927,0.07444395,40381.35666,1.491316916,59.10227313
3.162240031,0.075155835,39625.95438,1.525805808,59.42835725
3.459056855,0.075853257,38803.13179,1.567279777,59.81353155
3.587670424,0.076562292,38501.32005,1.587361909,60.11226022
3.552243789,0.077286069,38478.13379,1.600458956,60.52807259
3.70750174,0.078007688,38899.66112,1.594783565,60.90011576
3.766999567,0.078743192,39912.562,1.572518586,61.51836338
3.785694768,0.079488798,40808.20214,1.551563313,62.01843249
3.845190878,0.080239064,41916.40757,1.527115494,62.65418802
3.805596074,0.08100373,42850.56731,1.508779631,63.27790671
3.528683916,0.081792371,43462.42357,1.498738571,63.77578677
3.87961861,0.082545699,43985.73012,1.492626607,64.30540131
4.074839509,0.08331736,44257.86588,1.49786542,64.93678023
4.169304082,0.084103821,44213.45757,1.512272167,65.48827914
3.870738375,0.084925146,44134.83305,1.524932653,65.89533698
4.039310434,0.085722551,43915.29722,1.544578216,66.37461592
4.086308915,0.086536345,43738.8275,1.560731238,66.78386313
3.958441678,0.087370395,43712.43823,1.571645446,67.21827734
4.127010891,0.088192266,43945.94494,1.574701419,67.74023183
4.164846907,0.089031478,44241.71268,1.575574554,68.27093996
4.459150257,0.089861492,44623.95954,1.572082,68.72286323
4.24467945,0.090734846,44862.40515,1.573828279,69.16603125
4.321648897,0.091596879,45028.5394,1.580813367,69.70768195
4.214592995,0.092480211,44994.99919,1.593473849,70.185866
4.61547655,0.093337543,44933.84894,1.604388041,70.54806148
4.988047657,0.094205493,44640.36028,1.624470166,70.96715767
4.804381288,0.095120315,44671.14509,1.631455262,71.33810579
4.80057475,0.09603192,44975.39656,1.631455263,71.86224827
4.724323171,0.096957706,45309.44927,1.628399287,72.27806067
5.150182168,0.097858323,45797.93578,1.62228732,72.81642948
4.93237127,0.098812183,46454.51342,1.611373123,73.37777565
5.003502453,0.099755765,46986.22508,1.603514893,73.85267761
4.977207887,0.100715492,47633.21409,1.595220099,74.47749053
5.156586458,0.101670755,48184.52776,1.586925299,74.95895809
5.151106899,0.102648188,49087.14759,1.570772276,75.61112715
5.134801225,0.103636277,50125.99068,1.551563278,76.30378318
5.328332094,0.104619983,50831.37129,1.540649069,76.87607299
5.207937949,0.105635055,51470.96315,1.532790845,77.48009504
5.363995472,0.106641334,51992.97239,1.530171432,78.15743213
5.238602817,0.107677168,52187.91967,1.536719958,78.78662176
5.338035077,0.108707882,52072.82537,1.549380432,79.23635607
5.467442945,0.109746906,51910.0986,1.564223747,79.70250411
5.487350962,0.110803837,51747.56005,1.581686472,80.28573591
5.279933555,0.111887038,51612.25391,1.596966365,80.81206642
5.68745593,0.112938983,51495.9389,1.609190262,81.2245972
5.542071381,0.114039396,51408.64747,1.621850744,81.71262948
5.854664677,0.115119325,51449.33159,1.628835824,82.13829096
5.541907039,0.116253054,51444.69653,1.639313471,82.69088308
6.06641716,0.117340815,51544.13723,1.643679136,83.09794298
5.806532691,0.118493292,52107.98888,1.636694054,83.68117402
5.900956187,0.119632921,52999.47758,1.620977597,84.33990884
6.027020525,0.120781993,53939.88806,1.603078299,84.92861218
5.911187287,0.121959143,55116.28846,1.580813326,85.59719461
6.172560928,0.123122212,56693.637,1.551563252,86.43429155
6.027997175,0.124324841,57630.5906,1.539339347,87.19369617
5.821396665,0.125543793,58243.39551,1.533663967,87.7977179
5.961609831,0.126751139,58707.91363,1.535846804,88.60417582
5.966925908,0.12797997,58710.69829,1.545014736,89.14254352
5.957668497,0.12922205,58245.56884,1.567279712,89.73781191
6.211123108,0.130458594,58070.66079,1.581686455,90.32870414
6.154815831,0.131729019,57880.86076,1.594346933,90.78500353
6.250056543,0.133001628,57737.82664,1.607880544,91.37042396
6.187084791,0.13429797,57875.22876,1.613119364,91.90441463
6.549199414,0.13557812,58393.267,1.610063376,92.56096181
6.258067788,0.136915974,58886.1004,1.608317112,93.19890485
6.379532149,0.138238925,59406.75899,1.607007404,93.88390155
6.232036314,0.139593679,59767.08175,1.607443977,94.43649408
6.501716232,0.140933429,60034.33793,1.610499946,95.00221868
6.523669519,0.142303642,60174.00358,1.618358172,95.62484349
6.778774193,0.143671727,60129.97473,1.629708937,96.22339544
7.05219646,0.145052069,60052.10574,1.63887686,96.65562251
6.938416577,0.146472997,59955.34999,1.648917931,97.12614687
7.308427518,0.147874924,59768.34487,1.662888101,97.6973431
7.303726627,0.149316784,59767.78798,1.67030976,98.22914535
7.24573195,0.150776686,60042.40881,1.671619467,98.79486915
7.374257963,0.152238474,60589.57189,1.664634372,99.29165599
7.379544269,0.153723284,61789.80848,1.644988805,100.0434015
7.735391,0.155199168,63116.25116,1.622287251,100.7634147
7.736510384,0.156714145,64709.31274,1.596966298,101.6409983
7.829223822,0.158238023,66387.37265,1.570772206,102.5689168
8.304139854,0.159750981,67425.07818,1.55723858,103.2867424
8.314413501,0.16131107,68448.92051,1.545014672,104.0724093
8.496219311,0.162875073,69609.74434,1.533663895,105.0802081
8.617236965,0.164459064,70623.66472,1.524932529,106.0300119
8.446811536,0.166078891,71171.59014,1.524059397,106.7686256
8.515366031,0.167698602,71901.53845,1.522313123,107.6845078
8.474003652,0.169342116,72153.15112,1.52798851,108.4220278
8.489262233,0.170998172,71899.67605,1.545887804,109.2831975
8.679383613,0.172658953,71515.25253,1.562913956,109.8839379
8.769579356,0.174351748,71172.52678,1.580813248,110.6094216
8.811480118,0.176039299,70843.50151,1.596093132,111.1663917
8.71514848,0.177787766,70818.84555,1.605697634,111.7977699
8.851969805,0.179520496,71337.71512,1.606570766,112.6764481
8.945490288,0.181264794,71936.85259,1.603078218,113.3625392
8.779208658,0.183053268,72645.89859,1.599585678,114.228085
8.964319811,0.184835551,73062.27463,1.601768514,115.0356376
8.758897602,0.186662684,73286.87914,1.60657077,115.7217275
8.894043178,0.18848469,73388.58016,1.613992424,116.3804625
8.90345055,0.190333605,73289.83498,1.627089468,117.1092287
9.433286542,0.192165417,73221.56479,1.63713052,117.6694836
9.258665277,0.194064039,73412.39541,1.643679047,118.3982491
9.395467582,0.195960291,73814.62788,1.644115611,119.0657382
9.410695038,0.197883966,74085.26064,1.647171588,119.7255671
9.282697686,0.19983686,74505.42527,1.648044728,120.504668
9.227974711,0.201804313,74964.54305,1.646298458,121.1634023
9.493834806,0.203769477,75403.03804,1.646735018,121.9698612
9.401636231,0.205778913,75580.74015,1.650664134,122.5793542
10.38360443,0.207734853,76085.69242,1.64891783,123.2851455
10.73022846,0.209753892,76688.51315,1.647171548,124.1222434
10.84869327,0.211809018,77319.19695,1.644552136,124.9516804
11.29606793,0.213862158,77984.36894,1.639313305,125.6432444
10.88660296,0.215994808,79090.36536,1.626652841,126.4683024
11.45054921,0.218082043,80647.92677,1.608316964,127.5745849
11.35500315,0.220235571,82194.12243,1.588671402,128.5035974
11.42432705,0.222399351,84323.75405,1.56291388,129.7083601
11.47033313,0.224586408,85777.41757,1.547633994,130.6406557
11.58045372,0.226791089,86804.04103,1.540648901,131.5992137
11.79215981,0.229010993,87564.04655,1.541522032,132.7897517
11.63831274,0.231278199,87757.70973,1.548070558,133.5940201
12.12230296,0.233524483,87454.00065,1.564660133,134.5394488
12.02923692,0.235833056,87332.74139,1.577757179,135.4520476
11.78545145,0.238175008,87406.51135,1.586051981,136.2399018
12.06375938,0.240504693,87667.78766,1.59129079,137.074811
11.91905846,0.242886795,87954.54426,1.597402748,138.0541584
12.06079986,0.245273134,88112.11469,1.60526097,139.0006798
12.1767251,0.247685215,88019.07453,1.614865465,139.7283524
12.05366571,0.250138044,87961.56404,1.6240334,140.4877569
12.38691713,0.252584197,87708.3799,1.636693865,141.2143363
12.08648921,0.255098425,87608.47604,1.647608077,142.0536197
12.29608052,0.257602687,88229.3824,1.646734936,142.9881049
12.23171413,0.260151118,88967.54819,1.642369256,143.7693945
12.39841603,0.262709167,89832.0605,1.636693866,144.6163397
12.43812985,0.265301583,90806.52922,1.631891616,145.7149607
12.6073238,0.267911158,91237.01402,1.633637884,146.4896861
12.8960056,0.270538855,90917.18277,1.648917759,147.3180299
13.31416751,0.273183881,90298.91779,1.66638047,147.8914156
13.13195741,0.275896769,89558.36519,1.686026042,148.4626101
13.3461042,0.27860973,89307.86559,1.699123078,149.2471837
13.64310039,0.28134427,89586.92216,1.700432773,149.8938833
13.62658589,0.284127882,90510.19439,1.693011116,150.8207077
13.42895825,0.286951844,91590.61518,1.682096919,151.6118453
13.67515065,0.28977366,92539.60588,1.674675254,152.4730159
13.63780908,0.292643378,93222.50272,1.672928983,153.4315733
13.78740287,0.295529128,93394.05304,1.679040932,154.2883668
13.7363152,0.298457628,93410.14554,1.685589455,154.937253
13.81304191,0.301406691,93330.02697,1.695193951,155.7338629
13.95596395,0.304380862,94104.98503,1.690391698,156.5917507
13.75914534,0.307408212,94853.33883,1.685589455,157.3544376
14.23430336,0.310419885,95670.01708,1.680350623,158.1565208
13.98085482,0.313511861,96617.11461,1.675111814,159.1599409
14.65252036,0.316571302,97515.67712,1.66899984,159.9970408
15.02358152,0.31968214,97645.94149,1.675111782,160.756448
15.45001286,0.322820529,97642.8359,1.685152835,161.6876519
15.16740572,0.3260391,97880.82685,1.68820882,162.3726471
15.30988263,0.329260791,98143.98048,1.692574497,163.2425717
15.3832426,0.332519414,98394.57684,1.695193903,163.9560188
15.57733869,0.335802507,99255.82319,1.688645376,164.8084357
15.63403724,0.339127977,100500.3177,1.678604308,165.9125282
16.04462478,0.34246268,101394.6992,1.672492342,166.7791715
16.05468493,0.345858401,102867.8271,1.660268436,167.9171849
16.41780135,0.349263771,104007.1361,1.651973631,168.8549541
16.94745158,0.352692187,104852.0337,1.64848107,169.8069491
17.15151636,0.356177284,105678.366,1.647607928,170.9865454
17.2456621,0.359704938,106268.5015,1.647171357,171.8641294
17.28984237,0.363271498,107151.1047,1.644551948,173.018557
17.65127303,0.366852052,107541.6202,1.646734777,173.8972369
17.80119648,0.370483079,108131.4384,1.646298205,174.8273451
17.88949669,0.374154777,109114.8149,1.642369089,176.0616526
17.9011852,0.377868668,109716.5082,1.643242225,177.1996665
17.94784232,0.381617526,109791.9781,1.649790745,178.054271
18.04778715,0.38540038,109839.9682,1.656775831,178.8858969
18.34840565,0.389207489,109792.7273,1.667253456,179.9035456
18.55992195,0.393058951,109558.8386,1.678604219,180.7089105
18.28514332,0.396982454,109642.3066,1.686899021,181.6849743
18.51996586,0.400910247,109790.7778,1.692137831,182.4410982
18.72064354,0.404880016,110330.3685,1.693447529,183.4423326
18.70731548,0.408904321,111121.223,1.689954985,184.359309
19.14696558,0.412938013,112064.0047,1.684716155,185.3113039
19.38843336,0.417005273,113396.8753,1.675984786,186.4919944
19.20022398,0.421184373,114582.3721,1.667689999,187.4976035
19.43335037,0.425376855,116188.4483,1.656339222,188.7734934
19.41000604,0.429608188,117283.5123,1.65022727,189.8086479
19.06607397,0.433882418,118412.5023,1.644551896,190.9324343
19.41160101,0.438173664,119425.4811,1.641932477,192.2334926
19.26999989,0.442541554,120184.4195,1.640186209,193.2467613
19.57471502,0.446922699,120455.5991,1.646298153,194.4449603
19.62878562,0.451365032,120332.218,1.655466081,195.3827279
19.65620498,0.455853847,119901.6668,1.668126554,196.2767254
20.09330213,0.460359546,118958.9124,1.688208671,197.1838563
20.12237636,0.464938552,117594.3322,1.713966186,197.9629583
19.99156893,0.469574569,116654.4619,1.732302048,198.5253988
20.05643802,0.474243752,115912.0393,1.748455064,199.130516
20.25786267,0.478950465,115586.3529,1.759369259,199.7717448
20.42347618,0.483706891,115725.9682,1.764608071,200.5738266
20.51081135,0.488516594,116360.4863,1.762861796,201.4371856
21.46080682,0.493315151,117526.7226,1.753257268,202.2819482
22.45326382,0.498158867,118714.1522,1.743652739,203.1562564
23.09265499,0.503075502,120605.2106,1.727063133,204.4157357
23.1308389,0.508082893,122087.3275,1.714402659,205.4257231
23.43048132,0.513122676,124208.8572,1.696066792,206.7803993
23.2171814,0.518248259,125709.2725,1.684279462,207.8724535
23.41022775,0.523397451,127468.8497,1.67030928,209.0575212
23.47420126,0.528607322,129482.3114,1.656775668,210.5697665
23.70220843,0.533858283,131152.2674,1.645861462,211.7953219
23.73869098,0.539175185,132962.5497,1.635820395,213.3239807
23.83928438,0.544541097,134341.6966,1.628835304,214.559383
23.83745076,0.549967858,135557.9243,1.624469624,215.8429315
24.0646003,0.55543335,136995.4995,1.620103937,217.5215034
24.26842814,0.56095545,137591.2912,1.621850203,218.6803094
24.10586636,0.566558191,137934.0266,1.628398728,220.0678097
24.75600254,0.572161277,137822.2926,1.637566638,221.092027
24.44437632,0.577886854,137454.1183,1.649353985,222.1107659
24.8330349,0.58362183,136231.9109,1.672055509,223.2082957
25.01851065,0.589428352,134878.1782,1.695630177,224.1953053
25.1132165,0.595299473,134053.5086,1.710910053,224.9120359
25.67172329,0.601197709,133732.7933,1.722260804,225.928593
26.35054672,0.607147046,133845.5114,1.727499599,226.7941453
26.37695133,0.613201262,134678.6267,1.724880191,227.8117926
26.23889279,0.619327537,136350.5927,1.714402563,229.1259787
26.44347863,0.625491716,137762.9367,1.705671197,230.2410151
26.7933615,0.631707889,138977.1094,1.700868937,231.5738073
26.76894338,0.638012352,140107.4019,1.695630122,232.7348002
27.01139472,0.644361792,140914.5431,1.693883843,233.8509312
27.04899715,0.650789049,142077.2981,1.689518162,235.2274908
27.19817239,0.657273299,142859.6608,1.687335317,236.3107937
27.45975306,0.663814996,144216.7816,1.681223357,237.7738002
27.59392466,0.670431262,145037.6232,1.679477081,238.9424543
28.33262076,0.677072214,145608.3141,1.680350194,240.1340923
28.71908164,0.683804265,145635.4463,1.687771838,241.4001362
28.71541988,0.690630653,146047.0558,1.690391246,242.4385738
28.78461042,0.697520634,146541.6971,1.693883788,243.7571388
29.06404687,0.704465446,147174.8503,1.694320347,244.841537
30.13702778,0.71142552,147938.7598,1.696503153,246.2640637
30.4260239,0.718509317,148461.5808,1.698685984,247.3057869
30.79619892,0.725658755,148744.8244,1.704361356,248.5827728
30.78416135,0.732906339,148725.3063,1.711346444,249.5150689
31.07979389,0.740205413,148431.2566,1.721387498,250.426577
31.68684355,0.747556542,148891.5711,1.725316591,251.711225
31.9304159,0.755006443,149483.5905,1.725753151,252.7310628
32.00494369,0.762542926,150555.5687,1.723133741,254.0354028
32.22226882,0.770145243,151444.6874,1.720950894,255.1077641
32.17437365,0.777842179,153267.9127,1.709600129,256.3814643
32.59402433,0.785584195,155050.1972,1.700868757,257.990007
32.53944965,0.793436326,156536.7295,1.693010535,259.2407279
32.83792589,0.801343167,157666.3458,1.690391118,260.7223374
32.96652435,0.809341076,158565.4649,1.688208275,261.9435157
32.85696445,0.817435688,159023.5748,1.690391118,263.1263927
33.21370087,0.825579582,160002.553,1.689954539,264.6845998
33.2606675,0.833826576,160643.3407,1.690827674,265.8806093
33.59073871,0.842137127,162132.9312,1.685588848,267.4913398
33.45366174,0.850563209,163567.2987,1.681223173,269.0758047
33.55472396,0.859057415,164414.1113,1.680786602,270.3670144
34.13457236,0.867604226,164690.2723,1.685588831,271.6330604
34.43212922,0.876256375,163852.7129,1.701741836,272.903481
34.9003772,0.884983634,162745.0783,1.718331403,273.7569957
35.66255416,0.893778358,160976.7376,1.742342615,274.71009
36.40223823,0.90266293,159584.4056,1.761988147,275.5198379
37.09028519,0.911640434,158853.2096,1.774212027,276.2081243
37.24123736,0.920744941,158958.518,1.779450837,277.2575065
37.35720058,0.929989589,159682.0592,1.777267994,278.2029342
37.35742007,0.939242079,161754.7382,1.76329782,279.5937194
37.65572592,0.948613646,163182.1033,1.755439588,280.7448677
37.71920256,0.958095647,164869.1119,1.745398524,282.015286
38.03080939,0.967655907,166901.5326,1.733611181,283.550514
38.12090981,0.977327465,168453.2424,1.725752955,284.8165559
38.1235666,0.987102211,169721.0284,1.72269698,286.3091053
38.33022651,0.996911432,170672.82,1.720950702,287.5291904
38.48940593,1.006872064,170818.773,1.727062648,288.6639237
38.77097309,1.01697495,170945.5873,1.734484293,289.9343445
38.9492749,1.027187453,170545.5364,1.744525349,290.8655481
39.08261154,1.037402915,170168.1069,1.755439543,291.9707364
39.43076393,1.047757977,170825.3836,1.755439532,293.0387229
39.67814887,1.058224019,172520.6176,1.746271598,294.3441589
39.66072655,1.068813385,174206.0418,1.738413376,295.8531226
40.31527171,1.079463003,175735.6591,1.730991701,297.1399609
40.88736824,1.090225177,177462.9483,1.723570029,298.7550718
41.29624518,1.101106768,178064.1106,1.724879719,299.997044
41.63599623,1.112102482,178370.3284,1.728808819,301.198528
41.84250422,1.12321785,179160.2871,1.729245381,302.6254245
42.27715595,1.134429161,180278.3156,1.727062527,304.10266
42.67765434,1.145755458,181429.0509,1.723569972,305.384025
43.43453027,1.157171101,182277.0334,1.722696812,306.6621104
43.61267419,1.168741101,182196.5889,1.731428163,308.1196461
44.45362481,1.180381843,181822.11,1.740596062,309.1077577
44.20623771,1.192213902,181250.9421,1.75281997,310.2764093
44.89727699,1.204100237,180900.8869,1.761551305,311.2130896
45.31684584,1.216124769,181402.7413,1.763297562,312.3117161
45.72640838,1.228270727,183794.8751,1.750637081,314.0110832
45.98607275,1.240548986,186492.4403,1.734047495,315.5211432
46.64124992,1.252923369,190486.6256,1.709163107,317.6133477
47.01579653,1.265441401,193464.0249,1.691700381,319.2963
47.31538652,1.278090417,196535.9844,1.675110795,321.1652734
47.51836983,1.290873245,198908.8199,1.665942863,323.2990528
48.24010327,1.303748719,199857.0536,1.666379409,324.8693023
48.51216977,1.316784461,199858,1.675547325,326.5894584
48.96574716,1.329938681,200013.6167,1.682095829,327.9780603
49.05875498,1.343249942,200051.2896,1.689080911,329.3677525
49.44069022,1.35667503,200339.3377,1.696065984,331.177638
49.87673455,1.370231136,201257.7697,1.695629402,332.6658162
50.39603188,1.383917811,203322.5013,1.688207732,334.6529711
50.76542928,1.397752211,205073.6268,1.681659204,336.2779292
51.08318379,1.411729334,207015.2358,1.674674109,338.0746833
51.54664248,1.425836801,209160.72,1.668998714,340.3430587
52.26363833,1.440068908,209775.9822,1.672054667,341.8848584
51.97098254,1.454513889,209472.1825,1.683405439,343.6225162
52.55429831,1.469043695,207773.8272,1.703924107,345.0264395
52.80243991,1.483742627,206209.9054,1.722259946,346.1535149
52.94231484,1.498596556,204949.3498,1.737976383,347.2827777
53.26036777,1.513587464,204187.5201,1.750636839,348.6177604
53.86359901,1.528709553,204156.3073,1.756312201,349.7262379
53.87976711,1.544023965,205614.2235,1.752383089,351.3566634
54.26812912,1.559466548,206607.6068,1.751073374,352.7397943
54.81218585,1.575053621,207419.1039,1.751509924,354.1054189
55.43158268,1.590792103,208060.0605,1.75412931,355.6318987
56.03722174,1.606689682,208443.4582,1.757403548,356.9313223
57.34646403,1.622698665,208301.5917,1.764606873,358.1793246
57.62023941,1.638939672,208781.1446,1.766353135,359.3633015
58.09009394,1.655330448,210066.2031,1.763733714,361.0539166
58.25558167,1.671906795,211925.3158,1.755002353,362.4567414
58.48017092,1.688645539,214503.7088,1.742778449,364.4012179
58.81049205,1.705545196,216847.1303,1.730991109,365.9889715
59.26153326,1.72260643,219037.3832,1.721386605,367.7463352
60.03896842,1.73981663,220956.0724,1.715711199,369.8735587
60.41128051,1.757227576,221867.0048,1.715711187,371.3781504
60.76983288,1.774814459,222731.6498,1.717894015,373.2066392
61.33778586,1.792563598,223430.1411,1.720949971,374.849656
61.92112283,1.810489978,224193.6941,1.723569358,376.5265942
62.21965939,1.828616162,225433.48,1.722259646,378.1821918
62.78671678,1.846906003,227165.686,1.71789395,380.036398
62.81666878,1.865416316,228843.3213,1.71396484,381.8621475
63.17134773,1.884089469,230587.6739,1.710472287,383.8602448
63.76332107,1.902933912,231425.3623,1.711781971,385.4819237
64.39191068,1.921965155,231956.6885,1.715274493,387.1714476
64.68490459,1.941210781,231755.6218,1.724442405,388.9058307
65.22601716,1.960632702,231807.9346,1.730117768,390.2823981
65.6047328,1.980260887,232552.4766,1.732300594,392.0933799
66.3206643,2.000063017,233920.2608,1.72880803,393.6647253
66.95247113,2.020069963,237177.3332,1.716147547,396.078641
67.38857279,2.040291372,240474.5004,1.7017408,398.124886
68.02283067,2.060702266,244217.7667,1.686897479,400.6646389
68.53049605,2.081326987,246460.9351,1.67991238,402.5806704
69.04230077,2.102158643,248653.0361,1.674236985,404.7067971
69.63818266,2.123193776,249375.5295,1.679475778,407.1601041
70.30148772,2.144435715,249426.484,1.686024272,408.7861629
70.53177001,2.165920807,249429.6579,1.694755618,410.8838349
71.05013738,2.187601881,249318.6396,1.702177252,412.4497081
71.76499382,2.209487396,248541.2465,1.716583961,414.4620357
72.32744273,2.231603302,248753.2716,1.721822755,415.9535007
73.37115963,2.253908146,249182.7462,1.7274981,417.9286303
73.79782843,2.27647964,249083.8457,1.734483169,419.3522491
73.94801835,2.299296852,250409.6844,1.734046596,421.351439
74.2122599,2.322335439,252148.5897,1.730117479,423.1919647
75.17926343,2.345557144,253671.6627,1.727498042,425.0073324
75.91808321,2.369027984,255586.2199,1.724005478,427.2494533
76.53113963,2.392743282,257522.2539,1.718766647,429.1392257
76.92099389,2.416832571,259657.2236,1.713964391,431.4513728
77.19509037,2.44105115,261069.825,1.712218112,433.3980404
77.80223376,2.465490816,261678.4389,1.715274066,435.3096975
78.58504571,2.490164688,262246.1333,1.717893446,437.0539377
79.15217715,2.51497592,262775.2814,1.721822536,439.1472385
79.51192565,2.540176156,261976.0262,1.733173282,440.9319592
79.86997931,2.565629708,261036.3167,1.74408746,442.3632393
80.44700023,2.59132389,260556.1973,1.752818792,443.8623644
81.05480057,2.617274217,260110.9292,1.762859826,445.5737751
81.42025834,2.643501859,259809.5491,1.77071803,446.8420117
81.88644071,2.669986102,260441.07,1.774210556,448.5173098
82.27431945,2.696741802,261695.7416,1.773337408,450.1083499
83.3308155,2.723720349,263756.0192,1.767661995,451.8766682
84.00174541,2.75099646,266483.5899,1.758930622,454.0006106
84.64100128,2.778548833,269550.8629,1.74845298,456.297443
85.55334664,2.806359239,271722.3536,1.741904437,458.1357918
86.03515975,2.834478714,274283.5728,1.733609639,460.1645307
86.76091761,2.862863888,276280.4807,1.730553643,462.632069
87.35341231,2.891542377,277285.954,1.730990191,464.3949091
87.97002146,2.920507291,279281.1452,1.727934198,466.7256633
89.0096023,2.949734022,280789.0786,1.727497597,468.9480944
89.62780883,2.979283314,281893.5616,1.728370713,470.8706957
90.20351372,3.009132491,282977.4354,1.729243829,472.8326878
90.52438116,3.039299391,283666.1791,1.733172926,475.0080566
91.45557371,3.069726983,283187.1998,1.741467679,476.5411107
92.09195913,3.100480583,283940.7246,1.744087062,478.593927
92.5767594,3.131553528,284468.4547,1.747143019,480.3731813
93.3288162,3.162920315,284985.9349,1.750635534,482.1973029
93.58288891,3.194636647,286187.923,1.751072093,484.3442182
94.15750945,3.226649437,287673.6766,1.748452671,486.1508282
94.95691831,3.258968409,287725.8161,1.755001155,488.1095431
95.81624292,3.291608068,288386.0318,1.757183965,489.815488
96.62223735,3.324579364,289558.0318,1.756747372,491.7348103
97.25166341,3.357893939,291164.2198,1.755001081,493.9353512
98.32070975,3.391513019,292977.7217,1.752381642,496.1369938
99.00668034,3.425496256,295248.7581,1.746269675,498.1340059
99.52274275,3.459833841,296548.6895,1.745396523,500.1047533
100.341447,3.494496001,297825.2702,1.746269631,502.4125347
101.0639353,3.529513183,299199.5109,1.744959905,504.2213366
102.2435283,3.564850667,301023.8044,1.743213598,506.6287002
102.5525049,3.600603196,303142.6015,1.739721048,509.004317
103.2598808,3.636687538,306005.8774,1.731862812,511.2464406
104.3502509,3.673108084,309850.8416,1.720075458,513.8529557
105.2603015,3.709906859,313177.6555,1.711780649,516.6717522
105.9055144,3.747093759,316259.9602,1.703485848,519.0725422
106.3545858,3.784667624,318933.9755,1.69912016,522.0324887
107.4343743,3.822575726,319519.7362,1.703049231,524.2231908
108.5965546,3.860859193,319385.2987,1.710034272,526.3941981
109.4718292,3.899546879,318299.7299,1.722258129,528.7391862
110.2275679,3.938631474,316766.3597,1.734918557,530.3707225
111.2247404,3.978092194,315642.9432,1.746705842,532.4257365
112.0403408,4.017961857,315185.8233,1.75412746,534.2181292
112.8508984,4.058232395,315686.8589,1.757183405,536.0958721
113.7213626,4.098903499,316831.1291,1.758493078,538.3850534
114.707939,4.139975319,318643.8215,1.756746776,540.78038
115.5828874,4.181467365,320142.7112,1.755000478,542.7084602
116.4132385,4.223379432,322367.0234,1.750634778,544.9122892
117.0795011,4.265723882,324035.4192,1.750634756,547.4695586
117.7411344,4.308494083,325796.3673,1.748015331,549.520191
118.6795864,4.351675017,327459.6941,1.747578733,552.013999
119.6438012,4.39528809,329075.6097,1.746269,554.0930876
120.33068,4.439358457,330653.5255,1.746705545,556.5693824
121.3185241,4.483849339,332559.6433,1.744522676,558.8498139
122.3104797,4.528786334,333943.9114,1.745832345,561.3578484
123.5355353,4.574158641,335966.9361,1.742339768,563.5168214
124.437455,4.62000902,339227.0394,1.734918096,566.3903355
125.6074466,4.666301804,342234.7496,1.727496415,568.9738767
125.9879963,4.713113903,344075.1909,1.725313567,571.4053026
127.237817,4.760336571,347517.3744,1.717455317,574.4670327
128.4784229,4.808034336,349405.0515,1.71701871,577.3886981
129.4350267,4.856230702,349189.7272,1.723567187,579.374778
130.2192078,4.904923261,348603.307,1.732735072,581.4494877
131.2156674,4.954090377,348948.0768,1.740156681,584.2015413
132.1729331,5.003754249,348425.4473,1.748451425,586.0366154
133.0785142,5.053920537,348603.4448,1.754999903,588.3958321
134.1205974,5.104581557,350015.7922,1.754563301,590.3370491
135.1701155,5.155750994,351478.5466,1.754563267,592.6207668
136.0905073,5.207443407,353203.1714,1.754126669,595.3651596
137.0624653,5.259651613,355818.1868,1.748451265,597.6838922
138.2250476,5.31237124,360567.3035,1.735790781,600.8966284
139.4491872,5.365616508,364734.3985,1.726186265,604.189246
140.6882529,5.419395662,367770.6724,1.720510853,606.9522501
141.7865315,5.473724616,369722.8169,1.719201116,609.5839405
142.8339528,5.528603109,369487.6544,1.727932424,612.2823781
143.9978861,5.584024919,368171.1476,1.739283129,614.2400138
145.3690938,5.639989167,368013.1239,1.746704724,616.6933489
146.700267,5.69651871,369062.7352,1.748450948,619.0668015
147.7732411,5.753633974,371077.0626,1.746704645,621.5628047
148.8361562,5.811323527,374348.2756,1.740592672,624.5928019
149.8823501,5.869593675,376697.9926,1.737100102,627.0417531
150.8335841,5.928159773,377795.8922,1.74015604,629.8485208
152.0103383,5.987895926,378094.5055,1.745394805,632.193522
153.0479987,6.047943884,378347.9597,1.750197008,634.4892792
153.9465301,6.108604658,378340.1545,1.756745482,636.973243
155.1514194,6.169853846,379503.1969,1.75718201,639.1562958
156.3728909,6.231717381,381095.3158,1.757181969,641.9171128
157.6775587,6.29419682,382082.9964,1.758928194,644.2927566
158.7090322,6.357322654,384931.6316,1.754999057,647.32932
159.9794131,6.421066464,387519.49,1.750633346,649.7903151
160.9482868,6.485471351,390526.019,1.746267645,652.8826846
162.5432657,6.550480429,392772.0187,1.743648191,655.3393084
163.8200822,6.61616454,396482.9512,1.736226512,658.1756325
165.208402,6.682500769,399451.0421,1.733170499,661.587533
166.7040609,6.749496089,401541.4519,1.73317045,664.8123199
167.9331816,6.817183008,403485.1148,1.731860709,667.3805514
169.0914449,6.885553599,405914.5623,1.730550971,670.6961538
170.4436446,6.954596083,405949.7677,1.736662863,673.3278553
171.8299037,7.024329788,406232.7985,1.741028485,675.6597332
172.9771003,7.094780326,407469.819,1.743211282,678.6875484
174.5139118,7.165912013,407520.3576,1.748450033,680.917664
175.8824375,7.237769866,407057.5845,1.75630819,683.5832872
177.312498,7.31034545,408986.4997,1.754561876,686.2795538
178.768287,7.383648467,411064.1536,1.752378994,688.9298605
179.9092347,7.457709663,413862.8813,1.748886422,692.2356166
181.5347194,7.53248162,416638.7542,1.744520701,694.9110956
182.9985755,7.608015912,420621.8082,1.737972152,698.3875631
184.2591678,7.684323048,423556.0172,1.734479577,701.2818824
185.5629706,7.761393876,426148.4804,1.732733267,704.2670279
186.965773,7.839232291,427850.8469,1.735352622,707.5815453
188.4858932,7.917844554,429220.2106,1.736662272,710.1760493
189.715314,7.99726682,431191.1645,1.737535366,713.4577357
191.1727979,8.077471267,432671.8495,1.738845017,716.2481095
192.9033093,8.158462668,435253.7211,1.737535261,719.8208793
194.5279747,8.240276377,437313.3556,1.736225508,722.5795246
195.8998237,8.322932282,437794.4816,1.740591129,725.1401046
197.8323904,8.406380252,437545.6561,1.748012698,728.0377279
199.4675905,8.490687185,437073.0016,1.754997709,730.5009267
200.721738,8.575867288,436671.1402,1.763292433,733.5232784
202.7668379,8.661848915,436639.7496,1.768531164,735.732623
204.2672605,8.748731981,440079.6735,1.763292314,739.0515223
206.0540255,8.836468329,443641.0322,1.757180324,741.9009966
207.3489868,8.925119829,448672.2044,1.74713925,745.173934
209.168853,9.014625976,453047.7076,1.740590692,748.9786925
210.7891863,9.105045263,456512.3504,1.735351841,752.0141865
212.4181571,9.196372425,458099.294,1.737534619,755.4425176
214.3459554,9.288596723,458912.8181,1.741463654,758.6049527
215.9938633,9.381766858,458120.1607,1.749321796,761.1918058
217.3822807,9.47589095,458471.6436,1.753687415,763.8443052
218.904234,9.570951559,460341.1546,1.754123931,767.1741533
220.5942789,9.666955758,463343.7091,1.750194777,770.1319595
222.3071103,9.763922914,466233.3612,1.748011888,773.660965
224.3345837,9.861842794,469576.6878,1.743646157,776.7938603
226.0105491,9.960770696,472033.7157,1.742336402,780.0394558
227.7188736,10.06069038,472795.0703,1.747138576,783.3780631
229.4737117,10.16161078,472939.5373,1.75281388,786.2313716
231.1826341,10.26354839,474596.3552,1.754123523,789.2619487
232.9501417,10.36650614,476316.5422,1.754996597,792.1748939
235.0472724,10.47047576,481535.4526,1.746265201,796.224777
236.5351719,10.57553201,486590.9308,1.736660693,799.6235649
238.1649218,10.68163232,492706.7141,1.725746483,803.9984299
240.0156261,10.78877973,497436.9485,1.717451663,807.5515146
241.6930065,10.89701547,502685.5342,1.708720284,811.6123335
243.5401282,11.00632716,507090.7968,1.704354562,816.4008321
245.6002897,11.11672238,510405.3649,1.701298531,819.9922257
247.5562363,11.22823403,515258.1017,1.696059674,824.7391482
249.3080447,11.34087991,517858.6827,1.695186485,828.2090723
251.3686477,11.45463619,520505.7987,1.694749853,832.0663711
253.1593276,11.56955416,523195.0729,1.696059494,836.7903092
255.1699949,11.61865794,523680.7613,1.701298223,840.2153773
256.6659608,11.61855596,523788.6131,1.708719799,844.2543082
257.5907044,11.61849306,525603.2018,1.711339166,848.365443
258.3547398,11.61844116,526212.227,1.716141368,851.7291978
259.3885652,11.61837081,530065.8988,1.713958505,856.418101
259.8220245,11.61834152,534106.264,1.70959283,860.1735895
260.5852271,11.61828968,537242.5684,1.709592805,864.6480113
260.9437447,11.61826552,537619.8053,1.715268153,867.8705975
261.424667,11.61823299,539397.6884,1.717887534,871.5090024
261.9530523,11.61819722,537540.4181,1.731421065,875.3301499
262.0417799,11.61819152,534048.4542,1.746700875,877.6849828
262.7025622,11.61814668,530626.9861,1.763290364,880.7204612
263.4357881,11.61809689,531067.4085,1.767219435,883.4451716
263.7110371,11.61807843,531036.8972,1.772458219,886.2869574
263.7364806,11.61807707,534850.8157,1.768092557,890.4527781
264.0417063,11.61805656,539733.3814,1.759797792,893.9193808
264.6217181,11.61801725,544825.1768,1.752812716,898.3117305
265.0318621,11.61798956,545188.7026,1.757178363,901.2027587
265.4553291,11.61796096,543380.2044,1.7680925,903.8979166
265.6756209,11.61794626,539716.533,1.785555135,906.7364157
265.8126442,11.61793726,536229.1517,1.801271508,909.2170922
265.8888814,11.61793242,533640.0582,1.813495355,911.1024924
266.1682938,11.61791368,533280.982,1.820043837,913.649923
266.286998,11.61790593,532897.0021,1.825719191,915.8931457
266.5530875,11.6178881,532454.8261,1.830957975,917.9842708
266.7067645,11.61787796,530870.7791,1.840562422,920.1563692
267.0269785,11.61785642,529698.8426,1.847547468,921.8601296
266.967488,11.61786086,528749.1773,1.854095961,923.833065
267.1536397,11.6178485,529965.6427,1.854095955,925.9613947
267.1482738,11.61784924,531703.8758,1.852786257,928.138958
267.6483478,11.6178154,536098.9102,1.844491485,931.1230008
267.5996823,11.61781911,540428.9887,1.835760166,933.6780823
267.7025654,11.61781244,544583.9213,1.829211672,936.8995653
268.0685771,11.61778777,546984.4871,1.82702883,939.4283952
268.1173357,11.61778481,549886.7623,1.824409432,942.630183
268.4175653,11.61776464,550746.6949,1.826155686,944.8635636
268.5637481,11.61775501,549769.6373,1.834013869,947.2643584
268.4251526,11.61776487,549335.4623,1.839252667,949.1486578
268.6962381,11.6177467,548501.6116,1.845801148,951.1150401
269.0406,11.61772351,545731.9232,1.858461551,952.9512081
269.122666,11.61771827,541501.2168,1.874614491,954.1144
269.1297904,11.61771815,540155.0424,1.881599549,955.3946769
269.3051172,11.61770653,538270.099,1.890767427,956.8314374
269.4762805,11.6176952,538148.3995,1.893823384,958.2156731
269.594152,11.6176875,538843.7932,1.894259947,959.6600921
269.2665369,11.61771029,542268.5222,1.887274901,961.8792266
269.5942451,11.61768824,544876.4998,1.882909231,964.0480466
269.6763111,11.617683,547733.2077,1.877233871,966.0581893
269.8549686,11.61767115,551006.4313,1.870685375,968.2510785
269.8895716,11.61766916,555150.733,1.862390618,971.1727356
270.2534753,11.52241842,1.7977E+308,1.8431817,0
270.0063979,11.4063048,1.7977E+308,1.762416998,0
269.7189353,11.29019395,1.7977E+308,1.607436072,0
269.7000137,11.17406472,1.7977E+308,1.391772461,0
269.1531697,11.05797161,1.7977E+308,1.119136996,0
269.2949563,10.94183139,1.7977E+308,0.786255403,0
268.9304703,10.8257258,1.7977E+308,0.498121833,0
268.8436848,10.70960122,1.7977E+308,0.279838822,0
268.6819577,10.59348176,1.7977E+308,0.122675053,0
268.5672772,10.47735908,1.7977E+308,0.022701433,0
268.3193672,10.36124552,1.7977E+308,0.028813358,0
267.9103325,10.24514298,1.7977E+308,0.028813358,0
267.744442,10.12902381,1.7977E+308,0.021391736,0
267.3129248,10.01292281,1.7977E+308,0.016152943,0
267.1486996,9.896803523,1.7977E+308,0.013096981,0
267.0127857,9.7806823,1.7977E+308,0.010914151,0
266.7157472,9.664572099,1.7977E+308,0.007421623,0
266.552771,9.548452727,1.7977E+308,0.004802226,0
266.2715535,9.432341444,1.7977E+308,0.005675359,0
265.9953321,9.31622982,1.7977E+308,0.006111925,0
265.8261108,9.200110875,1.7977E+308,0.000873132,0
265.5548856,9.083998909,1.7977E+308,0.005457076,0
265.5501196,8.967868712,1.7977E+308,0.01222385,0
265.279727,8.851756689,1.7977E+308,0.015279812,0
265.1396496,8.73563575,1.7977E+308,0.010695868,0
264.7285333,8.619533355,1.7977E+308,0.004802227,0
264.5143469,8.503417486,1.7977E+308,0.017462643,0
264.1802539,8.387309821,1.7977E+308,0.031432757,0
264.1067914,8.271184324,1.7977E+308,0.041910342,0
263.7410563,8.155078824,1.7977E+308,0.041037211,0
263.6642631,8.038953555,1.7977E+308,0.032305889,0
263.7206994,7.922819171,1.7977E+308,0.027503662,0
263.2708632,7.806719425,1.7977E+308,0.032742456,0
263.2140544,7.690592789,1.7977E+308,0.035798418,0
262.8999458,7.574483757,1.7977E+308,0.03448872,0
262.5516971,7.458377061,1.7977E+308,0.028813361,0
262.2492461,7.342267231,1.7977E+308,0.022701436,0
262.1682894,7.226142247,1.7977E+308,0.028813362,0
261.9116361,7.110029284,1.7977E+308,0.034488721,0
261.7024459,6.993913073,1.7977E+308,0.033615589,0
261.2509442,6.877813441,1.7977E+308,0.028813362,0
261.2132872,6.761685495,1.7977E+308,0.021391739,0
260.8725327,6.645578285,1.7977E+308,0.012660417,0
260.7191323,6.529458258,1.7977E+308,0.013096983,0
260.4558176,6.41334575,1.7977E+308,0.020955173,0
260.6196704,6.297204017,1.7977E+308,0.028376796,0
259.8042852,6.181129281,1.7977E+308,0.024884268,0
259.6766981,6.065007488,1.7977E+308,0.019645475,0
259.5066441,5.948888599,1.7977E+308,0.014843248,0
259.0110101,5.832791987,1.7977E+308,0.011350719,0
259.0733428,5.716076545,1.7977E+308,0.012223851,0
258.6317658,5.600556888,1.7977E+308,0.013096983,0
258.7556497,5.484417889,1.7977E+308,0.014406682,0
258.3116422,5.368317745,1.7977E+308,0.013096984,0
258.2889734,5.252188773,1.7977E+308,0.008294756,0
257.9840244,5.136079114,1.7977E+308,0.00567536,0
257.5199649,5.020560995,1.7977E+308,0.007421624,0
257.1377111,4.903295316,1.7977E+308,0.011787285,0
257.0825677,4.787168566,1.7977E+308,0.014406682,0
256.5868661,4.671652613,1.7977E+308,0.009604455,0
256.5059094,4.555527629,1.7977E+308,0.007421624,0
256.1385089,4.439422243,1.7977E+308,0.006111926,0
256.1782916,4.323288998,1.7977E+308,0.008294757,0
255.6901517,4.207191873,1.7977E+308,0.010041021,0
255.5708915,4.091069509,1.7977E+308,0.004365661,0
255.2284715,3.974962414,1.7977E+308,0.003929095,0
254.7544873,3.85886432,1.7977E+308,0.010477588,0
254.397079,3.74275825,1.7977E+308,0.01702608,0
254.1887214,3.626641983,1.7977E+308,0.024884271,0
254.0261616,3.510522582,1.7977E+308,0.030996197,0
253.7645121,3.394409961,1.7977E+308,0.036234991,0
253.3679676,3.278306569,1.7977E+308,0.036671558,0
253.0596878,3.162197137,1.7977E+308,0.036234992,0
253.0944743,3.046064235,1.7977E+308,0.036671558,0
252.7945213,2.929954234,1.7977E+308,0.034488727,0
252.1398443,2.813868503,1.7977E+308,0.031869331,0
252.0813701,2.69774198,1.7977E+308,0.029249934,0
251.8921643,2.581624403,1.7977E+308,0.027067103,0
251.622188,2.465512351,1.7977E+308,0.029249934,0
251.0249663,2.349422689,1.7977E+308,0.033615596,0
251.2479398,2.233276911,1.7977E+308,0.036234993,0
250.7398154,2.117181152,1.7977E+308,0.034488729,0
250.4148818,2.001072861,1.7977E+308,0.030559633,0
250.0108431,1.884969981,1.7977E+308,0.026630538,0
249.8124777,1.76885303,1.7977E+308,0.024011141,0
249.1544699,1.652767527,1.7977E+308,0.015716383,0
248.9477777,1.536651145,1.7977E+308,0.010914155,0
248.7706458,1.420532741,1.7977E+308,0.007639909,0
248.4236461,1.30442596,1.7977E+308,0.001746265,0
247.8047745,1.188337778,1.7977E+308,0.004365662,0
247.9033168,1.078727772,1.7977E+308,0.037544696,0
247.4651379,0.962627228,1.7977E+308,0.027503673,0
247.1318775,0.846519506,1.7977E+308,0.013533553,0
246.6487336,0.730422039,1.7977E+308,0.003055964,0
246.2180489,0.614320983,1.7977E+308,0.008731325,0
245.7140879,0.49822494,1.7977E+308,0.015716385,0
245.1576677,0.382132486,1.7977E+308,0.016152951,0
244.4796753,0.26604835,1.7977E+308,0.012223855,0
244.0090217,0.149950028,1.7977E+308,0.006111928,0
242.2901723,0.033937104,1.7977E+308,0.005238795,0
241.7496942,0.003780147,1.7977E+308,0.008294759,0